/usr/local/bin/ginkgo --focus=Pods should be submitted and removed --skip=Alpha|\[(Disruptive|Feature:[^\]]+|Flaky)\] --noColor=true --nodes=1 /usr/local/bin/e2e.test -- --disable-log-dump --repo-root=/kubernetes --provider="local" --report-dir="/tmp/results" --kubeconfig=""
Oct  4 06:36:30.892: INFO: Overriding default scale value of zero to 1
Oct  4 06:36:30.892: INFO: Overriding default milliseconds value of zero to 5000
I1004 06:36:30.985104      17 test_context.go:382] Using a temporary kubeconfig file from in-cluster config : /tmp/kubeconfig-089469922
I1004 06:36:30.985292      17 e2e.go:333] Starting e2e run "4cf8667a-e671-11e9-b124-72e9dc3d0bc8" on Ginkgo node 1
Running Suite: Kubernetes e2e suite
===================================
Random Seed: 1570170990 - Will randomize all specs
Will run 1 of 996 specs

Oct  4 06:36:31.029: INFO: >>> kubeConfig: /tmp/kubeconfig-089469922
Oct  4 06:36:31.031: INFO: Waiting up to 30m0s for all (but 0) nodes to be schedulable
Oct  4 06:36:31.037: INFO: Waiting up to 10m0s for all pods (need at least 0) in namespace 'kube-system' to be running and ready
Oct  4 06:36:31.076: INFO: The status of Pod coredns-7c949f49d5-p6f2z is Pending (Ready = false), waiting for it to be either Running (with Ready = true) or Failed
Oct  4 06:36:31.076: INFO: 10 / 11 pods in namespace 'kube-system' are running and ready (0 seconds elapsed)
Oct  4 06:36:31.076: INFO: expected 6 pod replicas in namespace 'kube-system', 5 are Running and Ready.
Oct  4 06:36:31.076: INFO: POD                       NODE  PHASE    GRACE  CONDITIONS
Oct  4 06:36:31.076: INFO: coredns-7c949f49d5-p6f2z        Pending         [{PodScheduled False 0001-01-01 00:00:00 +0000 UTC 2019-05-15 03:24:15 +0000 UTC Unschedulable 0/1 nodes are available: 1 node(s) didn't match pod affinity/anti-affinity, 1 node(s) didn't satisfy existing pods anti-affinity rules.}]
Oct  4 06:36:31.076: INFO: 
Oct  4 06:36:33.447: INFO: The status of Pod coredns-7c949f49d5-p6f2z is Pending (Ready = false), waiting for it to be either Running (with Ready = true) or Failed
Oct  4 06:36:33.447: INFO: 10 / 11 pods in namespace 'kube-system' are running and ready (2 seconds elapsed)
Oct  4 06:36:33.447: INFO: expected 6 pod replicas in namespace 'kube-system', 5 are Running and Ready.
Oct  4 06:36:33.447: INFO: POD                       NODE  PHASE    GRACE  CONDITIONS
Oct  4 06:36:33.447: INFO: coredns-7c949f49d5-p6f2z        Pending         [{PodScheduled False 0001-01-01 00:00:00 +0000 UTC 2019-05-15 03:24:15 +0000 UTC Unschedulable 0/1 nodes are available: 1 node(s) didn't match pod affinity/anti-affinity, 1 node(s) didn't satisfy existing pods anti-affinity rules.}]
Oct  4 06:36:33.448: INFO: 
Oct  4 06:36:35.090: INFO: The status of Pod coredns-7c949f49d5-p6f2z is Pending (Ready = false), waiting for it to be either Running (with Ready = true) or Failed
Oct  4 06:36:35.090: INFO: 10 / 11 pods in namespace 'kube-system' are running and ready (4 seconds elapsed)
Oct  4 06:36:35.090: INFO: expected 6 pod replicas in namespace 'kube-system', 5 are Running and Ready.
Oct  4 06:36:35.090: INFO: POD                       NODE  PHASE    GRACE  CONDITIONS
Oct  4 06:36:35.090: INFO: coredns-7c949f49d5-p6f2z        Pending         [{PodScheduled False 0001-01-01 00:00:00 +0000 UTC 2019-05-15 03:24:15 +0000 UTC Unschedulable 0/1 nodes are available: 1 node(s) didn't match pod affinity/anti-affinity, 1 node(s) didn't satisfy existing pods anti-affinity rules.}]
Oct  4 06:36:35.090: INFO: 
Oct  4 06:36:37.081: INFO: The status of Pod coredns-7c949f49d5-p6f2z is Pending (Ready = false), waiting for it to be either Running (with Ready = true) or Failed
Oct  4 06:36:37.081: INFO: 10 / 11 pods in namespace 'kube-system' are running and ready (6 seconds elapsed)
Oct  4 06:36:37.081: INFO: expected 6 pod replicas in namespace 'kube-system', 5 are Running and Ready.
Oct  4 06:36:37.081: INFO: POD                       NODE  PHASE    GRACE  CONDITIONS
Oct  4 06:36:37.081: INFO: coredns-7c949f49d5-p6f2z        Pending         [{PodScheduled False 0001-01-01 00:00:00 +0000 UTC 2019-05-15 03:24:15 +0000 UTC Unschedulable 0/1 nodes are available: 1 node(s) didn't match pod affinity/anti-affinity, 1 node(s) didn't satisfy existing pods anti-affinity rules.}]
Oct  4 06:36:37.081: INFO: 
Oct  4 06:36:40.180: INFO: The status of Pod coredns-7c949f49d5-p6f2z is Pending (Ready = false), waiting for it to be either Running (with Ready = true) or Failed
Oct  4 06:36:40.180: INFO: 10 / 11 pods in namespace 'kube-system' are running and ready (9 seconds elapsed)
Oct  4 06:36:40.180: INFO: expected 6 pod replicas in namespace 'kube-system', 5 are Running and Ready.
Oct  4 06:36:40.180: INFO: POD                       NODE  PHASE    GRACE  CONDITIONS
Oct  4 06:36:40.180: INFO: coredns-7c949f49d5-p6f2z        Pending         [{PodScheduled False 0001-01-01 00:00:00 +0000 UTC 2019-05-15 03:24:15 +0000 UTC Unschedulable 0/1 nodes are available: 1 node(s) didn't match pod affinity/anti-affinity, 1 node(s) didn't satisfy existing pods anti-affinity rules.}]
Oct  4 06:36:40.180: INFO: 
Oct  4 06:36:41.092: INFO: The status of Pod coredns-7c949f49d5-p6f2z is Pending (Ready = false), waiting for it to be either Running (with Ready = true) or Failed
Oct  4 06:36:41.092: INFO: 10 / 11 pods in namespace 'kube-system' are running and ready (10 seconds elapsed)
Oct  4 06:36:41.092: INFO: expected 6 pod replicas in namespace 'kube-system', 5 are Running and Ready.
Oct  4 06:36:41.092: INFO: POD                       NODE  PHASE    GRACE  CONDITIONS
Oct  4 06:36:41.092: INFO: coredns-7c949f49d5-p6f2z        Pending         [{PodScheduled False 0001-01-01 00:00:00 +0000 UTC 2019-05-15 03:24:15 +0000 UTC Unschedulable 0/1 nodes are available: 1 node(s) didn't match pod affinity/anti-affinity, 1 node(s) didn't satisfy existing pods anti-affinity rules.}]
Oct  4 06:36:41.092: INFO: 
Oct  4 06:36:43.089: INFO: The status of Pod coredns-7c949f49d5-p6f2z is Pending (Ready = false), waiting for it to be either Running (with Ready = true) or Failed
Oct  4 06:36:43.089: INFO: 10 / 11 pods in namespace 'kube-system' are running and ready (12 seconds elapsed)
Oct  4 06:36:43.089: INFO: expected 6 pod replicas in namespace 'kube-system', 5 are Running and Ready.
Oct  4 06:36:43.089: INFO: POD                       NODE  PHASE    GRACE  CONDITIONS
Oct  4 06:36:43.089: INFO: coredns-7c949f49d5-p6f2z        Pending         [{PodScheduled False 0001-01-01 00:00:00 +0000 UTC 2019-05-15 03:24:15 +0000 UTC Unschedulable 0/1 nodes are available: 1 node(s) didn't match pod affinity/anti-affinity, 1 node(s) didn't satisfy existing pods anti-affinity rules.}]
Oct  4 06:36:43.089: INFO: 
Oct  4 06:36:45.091: INFO: The status of Pod coredns-7c949f49d5-p6f2z is Pending (Ready = false), waiting for it to be either Running (with Ready = true) or Failed
Oct  4 06:36:45.091: INFO: 10 / 11 pods in namespace 'kube-system' are running and ready (14 seconds elapsed)
Oct  4 06:36:45.091: INFO: expected 6 pod replicas in namespace 'kube-system', 5 are Running and Ready.
Oct  4 06:36:45.091: INFO: POD                       NODE  PHASE    GRACE  CONDITIONS
Oct  4 06:36:45.091: INFO: coredns-7c949f49d5-p6f2z        Pending         [{PodScheduled False 0001-01-01 00:00:00 +0000 UTC 2019-05-15 03:24:15 +0000 UTC Unschedulable 0/1 nodes are available: 1 node(s) didn't match pod affinity/anti-affinity, 1 node(s) didn't satisfy existing pods anti-affinity rules.}]
Oct  4 06:36:45.091: INFO: 
Oct  4 06:36:47.082: INFO: The status of Pod coredns-7c949f49d5-p6f2z is Pending (Ready = false), waiting for it to be either Running (with Ready = true) or Failed
Oct  4 06:36:47.082: INFO: 10 / 11 pods in namespace 'kube-system' are running and ready (16 seconds elapsed)
Oct  4 06:36:47.082: INFO: expected 6 pod replicas in namespace 'kube-system', 5 are Running and Ready.
Oct  4 06:36:47.082: INFO: POD                       NODE  PHASE    GRACE  CONDITIONS
Oct  4 06:36:47.082: INFO: coredns-7c949f49d5-p6f2z        Pending         [{PodScheduled False 0001-01-01 00:00:00 +0000 UTC 2019-05-15 03:24:15 +0000 UTC Unschedulable 0/1 nodes are available: 1 node(s) didn't match pod affinity/anti-affinity, 1 node(s) didn't satisfy existing pods anti-affinity rules.}]
Oct  4 06:36:47.082: INFO: 
Oct  4 06:36:49.081: INFO: The status of Pod coredns-7c949f49d5-p6f2z is Pending (Ready = false), waiting for it to be either Running (with Ready = true) or Failed
Oct  4 06:36:49.081: INFO: 10 / 11 pods in namespace 'kube-system' are running and ready (18 seconds elapsed)
Oct  4 06:36:49.081: INFO: expected 6 pod replicas in namespace 'kube-system', 5 are Running and Ready.
Oct  4 06:36:49.081: INFO: POD                       NODE  PHASE    GRACE  CONDITIONS
Oct  4 06:36:49.081: INFO: coredns-7c949f49d5-p6f2z        Pending         [{PodScheduled False 0001-01-01 00:00:00 +0000 UTC 2019-05-15 03:24:15 +0000 UTC Unschedulable 0/1 nodes are available: 1 node(s) didn't match pod affinity/anti-affinity, 1 node(s) didn't satisfy existing pods anti-affinity rules.}]
Oct  4 06:36:49.081: INFO: 
Oct  4 06:36:51.086: INFO: The status of Pod coredns-7c949f49d5-p6f2z is Pending (Ready = false), waiting for it to be either Running (with Ready = true) or Failed
Oct  4 06:36:51.086: INFO: 10 / 11 pods in namespace 'kube-system' are running and ready (20 seconds elapsed)
Oct  4 06:36:51.086: INFO: expected 6 pod replicas in namespace 'kube-system', 5 are Running and Ready.
Oct  4 06:36:51.086: INFO: POD                       NODE  PHASE    GRACE  CONDITIONS
Oct  4 06:36:51.086: INFO: coredns-7c949f49d5-p6f2z        Pending         [{PodScheduled False 0001-01-01 00:00:00 +0000 UTC 2019-05-15 03:24:15 +0000 UTC Unschedulable 0/1 nodes are available: 1 node(s) didn't match pod affinity/anti-affinity, 1 node(s) didn't satisfy existing pods anti-affinity rules.}]
Oct  4 06:36:51.086: INFO: 
Oct  4 06:36:53.091: INFO: The status of Pod coredns-7c949f49d5-p6f2z is Pending (Ready = false), waiting for it to be either Running (with Ready = true) or Failed
Oct  4 06:36:53.091: INFO: 10 / 11 pods in namespace 'kube-system' are running and ready (22 seconds elapsed)
Oct  4 06:36:53.091: INFO: expected 6 pod replicas in namespace 'kube-system', 5 are Running and Ready.
Oct  4 06:36:53.091: INFO: POD                       NODE  PHASE    GRACE  CONDITIONS
Oct  4 06:36:53.091: INFO: coredns-7c949f49d5-p6f2z        Pending         [{PodScheduled False 0001-01-01 00:00:00 +0000 UTC 2019-05-15 03:24:15 +0000 UTC Unschedulable 0/1 nodes are available: 1 node(s) didn't match pod affinity/anti-affinity, 1 node(s) didn't satisfy existing pods anti-affinity rules.}]
Oct  4 06:36:53.091: INFO: 
Oct  4 06:36:55.090: INFO: The status of Pod coredns-7c949f49d5-p6f2z is Pending (Ready = false), waiting for it to be either Running (with Ready = true) or Failed
Oct  4 06:36:55.090: INFO: 10 / 11 pods in namespace 'kube-system' are running and ready (24 seconds elapsed)
Oct  4 06:36:55.090: INFO: expected 6 pod replicas in namespace 'kube-system', 5 are Running and Ready.
Oct  4 06:36:55.090: INFO: POD                       NODE  PHASE    GRACE  CONDITIONS
Oct  4 06:36:55.090: INFO: coredns-7c949f49d5-p6f2z        Pending         [{PodScheduled False 0001-01-01 00:00:00 +0000 UTC 2019-05-15 03:24:15 +0000 UTC Unschedulable 0/1 nodes are available: 1 node(s) didn't match pod affinity/anti-affinity, 1 node(s) didn't satisfy existing pods anti-affinity rules.}]
Oct  4 06:36:55.090: INFO: 
Oct  4 06:36:58.403: INFO: The status of Pod coredns-7c949f49d5-p6f2z is Pending (Ready = false), waiting for it to be either Running (with Ready = true) or Failed
Oct  4 06:36:58.403: INFO: 10 / 11 pods in namespace 'kube-system' are running and ready (27 seconds elapsed)
Oct  4 06:36:58.403: INFO: expected 6 pod replicas in namespace 'kube-system', 5 are Running and Ready.
Oct  4 06:36:58.403: INFO: POD                       NODE  PHASE    GRACE  CONDITIONS
Oct  4 06:36:58.403: INFO: coredns-7c949f49d5-p6f2z        Pending         [{PodScheduled False 0001-01-01 00:00:00 +0000 UTC 2019-05-15 03:24:15 +0000 UTC Unschedulable 0/1 nodes are available: 1 node(s) didn't match pod affinity/anti-affinity, 1 node(s) didn't satisfy existing pods anti-affinity rules.}]
Oct  4 06:36:58.403: INFO: 
Oct  4 06:36:59.089: INFO: The status of Pod coredns-7c949f49d5-p6f2z is Pending (Ready = false), waiting for it to be either Running (with Ready = true) or Failed
Oct  4 06:36:59.089: INFO: 10 / 11 pods in namespace 'kube-system' are running and ready (28 seconds elapsed)
Oct  4 06:36:59.089: INFO: expected 6 pod replicas in namespace 'kube-system', 5 are Running and Ready.
Oct  4 06:36:59.089: INFO: POD                       NODE  PHASE    GRACE  CONDITIONS
Oct  4 06:36:59.089: INFO: coredns-7c949f49d5-p6f2z        Pending         [{PodScheduled False 0001-01-01 00:00:00 +0000 UTC 2019-05-15 03:24:15 +0000 UTC Unschedulable 0/1 nodes are available: 1 node(s) didn't match pod affinity/anti-affinity, 1 node(s) didn't satisfy existing pods anti-affinity rules.}]
Oct  4 06:36:59.089: INFO: 
Oct  4 06:37:01.090: INFO: The status of Pod coredns-7c949f49d5-p6f2z is Pending (Ready = false), waiting for it to be either Running (with Ready = true) or Failed
Oct  4 06:37:01.090: INFO: 10 / 11 pods in namespace 'kube-system' are running and ready (30 seconds elapsed)
Oct  4 06:37:01.090: INFO: expected 6 pod replicas in namespace 'kube-system', 5 are Running and Ready.
Oct  4 06:37:01.090: INFO: POD                       NODE  PHASE    GRACE  CONDITIONS
Oct  4 06:37:01.090: INFO: coredns-7c949f49d5-p6f2z        Pending         [{PodScheduled False 0001-01-01 00:00:00 +0000 UTC 2019-05-15 03:24:15 +0000 UTC Unschedulable 0/1 nodes are available: 1 node(s) didn't match pod affinity/anti-affinity, 1 node(s) didn't satisfy existing pods anti-affinity rules.}]
Oct  4 06:37:01.090: INFO: 
Oct  4 06:37:04.209: INFO: The status of Pod coredns-7c949f49d5-p6f2z is Pending (Ready = false), waiting for it to be either Running (with Ready = true) or Failed
Oct  4 06:37:04.209: INFO: 10 / 11 pods in namespace 'kube-system' are running and ready (33 seconds elapsed)
Oct  4 06:37:04.209: INFO: expected 6 pod replicas in namespace 'kube-system', 5 are Running and Ready.
Oct  4 06:37:04.209: INFO: POD                       NODE  PHASE    GRACE  CONDITIONS
Oct  4 06:37:04.209: INFO: coredns-7c949f49d5-p6f2z        Pending         [{PodScheduled False 0001-01-01 00:00:00 +0000 UTC 2019-05-15 03:24:15 +0000 UTC Unschedulable 0/1 nodes are available: 1 node(s) didn't match pod affinity/anti-affinity, 1 node(s) didn't satisfy existing pods anti-affinity rules.}]
Oct  4 06:37:04.209: INFO: 
Oct  4 06:37:05.081: INFO: The status of Pod coredns-7c949f49d5-p6f2z is Pending (Ready = false), waiting for it to be either Running (with Ready = true) or Failed
Oct  4 06:37:05.081: INFO: 10 / 11 pods in namespace 'kube-system' are running and ready (34 seconds elapsed)
Oct  4 06:37:05.081: INFO: expected 6 pod replicas in namespace 'kube-system', 5 are Running and Ready.
Oct  4 06:37:05.081: INFO: POD                       NODE  PHASE    GRACE  CONDITIONS
Oct  4 06:37:05.081: INFO: coredns-7c949f49d5-p6f2z        Pending         [{PodScheduled False 0001-01-01 00:00:00 +0000 UTC 2019-05-15 03:24:15 +0000 UTC Unschedulable 0/1 nodes are available: 1 node(s) didn't match pod affinity/anti-affinity, 1 node(s) didn't satisfy existing pods anti-affinity rules.}]
Oct  4 06:37:05.081: INFO: 
Oct  4 06:37:07.082: INFO: The status of Pod coredns-7c949f49d5-p6f2z is Pending (Ready = false), waiting for it to be either Running (with Ready = true) or Failed
Oct  4 06:37:07.082: INFO: 10 / 11 pods in namespace 'kube-system' are running and ready (36 seconds elapsed)
Oct  4 06:37:07.082: INFO: expected 6 pod replicas in namespace 'kube-system', 5 are Running and Ready.
Oct  4 06:37:07.082: INFO: POD                       NODE  PHASE    GRACE  CONDITIONS
Oct  4 06:37:07.082: INFO: coredns-7c949f49d5-p6f2z        Pending         [{PodScheduled False 0001-01-01 00:00:00 +0000 UTC 2019-05-15 03:24:15 +0000 UTC Unschedulable 0/1 nodes are available: 1 node(s) didn't match pod affinity/anti-affinity, 1 node(s) didn't satisfy existing pods anti-affinity rules.}]
Oct  4 06:37:07.082: INFO: 
Oct  4 06:37:09.274: INFO: The status of Pod coredns-7c949f49d5-p6f2z is Pending (Ready = false), waiting for it to be either Running (with Ready = true) or Failed
Oct  4 06:37:09.274: INFO: 10 / 11 pods in namespace 'kube-system' are running and ready (38 seconds elapsed)
Oct  4 06:37:09.274: INFO: expected 6 pod replicas in namespace 'kube-system', 5 are Running and Ready.
Oct  4 06:37:09.274: INFO: POD                       NODE  PHASE    GRACE  CONDITIONS
Oct  4 06:37:09.274: INFO: coredns-7c949f49d5-p6f2z        Pending         [{PodScheduled False 0001-01-01 00:00:00 +0000 UTC 2019-05-15 03:24:15 +0000 UTC Unschedulable 0/1 nodes are available: 1 node(s) didn't match pod affinity/anti-affinity, 1 node(s) didn't satisfy existing pods anti-affinity rules.}]
Oct  4 06:37:09.274: INFO: 
Oct  4 06:37:11.083: INFO: The status of Pod coredns-7c949f49d5-p6f2z is Pending (Ready = false), waiting for it to be either Running (with Ready = true) or Failed
Oct  4 06:37:11.083: INFO: 10 / 11 pods in namespace 'kube-system' are running and ready (40 seconds elapsed)
Oct  4 06:37:11.083: INFO: expected 6 pod replicas in namespace 'kube-system', 5 are Running and Ready.
Oct  4 06:37:11.083: INFO: POD                       NODE  PHASE    GRACE  CONDITIONS
Oct  4 06:37:11.083: INFO: coredns-7c949f49d5-p6f2z        Pending         [{PodScheduled False 0001-01-01 00:00:00 +0000 UTC 2019-05-15 03:24:15 +0000 UTC Unschedulable 0/1 nodes are available: 1 node(s) didn't match pod affinity/anti-affinity, 1 node(s) didn't satisfy existing pods anti-affinity rules.}]
Oct  4 06:37:11.083: INFO: 
Oct  4 06:37:13.092: INFO: The status of Pod coredns-7c949f49d5-p6f2z is Pending (Ready = false), waiting for it to be either Running (with Ready = true) or Failed
Oct  4 06:37:13.092: INFO: 10 / 11 pods in namespace 'kube-system' are running and ready (42 seconds elapsed)
Oct  4 06:37:13.092: INFO: expected 6 pod replicas in namespace 'kube-system', 5 are Running and Ready.
Oct  4 06:37:13.092: INFO: POD                       NODE  PHASE    GRACE  CONDITIONS
Oct  4 06:37:13.092: INFO: coredns-7c949f49d5-p6f2z        Pending         [{PodScheduled False 0001-01-01 00:00:00 +0000 UTC 2019-05-15 03:24:15 +0000 UTC Unschedulable 0/1 nodes are available: 1 node(s) didn't match pod affinity/anti-affinity, 1 node(s) didn't satisfy existing pods anti-affinity rules.}]
Oct  4 06:37:13.092: INFO: 
Oct  4 06:37:15.081: INFO: The status of Pod coredns-7c949f49d5-p6f2z is Pending (Ready = false), waiting for it to be either Running (with Ready = true) or Failed
Oct  4 06:37:15.081: INFO: 10 / 11 pods in namespace 'kube-system' are running and ready (44 seconds elapsed)
Oct  4 06:37:15.081: INFO: expected 6 pod replicas in namespace 'kube-system', 5 are Running and Ready.
Oct  4 06:37:15.081: INFO: POD                       NODE  PHASE    GRACE  CONDITIONS
Oct  4 06:37:15.081: INFO: coredns-7c949f49d5-p6f2z        Pending         [{PodScheduled False 0001-01-01 00:00:00 +0000 UTC 2019-05-15 03:24:15 +0000 UTC Unschedulable 0/1 nodes are available: 1 node(s) didn't match pod affinity/anti-affinity, 1 node(s) didn't satisfy existing pods anti-affinity rules.}]
Oct  4 06:37:15.081: INFO: 
Oct  4 06:37:17.135: INFO: The status of Pod coredns-7c949f49d5-p6f2z is Pending (Ready = false), waiting for it to be either Running (with Ready = true) or Failed
Oct  4 06:37:17.135: INFO: 10 / 11 pods in namespace 'kube-system' are running and ready (46 seconds elapsed)
Oct  4 06:37:17.135: INFO: expected 6 pod replicas in namespace 'kube-system', 5 are Running and Ready.
Oct  4 06:37:17.135: INFO: POD                       NODE  PHASE    GRACE  CONDITIONS
Oct  4 06:37:17.135: INFO: coredns-7c949f49d5-p6f2z        Pending         [{PodScheduled False 0001-01-01 00:00:00 +0000 UTC 2019-05-15 03:24:15 +0000 UTC Unschedulable 0/1 nodes are available: 1 node(s) didn't match pod affinity/anti-affinity, 1 node(s) didn't satisfy existing pods anti-affinity rules.}]
Oct  4 06:37:17.135: INFO: 
Oct  4 06:37:19.092: INFO: The status of Pod coredns-7c949f49d5-p6f2z is Pending (Ready = false), waiting for it to be either Running (with Ready = true) or Failed
Oct  4 06:37:19.092: INFO: 10 / 11 pods in namespace 'kube-system' are running and ready (48 seconds elapsed)
Oct  4 06:37:19.092: INFO: expected 6 pod replicas in namespace 'kube-system', 5 are Running and Ready.
Oct  4 06:37:19.092: INFO: POD                       NODE  PHASE    GRACE  CONDITIONS
Oct  4 06:37:19.092: INFO: coredns-7c949f49d5-p6f2z        Pending         [{PodScheduled False 0001-01-01 00:00:00 +0000 UTC 2019-05-15 03:24:15 +0000 UTC Unschedulable 0/1 nodes are available: 1 node(s) didn't match pod affinity/anti-affinity, 1 node(s) didn't satisfy existing pods anti-affinity rules.}]
Oct  4 06:37:19.092: INFO: 
Oct  4 06:37:21.093: INFO: The status of Pod coredns-7c949f49d5-p6f2z is Pending (Ready = false), waiting for it to be either Running (with Ready = true) or Failed
Oct  4 06:37:21.093: INFO: 10 / 11 pods in namespace 'kube-system' are running and ready (50 seconds elapsed)
Oct  4 06:37:21.093: INFO: expected 6 pod replicas in namespace 'kube-system', 5 are Running and Ready.
Oct  4 06:37:21.093: INFO: POD                       NODE  PHASE    GRACE  CONDITIONS
Oct  4 06:37:21.093: INFO: coredns-7c949f49d5-p6f2z        Pending         [{PodScheduled False 0001-01-01 00:00:00 +0000 UTC 2019-05-15 03:24:15 +0000 UTC Unschedulable 0/1 nodes are available: 1 node(s) didn't match pod affinity/anti-affinity, 1 node(s) didn't satisfy existing pods anti-affinity rules.}]
Oct  4 06:37:21.093: INFO: 
Oct  4 06:37:23.084: INFO: The status of Pod coredns-7c949f49d5-p6f2z is Pending (Ready = false), waiting for it to be either Running (with Ready = true) or Failed
Oct  4 06:37:23.084: INFO: 10 / 11 pods in namespace 'kube-system' are running and ready (52 seconds elapsed)
Oct  4 06:37:23.084: INFO: expected 6 pod replicas in namespace 'kube-system', 5 are Running and Ready.
Oct  4 06:37:23.084: INFO: POD                       NODE  PHASE    GRACE  CONDITIONS
Oct  4 06:37:23.084: INFO: coredns-7c949f49d5-p6f2z        Pending         [{PodScheduled False 0001-01-01 00:00:00 +0000 UTC 2019-05-15 03:24:15 +0000 UTC Unschedulable 0/1 nodes are available: 1 node(s) didn't match pod affinity/anti-affinity, 1 node(s) didn't satisfy existing pods anti-affinity rules.}]
Oct  4 06:37:23.084: INFO: 
Oct  4 06:37:25.081: INFO: The status of Pod coredns-7c949f49d5-p6f2z is Pending (Ready = false), waiting for it to be either Running (with Ready = true) or Failed
Oct  4 06:37:25.081: INFO: 10 / 11 pods in namespace 'kube-system' are running and ready (54 seconds elapsed)
Oct  4 06:37:25.081: INFO: expected 6 pod replicas in namespace 'kube-system', 5 are Running and Ready.
Oct  4 06:37:25.081: INFO: POD                       NODE  PHASE    GRACE  CONDITIONS
Oct  4 06:37:25.081: INFO: coredns-7c949f49d5-p6f2z        Pending         [{PodScheduled False 0001-01-01 00:00:00 +0000 UTC 2019-05-15 03:24:15 +0000 UTC Unschedulable 0/1 nodes are available: 1 node(s) didn't match pod affinity/anti-affinity, 1 node(s) didn't satisfy existing pods anti-affinity rules.}]
Oct  4 06:37:25.081: INFO: 
Oct  4 06:37:27.081: INFO: The status of Pod coredns-7c949f49d5-p6f2z is Pending (Ready = false), waiting for it to be either Running (with Ready = true) or Failed
Oct  4 06:37:27.081: INFO: 10 / 11 pods in namespace 'kube-system' are running and ready (56 seconds elapsed)
Oct  4 06:37:27.081: INFO: expected 6 pod replicas in namespace 'kube-system', 5 are Running and Ready.
Oct  4 06:37:27.081: INFO: POD                       NODE  PHASE    GRACE  CONDITIONS
Oct  4 06:37:27.081: INFO: coredns-7c949f49d5-p6f2z        Pending         [{PodScheduled False 0001-01-01 00:00:00 +0000 UTC 2019-05-15 03:24:15 +0000 UTC Unschedulable 0/1 nodes are available: 1 node(s) didn't match pod affinity/anti-affinity, 1 node(s) didn't satisfy existing pods anti-affinity rules.}]
Oct  4 06:37:27.081: INFO: 
Oct  4 06:37:29.084: INFO: The status of Pod coredns-7c949f49d5-p6f2z is Pending (Ready = false), waiting for it to be either Running (with Ready = true) or Failed
Oct  4 06:37:29.084: INFO: 10 / 11 pods in namespace 'kube-system' are running and ready (58 seconds elapsed)
Oct  4 06:37:29.084: INFO: expected 6 pod replicas in namespace 'kube-system', 5 are Running and Ready.
Oct  4 06:37:29.084: INFO: POD                       NODE  PHASE    GRACE  CONDITIONS
Oct  4 06:37:29.084: INFO: coredns-7c949f49d5-p6f2z        Pending         [{PodScheduled False 0001-01-01 00:00:00 +0000 UTC 2019-05-15 03:24:15 +0000 UTC Unschedulable 0/1 nodes are available: 1 node(s) didn't match pod affinity/anti-affinity, 1 node(s) didn't satisfy existing pods anti-affinity rules.}]
Oct  4 06:37:29.084: INFO: 
Oct  4 06:37:31.089: INFO: The status of Pod coredns-7c949f49d5-p6f2z is Pending (Ready = false), waiting for it to be either Running (with Ready = true) or Failed
Oct  4 06:37:31.089: INFO: 10 / 11 pods in namespace 'kube-system' are running and ready (60 seconds elapsed)
Oct  4 06:37:31.089: INFO: expected 6 pod replicas in namespace 'kube-system', 5 are Running and Ready.
Oct  4 06:37:31.089: INFO: POD                       NODE  PHASE    GRACE  CONDITIONS
Oct  4 06:37:31.089: INFO: coredns-7c949f49d5-p6f2z        Pending         [{PodScheduled False 0001-01-01 00:00:00 +0000 UTC 2019-05-15 03:24:15 +0000 UTC Unschedulable 0/1 nodes are available: 1 node(s) didn't match pod affinity/anti-affinity, 1 node(s) didn't satisfy existing pods anti-affinity rules.}]
Oct  4 06:37:31.089: INFO: 
Oct  4 06:37:33.081: INFO: The status of Pod coredns-7c949f49d5-p6f2z is Pending (Ready = false), waiting for it to be either Running (with Ready = true) or Failed
Oct  4 06:37:33.081: INFO: 10 / 11 pods in namespace 'kube-system' are running and ready (62 seconds elapsed)
Oct  4 06:37:33.081: INFO: expected 6 pod replicas in namespace 'kube-system', 5 are Running and Ready.
Oct  4 06:37:33.081: INFO: POD                       NODE  PHASE    GRACE  CONDITIONS
Oct  4 06:37:33.081: INFO: coredns-7c949f49d5-p6f2z        Pending         [{PodScheduled False 0001-01-01 00:00:00 +0000 UTC 2019-05-15 03:24:15 +0000 UTC Unschedulable 0/1 nodes are available: 1 node(s) didn't match pod affinity/anti-affinity, 1 node(s) didn't satisfy existing pods anti-affinity rules.}]
Oct  4 06:37:33.081: INFO: 
Oct  4 06:37:35.154: INFO: The status of Pod coredns-7c949f49d5-p6f2z is Pending (Ready = false), waiting for it to be either Running (with Ready = true) or Failed
Oct  4 06:37:35.154: INFO: 10 / 11 pods in namespace 'kube-system' are running and ready (64 seconds elapsed)
Oct  4 06:37:35.154: INFO: expected 6 pod replicas in namespace 'kube-system', 5 are Running and Ready.
Oct  4 06:37:35.154: INFO: POD                       NODE  PHASE    GRACE  CONDITIONS
Oct  4 06:37:35.154: INFO: coredns-7c949f49d5-p6f2z        Pending         [{PodScheduled False 0001-01-01 00:00:00 +0000 UTC 2019-05-15 03:24:15 +0000 UTC Unschedulable 0/1 nodes are available: 1 node(s) didn't match pod affinity/anti-affinity, 1 node(s) didn't satisfy existing pods anti-affinity rules.}]
Oct  4 06:37:35.154: INFO: 
Oct  4 06:37:37.112: INFO: The status of Pod coredns-7c949f49d5-p6f2z is Pending (Ready = false), waiting for it to be either Running (with Ready = true) or Failed
Oct  4 06:37:37.112: INFO: 10 / 11 pods in namespace 'kube-system' are running and ready (66 seconds elapsed)
Oct  4 06:37:37.112: INFO: expected 6 pod replicas in namespace 'kube-system', 5 are Running and Ready.
Oct  4 06:37:37.112: INFO: POD                       NODE  PHASE    GRACE  CONDITIONS
Oct  4 06:37:37.112: INFO: coredns-7c949f49d5-p6f2z        Pending         [{PodScheduled False 0001-01-01 00:00:00 +0000 UTC 2019-05-15 03:24:15 +0000 UTC Unschedulable 0/1 nodes are available: 1 node(s) didn't match pod affinity/anti-affinity, 1 node(s) didn't satisfy existing pods anti-affinity rules.}]
Oct  4 06:37:37.112: INFO: 
Oct  4 06:37:39.091: INFO: The status of Pod coredns-7c949f49d5-p6f2z is Pending (Ready = false), waiting for it to be either Running (with Ready = true) or Failed
Oct  4 06:37:39.091: INFO: 10 / 11 pods in namespace 'kube-system' are running and ready (68 seconds elapsed)
Oct  4 06:37:39.091: INFO: expected 6 pod replicas in namespace 'kube-system', 5 are Running and Ready.
Oct  4 06:37:39.091: INFO: POD                       NODE  PHASE    GRACE  CONDITIONS
Oct  4 06:37:39.091: INFO: coredns-7c949f49d5-p6f2z        Pending         [{PodScheduled False 0001-01-01 00:00:00 +0000 UTC 2019-05-15 03:24:15 +0000 UTC Unschedulable 0/1 nodes are available: 1 node(s) didn't match pod affinity/anti-affinity, 1 node(s) didn't satisfy existing pods anti-affinity rules.}]
Oct  4 06:37:39.091: INFO: 
Oct  4 06:37:41.083: INFO: The status of Pod coredns-7c949f49d5-p6f2z is Pending (Ready = false), waiting for it to be either Running (with Ready = true) or Failed
Oct  4 06:37:41.083: INFO: 10 / 11 pods in namespace 'kube-system' are running and ready (70 seconds elapsed)
Oct  4 06:37:41.083: INFO: expected 6 pod replicas in namespace 'kube-system', 5 are Running and Ready.
Oct  4 06:37:41.083: INFO: POD                       NODE  PHASE    GRACE  CONDITIONS
Oct  4 06:37:41.083: INFO: coredns-7c949f49d5-p6f2z        Pending         [{PodScheduled False 0001-01-01 00:00:00 +0000 UTC 2019-05-15 03:24:15 +0000 UTC Unschedulable 0/1 nodes are available: 1 node(s) didn't match pod affinity/anti-affinity, 1 node(s) didn't satisfy existing pods anti-affinity rules.}]
Oct  4 06:37:41.083: INFO: 
Oct  4 06:37:43.082: INFO: The status of Pod coredns-7c949f49d5-p6f2z is Pending (Ready = false), waiting for it to be either Running (with Ready = true) or Failed
Oct  4 06:37:43.082: INFO: 10 / 11 pods in namespace 'kube-system' are running and ready (72 seconds elapsed)
Oct  4 06:37:43.082: INFO: expected 6 pod replicas in namespace 'kube-system', 5 are Running and Ready.
Oct  4 06:37:43.082: INFO: POD                       NODE  PHASE    GRACE  CONDITIONS
Oct  4 06:37:43.082: INFO: coredns-7c949f49d5-p6f2z        Pending         [{PodScheduled False 0001-01-01 00:00:00 +0000 UTC 2019-05-15 03:24:15 +0000 UTC Unschedulable 0/1 nodes are available: 1 node(s) didn't match pod affinity/anti-affinity, 1 node(s) didn't satisfy existing pods anti-affinity rules.}]
Oct  4 06:37:43.082: INFO: 
Oct  4 06:37:45.081: INFO: The status of Pod coredns-7c949f49d5-p6f2z is Pending (Ready = false), waiting for it to be either Running (with Ready = true) or Failed
Oct  4 06:37:45.081: INFO: 10 / 11 pods in namespace 'kube-system' are running and ready (74 seconds elapsed)
Oct  4 06:37:45.081: INFO: expected 6 pod replicas in namespace 'kube-system', 5 are Running and Ready.
Oct  4 06:37:45.081: INFO: POD                       NODE  PHASE    GRACE  CONDITIONS
Oct  4 06:37:45.081: INFO: coredns-7c949f49d5-p6f2z        Pending         [{PodScheduled False 0001-01-01 00:00:00 +0000 UTC 2019-05-15 03:24:15 +0000 UTC Unschedulable 0/1 nodes are available: 1 node(s) didn't match pod affinity/anti-affinity, 1 node(s) didn't satisfy existing pods anti-affinity rules.}]
Oct  4 06:37:45.081: INFO: 
Oct  4 06:37:47.091: INFO: The status of Pod coredns-7c949f49d5-p6f2z is Pending (Ready = false), waiting for it to be either Running (with Ready = true) or Failed
Oct  4 06:37:47.091: INFO: 10 / 11 pods in namespace 'kube-system' are running and ready (76 seconds elapsed)
Oct  4 06:37:47.091: INFO: expected 6 pod replicas in namespace 'kube-system', 5 are Running and Ready.
Oct  4 06:37:47.091: INFO: POD                       NODE  PHASE    GRACE  CONDITIONS
Oct  4 06:37:47.091: INFO: coredns-7c949f49d5-p6f2z        Pending         [{PodScheduled False 0001-01-01 00:00:00 +0000 UTC 2019-05-15 03:24:15 +0000 UTC Unschedulable 0/1 nodes are available: 1 node(s) didn't match pod affinity/anti-affinity, 1 node(s) didn't satisfy existing pods anti-affinity rules.}]
Oct  4 06:37:47.091: INFO: 
Oct  4 06:37:49.089: INFO: The status of Pod coredns-7c949f49d5-p6f2z is Pending (Ready = false), waiting for it to be either Running (with Ready = true) or Failed
Oct  4 06:37:49.089: INFO: 10 / 11 pods in namespace 'kube-system' are running and ready (78 seconds elapsed)
Oct  4 06:37:49.089: INFO: expected 6 pod replicas in namespace 'kube-system', 5 are Running and Ready.
Oct  4 06:37:49.089: INFO: POD                       NODE  PHASE    GRACE  CONDITIONS
Oct  4 06:37:49.089: INFO: coredns-7c949f49d5-p6f2z        Pending         [{PodScheduled False 0001-01-01 00:00:00 +0000 UTC 2019-05-15 03:24:15 +0000 UTC Unschedulable 0/1 nodes are available: 1 node(s) didn't match pod affinity/anti-affinity, 1 node(s) didn't satisfy existing pods anti-affinity rules.}]
Oct  4 06:37:49.089: INFO: 
Oct  4 06:37:51.090: INFO: The status of Pod coredns-7c949f49d5-p6f2z is Pending (Ready = false), waiting for it to be either Running (with Ready = true) or Failed
Oct  4 06:37:51.090: INFO: 10 / 11 pods in namespace 'kube-system' are running and ready (80 seconds elapsed)
Oct  4 06:37:51.090: INFO: expected 6 pod replicas in namespace 'kube-system', 5 are Running and Ready.
Oct  4 06:37:51.090: INFO: POD                       NODE  PHASE    GRACE  CONDITIONS
Oct  4 06:37:51.090: INFO: coredns-7c949f49d5-p6f2z        Pending         [{PodScheduled False 0001-01-01 00:00:00 +0000 UTC 2019-05-15 03:24:15 +0000 UTC Unschedulable 0/1 nodes are available: 1 node(s) didn't match pod affinity/anti-affinity, 1 node(s) didn't satisfy existing pods anti-affinity rules.}]
Oct  4 06:37:51.090: INFO: 
Oct  4 06:37:53.082: INFO: The status of Pod coredns-7c949f49d5-p6f2z is Pending (Ready = false), waiting for it to be either Running (with Ready = true) or Failed
Oct  4 06:37:53.082: INFO: 10 / 11 pods in namespace 'kube-system' are running and ready (82 seconds elapsed)
Oct  4 06:37:53.082: INFO: expected 6 pod replicas in namespace 'kube-system', 5 are Running and Ready.
Oct  4 06:37:53.082: INFO: POD                       NODE  PHASE    GRACE  CONDITIONS
Oct  4 06:37:53.082: INFO: coredns-7c949f49d5-p6f2z        Pending         [{PodScheduled False 0001-01-01 00:00:00 +0000 UTC 2019-05-15 03:24:15 +0000 UTC Unschedulable 0/1 nodes are available: 1 node(s) didn't match pod affinity/anti-affinity, 1 node(s) didn't satisfy existing pods anti-affinity rules.}]
Oct  4 06:37:53.082: INFO: 
Oct  4 06:37:55.082: INFO: The status of Pod coredns-7c949f49d5-p6f2z is Pending (Ready = false), waiting for it to be either Running (with Ready = true) or Failed
Oct  4 06:37:55.082: INFO: 10 / 11 pods in namespace 'kube-system' are running and ready (84 seconds elapsed)
Oct  4 06:37:55.082: INFO: expected 6 pod replicas in namespace 'kube-system', 5 are Running and Ready.
Oct  4 06:37:55.082: INFO: POD                       NODE  PHASE    GRACE  CONDITIONS
Oct  4 06:37:55.082: INFO: coredns-7c949f49d5-p6f2z        Pending         [{PodScheduled False 0001-01-01 00:00:00 +0000 UTC 2019-05-15 03:24:15 +0000 UTC Unschedulable 0/1 nodes are available: 1 node(s) didn't match pod affinity/anti-affinity, 1 node(s) didn't satisfy existing pods anti-affinity rules.}]
Oct  4 06:37:55.082: INFO: 
Oct  4 06:37:57.092: INFO: The status of Pod coredns-7c949f49d5-p6f2z is Pending (Ready = false), waiting for it to be either Running (with Ready = true) or Failed
Oct  4 06:37:57.092: INFO: 10 / 11 pods in namespace 'kube-system' are running and ready (86 seconds elapsed)
Oct  4 06:37:57.092: INFO: expected 6 pod replicas in namespace 'kube-system', 5 are Running and Ready.
Oct  4 06:37:57.092: INFO: POD                       NODE  PHASE    GRACE  CONDITIONS
Oct  4 06:37:57.092: INFO: coredns-7c949f49d5-p6f2z        Pending         [{PodScheduled False 0001-01-01 00:00:00 +0000 UTC 2019-05-15 03:24:15 +0000 UTC Unschedulable 0/1 nodes are available: 1 node(s) didn't match pod affinity/anti-affinity, 1 node(s) didn't satisfy existing pods anti-affinity rules.}]
Oct  4 06:37:57.092: INFO: 
Oct  4 06:37:59.091: INFO: The status of Pod coredns-7c949f49d5-p6f2z is Pending (Ready = false), waiting for it to be either Running (with Ready = true) or Failed
Oct  4 06:37:59.091: INFO: 10 / 11 pods in namespace 'kube-system' are running and ready (88 seconds elapsed)
Oct  4 06:37:59.091: INFO: expected 6 pod replicas in namespace 'kube-system', 5 are Running and Ready.
Oct  4 06:37:59.091: INFO: POD                       NODE  PHASE    GRACE  CONDITIONS
Oct  4 06:37:59.091: INFO: coredns-7c949f49d5-p6f2z        Pending         [{PodScheduled False 0001-01-01 00:00:00 +0000 UTC 2019-05-15 03:24:15 +0000 UTC Unschedulable 0/1 nodes are available: 1 node(s) didn't match pod affinity/anti-affinity, 1 node(s) didn't satisfy existing pods anti-affinity rules.}]
Oct  4 06:37:59.091: INFO: 
Oct  4 06:38:01.091: INFO: The status of Pod coredns-7c949f49d5-p6f2z is Pending (Ready = false), waiting for it to be either Running (with Ready = true) or Failed
Oct  4 06:38:01.091: INFO: 10 / 11 pods in namespace 'kube-system' are running and ready (90 seconds elapsed)
Oct  4 06:38:01.091: INFO: expected 6 pod replicas in namespace 'kube-system', 5 are Running and Ready.
Oct  4 06:38:01.091: INFO: POD                       NODE  PHASE    GRACE  CONDITIONS
Oct  4 06:38:01.091: INFO: coredns-7c949f49d5-p6f2z        Pending         [{PodScheduled False 0001-01-01 00:00:00 +0000 UTC 2019-05-15 03:24:15 +0000 UTC Unschedulable 0/1 nodes are available: 1 node(s) didn't match pod affinity/anti-affinity, 1 node(s) didn't satisfy existing pods anti-affinity rules.}]
Oct  4 06:38:01.091: INFO: 
Oct  4 06:38:03.143: INFO: The status of Pod coredns-7c949f49d5-p6f2z is Pending (Ready = false), waiting for it to be either Running (with Ready = true) or Failed
Oct  4 06:38:03.143: INFO: 10 / 11 pods in namespace 'kube-system' are running and ready (92 seconds elapsed)
Oct  4 06:38:03.143: INFO: expected 6 pod replicas in namespace 'kube-system', 5 are Running and Ready.
Oct  4 06:38:03.143: INFO: POD                       NODE  PHASE    GRACE  CONDITIONS
Oct  4 06:38:03.143: INFO: coredns-7c949f49d5-p6f2z        Pending         [{PodScheduled False 0001-01-01 00:00:00 +0000 UTC 2019-05-15 03:24:15 +0000 UTC Unschedulable 0/1 nodes are available: 1 node(s) didn't match pod affinity/anti-affinity, 1 node(s) didn't satisfy existing pods anti-affinity rules.}]
Oct  4 06:38:03.143: INFO: 
Oct  4 06:38:05.093: INFO: The status of Pod coredns-7c949f49d5-p6f2z is Pending (Ready = false), waiting for it to be either Running (with Ready = true) or Failed
Oct  4 06:38:05.093: INFO: 10 / 11 pods in namespace 'kube-system' are running and ready (94 seconds elapsed)
Oct  4 06:38:05.093: INFO: expected 6 pod replicas in namespace 'kube-system', 5 are Running and Ready.
Oct  4 06:38:05.093: INFO: POD                       NODE  PHASE    GRACE  CONDITIONS
Oct  4 06:38:05.093: INFO: coredns-7c949f49d5-p6f2z        Pending         [{PodScheduled False 0001-01-01 00:00:00 +0000 UTC 2019-05-15 03:24:15 +0000 UTC Unschedulable 0/1 nodes are available: 1 node(s) didn't match pod affinity/anti-affinity, 1 node(s) didn't satisfy existing pods anti-affinity rules.}]
Oct  4 06:38:05.093: INFO: 
Oct  4 06:38:07.082: INFO: The status of Pod coredns-7c949f49d5-p6f2z is Pending (Ready = false), waiting for it to be either Running (with Ready = true) or Failed
Oct  4 06:38:07.082: INFO: 10 / 11 pods in namespace 'kube-system' are running and ready (96 seconds elapsed)
Oct  4 06:38:07.082: INFO: expected 6 pod replicas in namespace 'kube-system', 5 are Running and Ready.
Oct  4 06:38:07.082: INFO: POD                       NODE  PHASE    GRACE  CONDITIONS
Oct  4 06:38:07.082: INFO: coredns-7c949f49d5-p6f2z        Pending         [{PodScheduled False 0001-01-01 00:00:00 +0000 UTC 2019-05-15 03:24:15 +0000 UTC Unschedulable 0/1 nodes are available: 1 node(s) didn't match pod affinity/anti-affinity, 1 node(s) didn't satisfy existing pods anti-affinity rules.}]
Oct  4 06:38:07.083: INFO: 
Oct  4 06:38:09.091: INFO: The status of Pod coredns-7c949f49d5-p6f2z is Pending (Ready = false), waiting for it to be either Running (with Ready = true) or Failed
Oct  4 06:38:09.091: INFO: 10 / 11 pods in namespace 'kube-system' are running and ready (98 seconds elapsed)
Oct  4 06:38:09.091: INFO: expected 6 pod replicas in namespace 'kube-system', 5 are Running and Ready.
Oct  4 06:38:09.091: INFO: POD                       NODE  PHASE    GRACE  CONDITIONS
Oct  4 06:38:09.091: INFO: coredns-7c949f49d5-p6f2z        Pending         [{PodScheduled False 0001-01-01 00:00:00 +0000 UTC 2019-05-15 03:24:15 +0000 UTC Unschedulable 0/1 nodes are available: 1 node(s) didn't match pod affinity/anti-affinity, 1 node(s) didn't satisfy existing pods anti-affinity rules.}]
Oct  4 06:38:09.091: INFO: 
Oct  4 06:38:11.081: INFO: The status of Pod coredns-7c949f49d5-p6f2z is Pending (Ready = false), waiting for it to be either Running (with Ready = true) or Failed
Oct  4 06:38:11.081: INFO: 10 / 11 pods in namespace 'kube-system' are running and ready (100 seconds elapsed)
Oct  4 06:38:11.081: INFO: expected 6 pod replicas in namespace 'kube-system', 5 are Running and Ready.
Oct  4 06:38:11.081: INFO: POD                       NODE  PHASE    GRACE  CONDITIONS
Oct  4 06:38:11.081: INFO: coredns-7c949f49d5-p6f2z        Pending         [{PodScheduled False 0001-01-01 00:00:00 +0000 UTC 2019-05-15 03:24:15 +0000 UTC Unschedulable 0/1 nodes are available: 1 node(s) didn't match pod affinity/anti-affinity, 1 node(s) didn't satisfy existing pods anti-affinity rules.}]
Oct  4 06:38:11.081: INFO: 
Oct  4 06:38:13.082: INFO: The status of Pod coredns-7c949f49d5-p6f2z is Pending (Ready = false), waiting for it to be either Running (with Ready = true) or Failed
Oct  4 06:38:13.082: INFO: 10 / 11 pods in namespace 'kube-system' are running and ready (102 seconds elapsed)
Oct  4 06:38:13.082: INFO: expected 6 pod replicas in namespace 'kube-system', 5 are Running and Ready.
Oct  4 06:38:13.082: INFO: POD                       NODE  PHASE    GRACE  CONDITIONS
Oct  4 06:38:13.082: INFO: coredns-7c949f49d5-p6f2z        Pending         [{PodScheduled False 0001-01-01 00:00:00 +0000 UTC 2019-05-15 03:24:15 +0000 UTC Unschedulable 0/1 nodes are available: 1 node(s) didn't match pod affinity/anti-affinity, 1 node(s) didn't satisfy existing pods anti-affinity rules.}]
Oct  4 06:38:13.082: INFO: 
Oct  4 06:38:15.167: INFO: The status of Pod coredns-7c949f49d5-p6f2z is Pending (Ready = false), waiting for it to be either Running (with Ready = true) or Failed
Oct  4 06:38:15.167: INFO: 10 / 11 pods in namespace 'kube-system' are running and ready (104 seconds elapsed)
Oct  4 06:38:15.167: INFO: expected 6 pod replicas in namespace 'kube-system', 5 are Running and Ready.
Oct  4 06:38:15.167: INFO: POD                       NODE  PHASE    GRACE  CONDITIONS
Oct  4 06:38:15.167: INFO: coredns-7c949f49d5-p6f2z        Pending         [{PodScheduled False 0001-01-01 00:00:00 +0000 UTC 2019-05-15 03:24:15 +0000 UTC Unschedulable 0/1 nodes are available: 1 node(s) didn't match pod affinity/anti-affinity, 1 node(s) didn't satisfy existing pods anti-affinity rules.}]
Oct  4 06:38:15.167: INFO: 
Oct  4 06:38:17.091: INFO: The status of Pod coredns-7c949f49d5-p6f2z is Pending (Ready = false), waiting for it to be either Running (with Ready = true) or Failed
Oct  4 06:38:17.091: INFO: 10 / 11 pods in namespace 'kube-system' are running and ready (106 seconds elapsed)
Oct  4 06:38:17.091: INFO: expected 6 pod replicas in namespace 'kube-system', 5 are Running and Ready.
Oct  4 06:38:17.091: INFO: POD                       NODE  PHASE    GRACE  CONDITIONS
Oct  4 06:38:17.091: INFO: coredns-7c949f49d5-p6f2z        Pending         [{PodScheduled False 0001-01-01 00:00:00 +0000 UTC 2019-05-15 03:24:15 +0000 UTC Unschedulable 0/1 nodes are available: 1 node(s) didn't match pod affinity/anti-affinity, 1 node(s) didn't satisfy existing pods anti-affinity rules.}]
Oct  4 06:38:17.091: INFO: 
Oct  4 06:38:19.083: INFO: The status of Pod coredns-7c949f49d5-p6f2z is Pending (Ready = false), waiting for it to be either Running (with Ready = true) or Failed
Oct  4 06:38:19.083: INFO: 10 / 11 pods in namespace 'kube-system' are running and ready (108 seconds elapsed)
Oct  4 06:38:19.083: INFO: expected 6 pod replicas in namespace 'kube-system', 5 are Running and Ready.
Oct  4 06:38:19.083: INFO: POD                       NODE  PHASE    GRACE  CONDITIONS
Oct  4 06:38:19.083: INFO: coredns-7c949f49d5-p6f2z        Pending         [{PodScheduled False 0001-01-01 00:00:00 +0000 UTC 2019-05-15 03:24:15 +0000 UTC Unschedulable 0/1 nodes are available: 1 node(s) didn't match pod affinity/anti-affinity, 1 node(s) didn't satisfy existing pods anti-affinity rules.}]
Oct  4 06:38:19.083: INFO: 
Oct  4 06:38:21.081: INFO: The status of Pod coredns-7c949f49d5-p6f2z is Pending (Ready = false), waiting for it to be either Running (with Ready = true) or Failed
Oct  4 06:38:21.081: INFO: 10 / 11 pods in namespace 'kube-system' are running and ready (110 seconds elapsed)
Oct  4 06:38:21.081: INFO: expected 6 pod replicas in namespace 'kube-system', 5 are Running and Ready.
Oct  4 06:38:21.081: INFO: POD                       NODE  PHASE    GRACE  CONDITIONS
Oct  4 06:38:21.081: INFO: coredns-7c949f49d5-p6f2z        Pending         [{PodScheduled False 0001-01-01 00:00:00 +0000 UTC 2019-05-15 03:24:15 +0000 UTC Unschedulable 0/1 nodes are available: 1 node(s) didn't match pod affinity/anti-affinity, 1 node(s) didn't satisfy existing pods anti-affinity rules.}]
Oct  4 06:38:21.081: INFO: 
Oct  4 06:38:23.245: INFO: The status of Pod coredns-7c949f49d5-p6f2z is Pending (Ready = false), waiting for it to be either Running (with Ready = true) or Failed
Oct  4 06:38:23.246: INFO: 10 / 11 pods in namespace 'kube-system' are running and ready (112 seconds elapsed)
Oct  4 06:38:23.246: INFO: expected 6 pod replicas in namespace 'kube-system', 5 are Running and Ready.
Oct  4 06:38:23.246: INFO: POD                       NODE  PHASE    GRACE  CONDITIONS
Oct  4 06:38:23.246: INFO: coredns-7c949f49d5-p6f2z        Pending         [{PodScheduled False 0001-01-01 00:00:00 +0000 UTC 2019-05-15 03:24:15 +0000 UTC Unschedulable 0/1 nodes are available: 1 node(s) didn't match pod affinity/anti-affinity, 1 node(s) didn't satisfy existing pods anti-affinity rules.}]
Oct  4 06:38:23.246: INFO: 
Oct  4 06:38:25.438: INFO: The status of Pod coredns-7c949f49d5-p6f2z is Pending (Ready = false), waiting for it to be either Running (with Ready = true) or Failed
Oct  4 06:38:25.438: INFO: 10 / 11 pods in namespace 'kube-system' are running and ready (114 seconds elapsed)
Oct  4 06:38:25.438: INFO: expected 6 pod replicas in namespace 'kube-system', 5 are Running and Ready.
Oct  4 06:38:25.438: INFO: POD                       NODE  PHASE    GRACE  CONDITIONS
Oct  4 06:38:25.438: INFO: coredns-7c949f49d5-p6f2z        Pending         [{PodScheduled False 0001-01-01 00:00:00 +0000 UTC 2019-05-15 03:24:15 +0000 UTC Unschedulable 0/1 nodes are available: 1 node(s) didn't match pod affinity/anti-affinity, 1 node(s) didn't satisfy existing pods anti-affinity rules.}]
Oct  4 06:38:25.438: INFO: 
Oct  4 06:38:27.091: INFO: The status of Pod coredns-7c949f49d5-p6f2z is Pending (Ready = false), waiting for it to be either Running (with Ready = true) or Failed
Oct  4 06:38:27.091: INFO: 10 / 11 pods in namespace 'kube-system' are running and ready (116 seconds elapsed)
Oct  4 06:38:27.091: INFO: expected 6 pod replicas in namespace 'kube-system', 5 are Running and Ready.
Oct  4 06:38:27.091: INFO: POD                       NODE  PHASE    GRACE  CONDITIONS
Oct  4 06:38:27.091: INFO: coredns-7c949f49d5-p6f2z        Pending         [{PodScheduled False 0001-01-01 00:00:00 +0000 UTC 2019-05-15 03:24:15 +0000 UTC Unschedulable 0/1 nodes are available: 1 node(s) didn't match pod affinity/anti-affinity, 1 node(s) didn't satisfy existing pods anti-affinity rules.}]
Oct  4 06:38:27.091: INFO: 
Oct  4 06:38:29.115: INFO: The status of Pod coredns-7c949f49d5-p6f2z is Pending (Ready = false), waiting for it to be either Running (with Ready = true) or Failed
Oct  4 06:38:29.115: INFO: 10 / 11 pods in namespace 'kube-system' are running and ready (118 seconds elapsed)
Oct  4 06:38:29.115: INFO: expected 6 pod replicas in namespace 'kube-system', 5 are Running and Ready.
Oct  4 06:38:29.115: INFO: POD                       NODE  PHASE    GRACE  CONDITIONS
Oct  4 06:38:29.115: INFO: coredns-7c949f49d5-p6f2z        Pending         [{PodScheduled False 0001-01-01 00:00:00 +0000 UTC 2019-05-15 03:24:15 +0000 UTC Unschedulable 0/1 nodes are available: 1 node(s) didn't match pod affinity/anti-affinity, 1 node(s) didn't satisfy existing pods anti-affinity rules.}]
Oct  4 06:38:29.115: INFO: 
Oct  4 06:38:31.146: INFO: The status of Pod coredns-7c949f49d5-p6f2z is Pending (Ready = false), waiting for it to be either Running (with Ready = true) or Failed
Oct  4 06:38:31.146: INFO: 10 / 11 pods in namespace 'kube-system' are running and ready (120 seconds elapsed)
Oct  4 06:38:31.146: INFO: expected 6 pod replicas in namespace 'kube-system', 5 are Running and Ready.
Oct  4 06:38:31.146: INFO: POD                       NODE  PHASE    GRACE  CONDITIONS
Oct  4 06:38:31.146: INFO: coredns-7c949f49d5-p6f2z        Pending         [{PodScheduled False 0001-01-01 00:00:00 +0000 UTC 2019-05-15 03:24:15 +0000 UTC Unschedulable 0/1 nodes are available: 1 node(s) didn't match pod affinity/anti-affinity, 1 node(s) didn't satisfy existing pods anti-affinity rules.}]
Oct  4 06:38:31.146: INFO: 
Oct  4 06:38:33.083: INFO: The status of Pod coredns-7c949f49d5-p6f2z is Pending (Ready = false), waiting for it to be either Running (with Ready = true) or Failed
Oct  4 06:38:33.083: INFO: 10 / 11 pods in namespace 'kube-system' are running and ready (122 seconds elapsed)
Oct  4 06:38:33.083: INFO: expected 6 pod replicas in namespace 'kube-system', 5 are Running and Ready.
Oct  4 06:38:33.083: INFO: POD                       NODE  PHASE    GRACE  CONDITIONS
Oct  4 06:38:33.083: INFO: coredns-7c949f49d5-p6f2z        Pending         [{PodScheduled False 0001-01-01 00:00:00 +0000 UTC 2019-05-15 03:24:15 +0000 UTC Unschedulable 0/1 nodes are available: 1 node(s) didn't match pod affinity/anti-affinity, 1 node(s) didn't satisfy existing pods anti-affinity rules.}]
Oct  4 06:38:33.083: INFO: 
Oct  4 06:38:35.081: INFO: The status of Pod coredns-7c949f49d5-p6f2z is Pending (Ready = false), waiting for it to be either Running (with Ready = true) or Failed
Oct  4 06:38:35.081: INFO: 10 / 11 pods in namespace 'kube-system' are running and ready (124 seconds elapsed)
Oct  4 06:38:35.081: INFO: expected 6 pod replicas in namespace 'kube-system', 5 are Running and Ready.
Oct  4 06:38:35.081: INFO: POD                       NODE  PHASE    GRACE  CONDITIONS
Oct  4 06:38:35.081: INFO: coredns-7c949f49d5-p6f2z        Pending         [{PodScheduled False 0001-01-01 00:00:00 +0000 UTC 2019-05-15 03:24:15 +0000 UTC Unschedulable 0/1 nodes are available: 1 node(s) didn't match pod affinity/anti-affinity, 1 node(s) didn't satisfy existing pods anti-affinity rules.}]
Oct  4 06:38:35.081: INFO: 
Oct  4 06:38:37.088: INFO: The status of Pod coredns-7c949f49d5-p6f2z is Pending (Ready = false), waiting for it to be either Running (with Ready = true) or Failed
Oct  4 06:38:37.088: INFO: 10 / 11 pods in namespace 'kube-system' are running and ready (126 seconds elapsed)
Oct  4 06:38:37.088: INFO: expected 6 pod replicas in namespace 'kube-system', 5 are Running and Ready.
Oct  4 06:38:37.088: INFO: POD                       NODE  PHASE    GRACE  CONDITIONS
Oct  4 06:38:37.088: INFO: coredns-7c949f49d5-p6f2z        Pending         [{PodScheduled False 0001-01-01 00:00:00 +0000 UTC 2019-05-15 03:24:15 +0000 UTC Unschedulable 0/1 nodes are available: 1 node(s) didn't match pod affinity/anti-affinity, 1 node(s) didn't satisfy existing pods anti-affinity rules.}]
Oct  4 06:38:37.089: INFO: 
Oct  4 06:38:39.116: INFO: The status of Pod coredns-7c949f49d5-p6f2z is Pending (Ready = false), waiting for it to be either Running (with Ready = true) or Failed
Oct  4 06:38:39.116: INFO: 10 / 11 pods in namespace 'kube-system' are running and ready (128 seconds elapsed)
Oct  4 06:38:39.116: INFO: expected 6 pod replicas in namespace 'kube-system', 5 are Running and Ready.
Oct  4 06:38:39.116: INFO: POD                       NODE  PHASE    GRACE  CONDITIONS
Oct  4 06:38:39.116: INFO: coredns-7c949f49d5-p6f2z        Pending         [{PodScheduled False 0001-01-01 00:00:00 +0000 UTC 2019-05-15 03:24:15 +0000 UTC Unschedulable 0/1 nodes are available: 1 node(s) didn't match pod affinity/anti-affinity, 1 node(s) didn't satisfy existing pods anti-affinity rules.}]
Oct  4 06:38:39.116: INFO: 
Oct  4 06:38:41.090: INFO: The status of Pod coredns-7c949f49d5-p6f2z is Pending (Ready = false), waiting for it to be either Running (with Ready = true) or Failed
Oct  4 06:38:41.090: INFO: 10 / 11 pods in namespace 'kube-system' are running and ready (130 seconds elapsed)
Oct  4 06:38:41.090: INFO: expected 6 pod replicas in namespace 'kube-system', 5 are Running and Ready.
Oct  4 06:38:41.090: INFO: POD                       NODE  PHASE    GRACE  CONDITIONS
Oct  4 06:38:41.090: INFO: coredns-7c949f49d5-p6f2z        Pending         [{PodScheduled False 0001-01-01 00:00:00 +0000 UTC 2019-05-15 03:24:15 +0000 UTC Unschedulable 0/1 nodes are available: 1 node(s) didn't match pod affinity/anti-affinity, 1 node(s) didn't satisfy existing pods anti-affinity rules.}]
Oct  4 06:38:41.090: INFO: 
Oct  4 06:38:43.130: INFO: The status of Pod coredns-7c949f49d5-p6f2z is Pending (Ready = false), waiting for it to be either Running (with Ready = true) or Failed
Oct  4 06:38:43.130: INFO: 10 / 11 pods in namespace 'kube-system' are running and ready (132 seconds elapsed)
Oct  4 06:38:43.130: INFO: expected 6 pod replicas in namespace 'kube-system', 5 are Running and Ready.
Oct  4 06:38:43.130: INFO: POD                       NODE  PHASE    GRACE  CONDITIONS
Oct  4 06:38:43.130: INFO: coredns-7c949f49d5-p6f2z        Pending         [{PodScheduled False 0001-01-01 00:00:00 +0000 UTC 2019-05-15 03:24:15 +0000 UTC Unschedulable 0/1 nodes are available: 1 node(s) didn't match pod affinity/anti-affinity, 1 node(s) didn't satisfy existing pods anti-affinity rules.}]
Oct  4 06:38:43.130: INFO: 
Oct  4 06:38:45.081: INFO: The status of Pod coredns-7c949f49d5-p6f2z is Pending (Ready = false), waiting for it to be either Running (with Ready = true) or Failed
Oct  4 06:38:45.081: INFO: 10 / 11 pods in namespace 'kube-system' are running and ready (134 seconds elapsed)
Oct  4 06:38:45.081: INFO: expected 6 pod replicas in namespace 'kube-system', 5 are Running and Ready.
Oct  4 06:38:45.081: INFO: POD                       NODE  PHASE    GRACE  CONDITIONS
Oct  4 06:38:45.081: INFO: coredns-7c949f49d5-p6f2z        Pending         [{PodScheduled False 0001-01-01 00:00:00 +0000 UTC 2019-05-15 03:24:15 +0000 UTC Unschedulable 0/1 nodes are available: 1 node(s) didn't match pod affinity/anti-affinity, 1 node(s) didn't satisfy existing pods anti-affinity rules.}]
Oct  4 06:38:45.081: INFO: 
Oct  4 06:38:47.089: INFO: The status of Pod coredns-7c949f49d5-p6f2z is Pending (Ready = false), waiting for it to be either Running (with Ready = true) or Failed
Oct  4 06:38:47.089: INFO: 10 / 11 pods in namespace 'kube-system' are running and ready (136 seconds elapsed)
Oct  4 06:38:47.089: INFO: expected 6 pod replicas in namespace 'kube-system', 5 are Running and Ready.
Oct  4 06:38:47.089: INFO: POD                       NODE  PHASE    GRACE  CONDITIONS
Oct  4 06:38:47.089: INFO: coredns-7c949f49d5-p6f2z        Pending         [{PodScheduled False 0001-01-01 00:00:00 +0000 UTC 2019-05-15 03:24:15 +0000 UTC Unschedulable 0/1 nodes are available: 1 node(s) didn't match pod affinity/anti-affinity, 1 node(s) didn't satisfy existing pods anti-affinity rules.}]
Oct  4 06:38:47.089: INFO: 
Oct  4 06:38:49.097: INFO: The status of Pod coredns-7c949f49d5-p6f2z is Pending (Ready = false), waiting for it to be either Running (with Ready = true) or Failed
Oct  4 06:38:49.097: INFO: 10 / 11 pods in namespace 'kube-system' are running and ready (138 seconds elapsed)
Oct  4 06:38:49.097: INFO: expected 6 pod replicas in namespace 'kube-system', 5 are Running and Ready.
Oct  4 06:38:49.097: INFO: POD                       NODE  PHASE    GRACE  CONDITIONS
Oct  4 06:38:49.097: INFO: coredns-7c949f49d5-p6f2z        Pending         [{PodScheduled False 0001-01-01 00:00:00 +0000 UTC 2019-05-15 03:24:15 +0000 UTC Unschedulable 0/1 nodes are available: 1 node(s) didn't match pod affinity/anti-affinity, 1 node(s) didn't satisfy existing pods anti-affinity rules.}]
Oct  4 06:38:49.097: INFO: 
Oct  4 06:38:51.081: INFO: The status of Pod coredns-7c949f49d5-p6f2z is Pending (Ready = false), waiting for it to be either Running (with Ready = true) or Failed
Oct  4 06:38:51.081: INFO: 10 / 11 pods in namespace 'kube-system' are running and ready (140 seconds elapsed)
Oct  4 06:38:51.081: INFO: expected 6 pod replicas in namespace 'kube-system', 5 are Running and Ready.
Oct  4 06:38:51.081: INFO: POD                       NODE  PHASE    GRACE  CONDITIONS
Oct  4 06:38:51.081: INFO: coredns-7c949f49d5-p6f2z        Pending         [{PodScheduled False 0001-01-01 00:00:00 +0000 UTC 2019-05-15 03:24:15 +0000 UTC Unschedulable 0/1 nodes are available: 1 node(s) didn't match pod affinity/anti-affinity, 1 node(s) didn't satisfy existing pods anti-affinity rules.}]
Oct  4 06:38:51.081: INFO: 
Oct  4 06:38:53.082: INFO: The status of Pod coredns-7c949f49d5-p6f2z is Pending (Ready = false), waiting for it to be either Running (with Ready = true) or Failed
Oct  4 06:38:53.082: INFO: 10 / 11 pods in namespace 'kube-system' are running and ready (142 seconds elapsed)
Oct  4 06:38:53.082: INFO: expected 6 pod replicas in namespace 'kube-system', 5 are Running and Ready.
Oct  4 06:38:53.082: INFO: POD                       NODE  PHASE    GRACE  CONDITIONS
Oct  4 06:38:53.082: INFO: coredns-7c949f49d5-p6f2z        Pending         [{PodScheduled False 0001-01-01 00:00:00 +0000 UTC 2019-05-15 03:24:15 +0000 UTC Unschedulable 0/1 nodes are available: 1 node(s) didn't match pod affinity/anti-affinity, 1 node(s) didn't satisfy existing pods anti-affinity rules.}]
Oct  4 06:38:53.082: INFO: 
Oct  4 06:38:55.081: INFO: The status of Pod coredns-7c949f49d5-p6f2z is Pending (Ready = false), waiting for it to be either Running (with Ready = true) or Failed
Oct  4 06:38:55.081: INFO: 10 / 11 pods in namespace 'kube-system' are running and ready (144 seconds elapsed)
Oct  4 06:38:55.081: INFO: expected 6 pod replicas in namespace 'kube-system', 5 are Running and Ready.
Oct  4 06:38:55.081: INFO: POD                       NODE  PHASE    GRACE  CONDITIONS
Oct  4 06:38:55.081: INFO: coredns-7c949f49d5-p6f2z        Pending         [{PodScheduled False 0001-01-01 00:00:00 +0000 UTC 2019-05-15 03:24:15 +0000 UTC Unschedulable 0/1 nodes are available: 1 node(s) didn't match pod affinity/anti-affinity, 1 node(s) didn't satisfy existing pods anti-affinity rules.}]
Oct  4 06:38:55.081: INFO: 
Oct  4 06:38:57.294: INFO: The status of Pod coredns-7c949f49d5-p6f2z is Pending (Ready = false), waiting for it to be either Running (with Ready = true) or Failed
Oct  4 06:38:57.294: INFO: 10 / 11 pods in namespace 'kube-system' are running and ready (146 seconds elapsed)
Oct  4 06:38:57.294: INFO: expected 6 pod replicas in namespace 'kube-system', 5 are Running and Ready.
Oct  4 06:38:57.294: INFO: POD                       NODE  PHASE    GRACE  CONDITIONS
Oct  4 06:38:57.294: INFO: coredns-7c949f49d5-p6f2z        Pending         [{PodScheduled False 0001-01-01 00:00:00 +0000 UTC 2019-05-15 03:24:15 +0000 UTC Unschedulable 0/1 nodes are available: 1 node(s) didn't match pod affinity/anti-affinity, 1 node(s) didn't satisfy existing pods anti-affinity rules.}]
Oct  4 06:38:57.294: INFO: 
Oct  4 06:38:59.091: INFO: The status of Pod coredns-7c949f49d5-p6f2z is Pending (Ready = false), waiting for it to be either Running (with Ready = true) or Failed
Oct  4 06:38:59.091: INFO: 10 / 11 pods in namespace 'kube-system' are running and ready (148 seconds elapsed)
Oct  4 06:38:59.091: INFO: expected 6 pod replicas in namespace 'kube-system', 5 are Running and Ready.
Oct  4 06:38:59.091: INFO: POD                       NODE  PHASE    GRACE  CONDITIONS
Oct  4 06:38:59.091: INFO: coredns-7c949f49d5-p6f2z        Pending         [{PodScheduled False 0001-01-01 00:00:00 +0000 UTC 2019-05-15 03:24:15 +0000 UTC Unschedulable 0/1 nodes are available: 1 node(s) didn't match pod affinity/anti-affinity, 1 node(s) didn't satisfy existing pods anti-affinity rules.}]
Oct  4 06:38:59.091: INFO: 
Oct  4 06:39:01.089: INFO: The status of Pod coredns-7c949f49d5-p6f2z is Pending (Ready = false), waiting for it to be either Running (with Ready = true) or Failed
Oct  4 06:39:01.089: INFO: 10 / 11 pods in namespace 'kube-system' are running and ready (150 seconds elapsed)
Oct  4 06:39:01.089: INFO: expected 6 pod replicas in namespace 'kube-system', 5 are Running and Ready.
Oct  4 06:39:01.089: INFO: POD                       NODE  PHASE    GRACE  CONDITIONS
Oct  4 06:39:01.089: INFO: coredns-7c949f49d5-p6f2z        Pending         [{PodScheduled False 0001-01-01 00:00:00 +0000 UTC 2019-05-15 03:24:15 +0000 UTC Unschedulable 0/1 nodes are available: 1 node(s) didn't match pod affinity/anti-affinity, 1 node(s) didn't satisfy existing pods anti-affinity rules.}]
Oct  4 06:39:01.089: INFO: 
Oct  4 06:39:03.086: INFO: The status of Pod coredns-7c949f49d5-p6f2z is Pending (Ready = false), waiting for it to be either Running (with Ready = true) or Failed
Oct  4 06:39:03.086: INFO: 10 / 11 pods in namespace 'kube-system' are running and ready (152 seconds elapsed)
Oct  4 06:39:03.086: INFO: expected 6 pod replicas in namespace 'kube-system', 5 are Running and Ready.
Oct  4 06:39:03.086: INFO: POD                       NODE  PHASE    GRACE  CONDITIONS
Oct  4 06:39:03.086: INFO: coredns-7c949f49d5-p6f2z        Pending         [{PodScheduled False 0001-01-01 00:00:00 +0000 UTC 2019-05-15 03:24:15 +0000 UTC Unschedulable 0/1 nodes are available: 1 node(s) didn't match pod affinity/anti-affinity, 1 node(s) didn't satisfy existing pods anti-affinity rules.}]
Oct  4 06:39:03.086: INFO: 
Oct  4 06:39:05.081: INFO: The status of Pod coredns-7c949f49d5-p6f2z is Pending (Ready = false), waiting for it to be either Running (with Ready = true) or Failed
Oct  4 06:39:05.081: INFO: 10 / 11 pods in namespace 'kube-system' are running and ready (154 seconds elapsed)
Oct  4 06:39:05.081: INFO: expected 6 pod replicas in namespace 'kube-system', 5 are Running and Ready.
Oct  4 06:39:05.081: INFO: POD                       NODE  PHASE    GRACE  CONDITIONS
Oct  4 06:39:05.081: INFO: coredns-7c949f49d5-p6f2z        Pending         [{PodScheduled False 0001-01-01 00:00:00 +0000 UTC 2019-05-15 03:24:15 +0000 UTC Unschedulable 0/1 nodes are available: 1 node(s) didn't match pod affinity/anti-affinity, 1 node(s) didn't satisfy existing pods anti-affinity rules.}]
Oct  4 06:39:05.081: INFO: 
Oct  4 06:39:07.089: INFO: The status of Pod coredns-7c949f49d5-p6f2z is Pending (Ready = false), waiting for it to be either Running (with Ready = true) or Failed
Oct  4 06:39:07.089: INFO: 10 / 11 pods in namespace 'kube-system' are running and ready (156 seconds elapsed)
Oct  4 06:39:07.089: INFO: expected 6 pod replicas in namespace 'kube-system', 5 are Running and Ready.
Oct  4 06:39:07.089: INFO: POD                       NODE  PHASE    GRACE  CONDITIONS
Oct  4 06:39:07.089: INFO: coredns-7c949f49d5-p6f2z        Pending         [{PodScheduled False 0001-01-01 00:00:00 +0000 UTC 2019-05-15 03:24:15 +0000 UTC Unschedulable 0/1 nodes are available: 1 node(s) didn't match pod affinity/anti-affinity, 1 node(s) didn't satisfy existing pods anti-affinity rules.}]
Oct  4 06:39:07.089: INFO: 
Oct  4 06:39:09.090: INFO: The status of Pod coredns-7c949f49d5-p6f2z is Pending (Ready = false), waiting for it to be either Running (with Ready = true) or Failed
Oct  4 06:39:09.090: INFO: 10 / 11 pods in namespace 'kube-system' are running and ready (158 seconds elapsed)
Oct  4 06:39:09.090: INFO: expected 6 pod replicas in namespace 'kube-system', 5 are Running and Ready.
Oct  4 06:39:09.090: INFO: POD                       NODE  PHASE    GRACE  CONDITIONS
Oct  4 06:39:09.090: INFO: coredns-7c949f49d5-p6f2z        Pending         [{PodScheduled False 0001-01-01 00:00:00 +0000 UTC 2019-05-15 03:24:15 +0000 UTC Unschedulable 0/1 nodes are available: 1 node(s) didn't match pod affinity/anti-affinity, 1 node(s) didn't satisfy existing pods anti-affinity rules.}]
Oct  4 06:39:09.090: INFO: 
Oct  4 06:39:11.090: INFO: The status of Pod coredns-7c949f49d5-p6f2z is Pending (Ready = false), waiting for it to be either Running (with Ready = true) or Failed
Oct  4 06:39:11.090: INFO: 10 / 11 pods in namespace 'kube-system' are running and ready (160 seconds elapsed)
Oct  4 06:39:11.090: INFO: expected 6 pod replicas in namespace 'kube-system', 5 are Running and Ready.
Oct  4 06:39:11.090: INFO: POD                       NODE  PHASE    GRACE  CONDITIONS
Oct  4 06:39:11.090: INFO: coredns-7c949f49d5-p6f2z        Pending         [{PodScheduled False 0001-01-01 00:00:00 +0000 UTC 2019-05-15 03:24:15 +0000 UTC Unschedulable 0/1 nodes are available: 1 node(s) didn't match pod affinity/anti-affinity, 1 node(s) didn't satisfy existing pods anti-affinity rules.}]
Oct  4 06:39:11.090: INFO: 
Oct  4 06:39:13.081: INFO: The status of Pod coredns-7c949f49d5-p6f2z is Pending (Ready = false), waiting for it to be either Running (with Ready = true) or Failed
Oct  4 06:39:13.081: INFO: 10 / 11 pods in namespace 'kube-system' are running and ready (162 seconds elapsed)
Oct  4 06:39:13.081: INFO: expected 6 pod replicas in namespace 'kube-system', 5 are Running and Ready.
Oct  4 06:39:13.081: INFO: POD                       NODE  PHASE    GRACE  CONDITIONS
Oct  4 06:39:13.081: INFO: coredns-7c949f49d5-p6f2z        Pending         [{PodScheduled False 0001-01-01 00:00:00 +0000 UTC 2019-05-15 03:24:15 +0000 UTC Unschedulable 0/1 nodes are available: 1 node(s) didn't match pod affinity/anti-affinity, 1 node(s) didn't satisfy existing pods anti-affinity rules.}]
Oct  4 06:39:13.081: INFO: 
Oct  4 06:39:15.120: INFO: The status of Pod coredns-7c949f49d5-p6f2z is Pending (Ready = false), waiting for it to be either Running (with Ready = true) or Failed
Oct  4 06:39:15.120: INFO: 10 / 11 pods in namespace 'kube-system' are running and ready (164 seconds elapsed)
Oct  4 06:39:15.120: INFO: expected 6 pod replicas in namespace 'kube-system', 5 are Running and Ready.
Oct  4 06:39:15.120: INFO: POD                       NODE  PHASE    GRACE  CONDITIONS
Oct  4 06:39:15.120: INFO: coredns-7c949f49d5-p6f2z        Pending         [{PodScheduled False 0001-01-01 00:00:00 +0000 UTC 2019-05-15 03:24:15 +0000 UTC Unschedulable 0/1 nodes are available: 1 node(s) didn't match pod affinity/anti-affinity, 1 node(s) didn't satisfy existing pods anti-affinity rules.}]
Oct  4 06:39:15.120: INFO: 
Oct  4 06:39:17.089: INFO: The status of Pod coredns-7c949f49d5-p6f2z is Pending (Ready = false), waiting for it to be either Running (with Ready = true) or Failed
Oct  4 06:39:17.089: INFO: 10 / 11 pods in namespace 'kube-system' are running and ready (166 seconds elapsed)
Oct  4 06:39:17.089: INFO: expected 6 pod replicas in namespace 'kube-system', 5 are Running and Ready.
Oct  4 06:39:17.089: INFO: POD                       NODE  PHASE    GRACE  CONDITIONS
Oct  4 06:39:17.089: INFO: coredns-7c949f49d5-p6f2z        Pending         [{PodScheduled False 0001-01-01 00:00:00 +0000 UTC 2019-05-15 03:24:15 +0000 UTC Unschedulable 0/1 nodes are available: 1 node(s) didn't match pod affinity/anti-affinity, 1 node(s) didn't satisfy existing pods anti-affinity rules.}]
Oct  4 06:39:17.090: INFO: 
Oct  4 06:39:19.325: INFO: The status of Pod coredns-7c949f49d5-p6f2z is Pending (Ready = false), waiting for it to be either Running (with Ready = true) or Failed
Oct  4 06:39:19.326: INFO: 10 / 11 pods in namespace 'kube-system' are running and ready (168 seconds elapsed)
Oct  4 06:39:19.326: INFO: expected 6 pod replicas in namespace 'kube-system', 5 are Running and Ready.
Oct  4 06:39:19.326: INFO: POD                       NODE  PHASE    GRACE  CONDITIONS
Oct  4 06:39:19.326: INFO: coredns-7c949f49d5-p6f2z        Pending         [{PodScheduled False 0001-01-01 00:00:00 +0000 UTC 2019-05-15 03:24:15 +0000 UTC Unschedulable 0/1 nodes are available: 1 node(s) didn't match pod affinity/anti-affinity, 1 node(s) didn't satisfy existing pods anti-affinity rules.}]
Oct  4 06:39:19.326: INFO: 
Oct  4 06:39:21.094: INFO: The status of Pod coredns-7c949f49d5-p6f2z is Pending (Ready = false), waiting for it to be either Running (with Ready = true) or Failed
Oct  4 06:39:21.094: INFO: 10 / 11 pods in namespace 'kube-system' are running and ready (170 seconds elapsed)
Oct  4 06:39:21.094: INFO: expected 6 pod replicas in namespace 'kube-system', 5 are Running and Ready.
Oct  4 06:39:21.094: INFO: POD                       NODE  PHASE    GRACE  CONDITIONS
Oct  4 06:39:21.094: INFO: coredns-7c949f49d5-p6f2z        Pending         [{PodScheduled False 0001-01-01 00:00:00 +0000 UTC 2019-05-15 03:24:15 +0000 UTC Unschedulable 0/1 nodes are available: 1 node(s) didn't match pod affinity/anti-affinity, 1 node(s) didn't satisfy existing pods anti-affinity rules.}]
Oct  4 06:39:21.094: INFO: 
Oct  4 06:39:23.081: INFO: The status of Pod coredns-7c949f49d5-p6f2z is Pending (Ready = false), waiting for it to be either Running (with Ready = true) or Failed
Oct  4 06:39:23.081: INFO: 10 / 11 pods in namespace 'kube-system' are running and ready (172 seconds elapsed)
Oct  4 06:39:23.081: INFO: expected 6 pod replicas in namespace 'kube-system', 5 are Running and Ready.
Oct  4 06:39:23.081: INFO: POD                       NODE  PHASE    GRACE  CONDITIONS
Oct  4 06:39:23.081: INFO: coredns-7c949f49d5-p6f2z        Pending         [{PodScheduled False 0001-01-01 00:00:00 +0000 UTC 2019-05-15 03:24:15 +0000 UTC Unschedulable 0/1 nodes are available: 1 node(s) didn't match pod affinity/anti-affinity, 1 node(s) didn't satisfy existing pods anti-affinity rules.}]
Oct  4 06:39:23.081: INFO: 
Oct  4 06:39:25.082: INFO: The status of Pod coredns-7c949f49d5-p6f2z is Pending (Ready = false), waiting for it to be either Running (with Ready = true) or Failed
Oct  4 06:39:25.082: INFO: 10 / 11 pods in namespace 'kube-system' are running and ready (174 seconds elapsed)
Oct  4 06:39:25.082: INFO: expected 6 pod replicas in namespace 'kube-system', 5 are Running and Ready.
Oct  4 06:39:25.082: INFO: POD                       NODE  PHASE    GRACE  CONDITIONS
Oct  4 06:39:25.082: INFO: coredns-7c949f49d5-p6f2z        Pending         [{PodScheduled False 0001-01-01 00:00:00 +0000 UTC 2019-05-15 03:24:15 +0000 UTC Unschedulable 0/1 nodes are available: 1 node(s) didn't match pod affinity/anti-affinity, 1 node(s) didn't satisfy existing pods anti-affinity rules.}]
Oct  4 06:39:25.082: INFO: 
Oct  4 06:39:27.093: INFO: The status of Pod coredns-7c949f49d5-p6f2z is Pending (Ready = false), waiting for it to be either Running (with Ready = true) or Failed
Oct  4 06:39:27.094: INFO: 10 / 11 pods in namespace 'kube-system' are running and ready (176 seconds elapsed)
Oct  4 06:39:27.094: INFO: expected 6 pod replicas in namespace 'kube-system', 5 are Running and Ready.
Oct  4 06:39:27.094: INFO: POD                       NODE  PHASE    GRACE  CONDITIONS
Oct  4 06:39:27.094: INFO: coredns-7c949f49d5-p6f2z        Pending         [{PodScheduled False 0001-01-01 00:00:00 +0000 UTC 2019-05-15 03:24:15 +0000 UTC Unschedulable 0/1 nodes are available: 1 node(s) didn't match pod affinity/anti-affinity, 1 node(s) didn't satisfy existing pods anti-affinity rules.}]
Oct  4 06:39:27.094: INFO: 
Oct  4 06:39:29.091: INFO: The status of Pod coredns-7c949f49d5-p6f2z is Pending (Ready = false), waiting for it to be either Running (with Ready = true) or Failed
Oct  4 06:39:29.091: INFO: 10 / 11 pods in namespace 'kube-system' are running and ready (178 seconds elapsed)
Oct  4 06:39:29.091: INFO: expected 6 pod replicas in namespace 'kube-system', 5 are Running and Ready.
Oct  4 06:39:29.091: INFO: POD                       NODE  PHASE    GRACE  CONDITIONS
Oct  4 06:39:29.091: INFO: coredns-7c949f49d5-p6f2z        Pending         [{PodScheduled False 0001-01-01 00:00:00 +0000 UTC 2019-05-15 03:24:15 +0000 UTC Unschedulable 0/1 nodes are available: 1 node(s) didn't match pod affinity/anti-affinity, 1 node(s) didn't satisfy existing pods anti-affinity rules.}]
Oct  4 06:39:29.091: INFO: 
Oct  4 06:39:31.091: INFO: The status of Pod coredns-7c949f49d5-p6f2z is Pending (Ready = false), waiting for it to be either Running (with Ready = true) or Failed
Oct  4 06:39:31.091: INFO: 10 / 11 pods in namespace 'kube-system' are running and ready (180 seconds elapsed)
Oct  4 06:39:31.091: INFO: expected 6 pod replicas in namespace 'kube-system', 5 are Running and Ready.
Oct  4 06:39:31.091: INFO: POD                       NODE  PHASE    GRACE  CONDITIONS
Oct  4 06:39:31.091: INFO: coredns-7c949f49d5-p6f2z        Pending         [{PodScheduled False 0001-01-01 00:00:00 +0000 UTC 2019-05-15 03:24:15 +0000 UTC Unschedulable 0/1 nodes are available: 1 node(s) didn't match pod affinity/anti-affinity, 1 node(s) didn't satisfy existing pods anti-affinity rules.}]
Oct  4 06:39:31.091: INFO: 
Oct  4 06:39:33.081: INFO: The status of Pod coredns-7c949f49d5-p6f2z is Pending (Ready = false), waiting for it to be either Running (with Ready = true) or Failed
Oct  4 06:39:33.081: INFO: 10 / 11 pods in namespace 'kube-system' are running and ready (182 seconds elapsed)
Oct  4 06:39:33.081: INFO: expected 6 pod replicas in namespace 'kube-system', 5 are Running and Ready.
Oct  4 06:39:33.081: INFO: POD                       NODE  PHASE    GRACE  CONDITIONS
Oct  4 06:39:33.081: INFO: coredns-7c949f49d5-p6f2z        Pending         [{PodScheduled False 0001-01-01 00:00:00 +0000 UTC 2019-05-15 03:24:15 +0000 UTC Unschedulable 0/1 nodes are available: 1 node(s) didn't match pod affinity/anti-affinity, 1 node(s) didn't satisfy existing pods anti-affinity rules.}]
Oct  4 06:39:33.081: INFO: 
Oct  4 06:39:35.082: INFO: The status of Pod coredns-7c949f49d5-p6f2z is Pending (Ready = false), waiting for it to be either Running (with Ready = true) or Failed
Oct  4 06:39:35.082: INFO: 10 / 11 pods in namespace 'kube-system' are running and ready (184 seconds elapsed)
Oct  4 06:39:35.082: INFO: expected 6 pod replicas in namespace 'kube-system', 5 are Running and Ready.
Oct  4 06:39:35.082: INFO: POD                       NODE  PHASE    GRACE  CONDITIONS
Oct  4 06:39:35.082: INFO: coredns-7c949f49d5-p6f2z        Pending         [{PodScheduled False 0001-01-01 00:00:00 +0000 UTC 2019-05-15 03:24:15 +0000 UTC Unschedulable 0/1 nodes are available: 1 node(s) didn't match pod affinity/anti-affinity, 1 node(s) didn't satisfy existing pods anti-affinity rules.}]
Oct  4 06:39:35.082: INFO: 
Oct  4 06:39:37.088: INFO: The status of Pod coredns-7c949f49d5-p6f2z is Pending (Ready = false), waiting for it to be either Running (with Ready = true) or Failed
Oct  4 06:39:37.088: INFO: 10 / 11 pods in namespace 'kube-system' are running and ready (186 seconds elapsed)
Oct  4 06:39:37.088: INFO: expected 6 pod replicas in namespace 'kube-system', 5 are Running and Ready.
Oct  4 06:39:37.088: INFO: POD                       NODE  PHASE    GRACE  CONDITIONS
Oct  4 06:39:37.088: INFO: coredns-7c949f49d5-p6f2z        Pending         [{PodScheduled False 0001-01-01 00:00:00 +0000 UTC 2019-05-15 03:24:15 +0000 UTC Unschedulable 0/1 nodes are available: 1 node(s) didn't match pod affinity/anti-affinity, 1 node(s) didn't satisfy existing pods anti-affinity rules.}]
Oct  4 06:39:37.088: INFO: 
Oct  4 06:39:39.090: INFO: The status of Pod coredns-7c949f49d5-p6f2z is Pending (Ready = false), waiting for it to be either Running (with Ready = true) or Failed
Oct  4 06:39:39.090: INFO: 10 / 11 pods in namespace 'kube-system' are running and ready (188 seconds elapsed)
Oct  4 06:39:39.090: INFO: expected 6 pod replicas in namespace 'kube-system', 5 are Running and Ready.
Oct  4 06:39:39.090: INFO: POD                       NODE  PHASE    GRACE  CONDITIONS
Oct  4 06:39:39.090: INFO: coredns-7c949f49d5-p6f2z        Pending         [{PodScheduled False 0001-01-01 00:00:00 +0000 UTC 2019-05-15 03:24:15 +0000 UTC Unschedulable 0/1 nodes are available: 1 node(s) didn't match pod affinity/anti-affinity, 1 node(s) didn't satisfy existing pods anti-affinity rules.}]
Oct  4 06:39:39.090: INFO: 
Oct  4 06:39:41.104: INFO: The status of Pod coredns-7c949f49d5-p6f2z is Pending (Ready = false), waiting for it to be either Running (with Ready = true) or Failed
Oct  4 06:39:41.104: INFO: 10 / 11 pods in namespace 'kube-system' are running and ready (190 seconds elapsed)
Oct  4 06:39:41.104: INFO: expected 6 pod replicas in namespace 'kube-system', 5 are Running and Ready.
Oct  4 06:39:41.104: INFO: POD                       NODE  PHASE    GRACE  CONDITIONS
Oct  4 06:39:41.104: INFO: coredns-7c949f49d5-p6f2z        Pending         [{PodScheduled False 0001-01-01 00:00:00 +0000 UTC 2019-05-15 03:24:15 +0000 UTC Unschedulable 0/1 nodes are available: 1 node(s) didn't match pod affinity/anti-affinity, 1 node(s) didn't satisfy existing pods anti-affinity rules.}]
Oct  4 06:39:41.104: INFO: 
Oct  4 06:39:43.095: INFO: The status of Pod coredns-7c949f49d5-p6f2z is Pending (Ready = false), waiting for it to be either Running (with Ready = true) or Failed
Oct  4 06:39:43.095: INFO: 10 / 11 pods in namespace 'kube-system' are running and ready (192 seconds elapsed)
Oct  4 06:39:43.095: INFO: expected 6 pod replicas in namespace 'kube-system', 5 are Running and Ready.
Oct  4 06:39:43.095: INFO: POD                       NODE  PHASE    GRACE  CONDITIONS
Oct  4 06:39:43.095: INFO: coredns-7c949f49d5-p6f2z        Pending         [{PodScheduled False 0001-01-01 00:00:00 +0000 UTC 2019-05-15 03:24:15 +0000 UTC Unschedulable 0/1 nodes are available: 1 node(s) didn't match pod affinity/anti-affinity, 1 node(s) didn't satisfy existing pods anti-affinity rules.}]
Oct  4 06:39:43.095: INFO: 
Oct  4 06:39:45.081: INFO: The status of Pod coredns-7c949f49d5-p6f2z is Pending (Ready = false), waiting for it to be either Running (with Ready = true) or Failed
Oct  4 06:39:45.081: INFO: 10 / 11 pods in namespace 'kube-system' are running and ready (194 seconds elapsed)
Oct  4 06:39:45.081: INFO: expected 6 pod replicas in namespace 'kube-system', 5 are Running and Ready.
Oct  4 06:39:45.081: INFO: POD                       NODE  PHASE    GRACE  CONDITIONS
Oct  4 06:39:45.081: INFO: coredns-7c949f49d5-p6f2z        Pending         [{PodScheduled False 0001-01-01 00:00:00 +0000 UTC 2019-05-15 03:24:15 +0000 UTC Unschedulable 0/1 nodes are available: 1 node(s) didn't match pod affinity/anti-affinity, 1 node(s) didn't satisfy existing pods anti-affinity rules.}]
Oct  4 06:39:45.081: INFO: 
Oct  4 06:39:47.088: INFO: The status of Pod coredns-7c949f49d5-p6f2z is Pending (Ready = false), waiting for it to be either Running (with Ready = true) or Failed
Oct  4 06:39:47.088: INFO: 10 / 11 pods in namespace 'kube-system' are running and ready (196 seconds elapsed)
Oct  4 06:39:47.088: INFO: expected 6 pod replicas in namespace 'kube-system', 5 are Running and Ready.
Oct  4 06:39:47.088: INFO: POD                       NODE  PHASE    GRACE  CONDITIONS
Oct  4 06:39:47.088: INFO: coredns-7c949f49d5-p6f2z        Pending         [{PodScheduled False 0001-01-01 00:00:00 +0000 UTC 2019-05-15 03:24:15 +0000 UTC Unschedulable 0/1 nodes are available: 1 node(s) didn't match pod affinity/anti-affinity, 1 node(s) didn't satisfy existing pods anti-affinity rules.}]
Oct  4 06:39:47.088: INFO: 
Oct  4 06:39:49.092: INFO: The status of Pod coredns-7c949f49d5-p6f2z is Pending (Ready = false), waiting for it to be either Running (with Ready = true) or Failed
Oct  4 06:39:49.092: INFO: 10 / 11 pods in namespace 'kube-system' are running and ready (198 seconds elapsed)
Oct  4 06:39:49.092: INFO: expected 6 pod replicas in namespace 'kube-system', 5 are Running and Ready.
Oct  4 06:39:49.092: INFO: POD                       NODE  PHASE    GRACE  CONDITIONS
Oct  4 06:39:49.092: INFO: coredns-7c949f49d5-p6f2z        Pending         [{PodScheduled False 0001-01-01 00:00:00 +0000 UTC 2019-05-15 03:24:15 +0000 UTC Unschedulable 0/1 nodes are available: 1 node(s) didn't match pod affinity/anti-affinity, 1 node(s) didn't satisfy existing pods anti-affinity rules.}]
Oct  4 06:39:49.092: INFO: 
Oct  4 06:39:51.090: INFO: The status of Pod coredns-7c949f49d5-p6f2z is Pending (Ready = false), waiting for it to be either Running (with Ready = true) or Failed
Oct  4 06:39:51.090: INFO: 10 / 11 pods in namespace 'kube-system' are running and ready (200 seconds elapsed)
Oct  4 06:39:51.090: INFO: expected 6 pod replicas in namespace 'kube-system', 5 are Running and Ready.
Oct  4 06:39:51.090: INFO: POD                       NODE  PHASE    GRACE  CONDITIONS
Oct  4 06:39:51.090: INFO: coredns-7c949f49d5-p6f2z        Pending         [{PodScheduled False 0001-01-01 00:00:00 +0000 UTC 2019-05-15 03:24:15 +0000 UTC Unschedulable 0/1 nodes are available: 1 node(s) didn't match pod affinity/anti-affinity, 1 node(s) didn't satisfy existing pods anti-affinity rules.}]
Oct  4 06:39:51.090: INFO: 
Oct  4 06:39:53.082: INFO: The status of Pod coredns-7c949f49d5-p6f2z is Pending (Ready = false), waiting for it to be either Running (with Ready = true) or Failed
Oct  4 06:39:53.082: INFO: 10 / 11 pods in namespace 'kube-system' are running and ready (202 seconds elapsed)
Oct  4 06:39:53.082: INFO: expected 6 pod replicas in namespace 'kube-system', 5 are Running and Ready.
Oct  4 06:39:53.082: INFO: POD                       NODE  PHASE    GRACE  CONDITIONS
Oct  4 06:39:53.082: INFO: coredns-7c949f49d5-p6f2z        Pending         [{PodScheduled False 0001-01-01 00:00:00 +0000 UTC 2019-05-15 03:24:15 +0000 UTC Unschedulable 0/1 nodes are available: 1 node(s) didn't match pod affinity/anti-affinity, 1 node(s) didn't satisfy existing pods anti-affinity rules.}]
Oct  4 06:39:53.082: INFO: 
Oct  4 06:39:55.082: INFO: The status of Pod coredns-7c949f49d5-p6f2z is Pending (Ready = false), waiting for it to be either Running (with Ready = true) or Failed
Oct  4 06:39:55.082: INFO: 10 / 11 pods in namespace 'kube-system' are running and ready (204 seconds elapsed)
Oct  4 06:39:55.082: INFO: expected 6 pod replicas in namespace 'kube-system', 5 are Running and Ready.
Oct  4 06:39:55.082: INFO: POD                       NODE  PHASE    GRACE  CONDITIONS
Oct  4 06:39:55.082: INFO: coredns-7c949f49d5-p6f2z        Pending         [{PodScheduled False 0001-01-01 00:00:00 +0000 UTC 2019-05-15 03:24:15 +0000 UTC Unschedulable 0/1 nodes are available: 1 node(s) didn't match pod affinity/anti-affinity, 1 node(s) didn't satisfy existing pods anti-affinity rules.}]
Oct  4 06:39:55.082: INFO: 
Oct  4 06:39:57.081: INFO: The status of Pod coredns-7c949f49d5-p6f2z is Pending (Ready = false), waiting for it to be either Running (with Ready = true) or Failed
Oct  4 06:39:57.081: INFO: 10 / 11 pods in namespace 'kube-system' are running and ready (206 seconds elapsed)
Oct  4 06:39:57.081: INFO: expected 6 pod replicas in namespace 'kube-system', 5 are Running and Ready.
Oct  4 06:39:57.081: INFO: POD                       NODE  PHASE    GRACE  CONDITIONS
Oct  4 06:39:57.081: INFO: coredns-7c949f49d5-p6f2z        Pending         [{PodScheduled False 0001-01-01 00:00:00 +0000 UTC 2019-05-15 03:24:15 +0000 UTC Unschedulable 0/1 nodes are available: 1 node(s) didn't match pod affinity/anti-affinity, 1 node(s) didn't satisfy existing pods anti-affinity rules.}]
Oct  4 06:39:57.081: INFO: 
Oct  4 06:39:59.089: INFO: The status of Pod coredns-7c949f49d5-p6f2z is Pending (Ready = false), waiting for it to be either Running (with Ready = true) or Failed
Oct  4 06:39:59.089: INFO: 10 / 11 pods in namespace 'kube-system' are running and ready (208 seconds elapsed)
Oct  4 06:39:59.089: INFO: expected 6 pod replicas in namespace 'kube-system', 5 are Running and Ready.
Oct  4 06:39:59.089: INFO: POD                       NODE  PHASE    GRACE  CONDITIONS
Oct  4 06:39:59.090: INFO: coredns-7c949f49d5-p6f2z        Pending         [{PodScheduled False 0001-01-01 00:00:00 +0000 UTC 2019-05-15 03:24:15 +0000 UTC Unschedulable 0/1 nodes are available: 1 node(s) didn't match pod affinity/anti-affinity, 1 node(s) didn't satisfy existing pods anti-affinity rules.}]
Oct  4 06:39:59.090: INFO: 
Oct  4 06:40:01.174: INFO: The status of Pod coredns-7c949f49d5-p6f2z is Pending (Ready = false), waiting for it to be either Running (with Ready = true) or Failed
Oct  4 06:40:01.174: INFO: 10 / 11 pods in namespace 'kube-system' are running and ready (210 seconds elapsed)
Oct  4 06:40:01.174: INFO: expected 6 pod replicas in namespace 'kube-system', 5 are Running and Ready.
Oct  4 06:40:01.174: INFO: POD                       NODE  PHASE    GRACE  CONDITIONS
Oct  4 06:40:01.174: INFO: coredns-7c949f49d5-p6f2z        Pending         [{PodScheduled False 0001-01-01 00:00:00 +0000 UTC 2019-05-15 03:24:15 +0000 UTC Unschedulable 0/1 nodes are available: 1 node(s) didn't match pod affinity/anti-affinity, 1 node(s) didn't satisfy existing pods anti-affinity rules.}]
Oct  4 06:40:01.174: INFO: 
Oct  4 06:40:03.081: INFO: The status of Pod coredns-7c949f49d5-p6f2z is Pending (Ready = false), waiting for it to be either Running (with Ready = true) or Failed
Oct  4 06:40:03.081: INFO: 10 / 11 pods in namespace 'kube-system' are running and ready (212 seconds elapsed)
Oct  4 06:40:03.081: INFO: expected 6 pod replicas in namespace 'kube-system', 5 are Running and Ready.
Oct  4 06:40:03.081: INFO: POD                       NODE  PHASE    GRACE  CONDITIONS
Oct  4 06:40:03.081: INFO: coredns-7c949f49d5-p6f2z        Pending         [{PodScheduled False 0001-01-01 00:00:00 +0000 UTC 2019-05-15 03:24:15 +0000 UTC Unschedulable 0/1 nodes are available: 1 node(s) didn't match pod affinity/anti-affinity, 1 node(s) didn't satisfy existing pods anti-affinity rules.}]
Oct  4 06:40:03.081: INFO: 
Oct  4 06:40:05.081: INFO: The status of Pod coredns-7c949f49d5-p6f2z is Pending (Ready = false), waiting for it to be either Running (with Ready = true) or Failed
Oct  4 06:40:05.081: INFO: 10 / 11 pods in namespace 'kube-system' are running and ready (214 seconds elapsed)
Oct  4 06:40:05.081: INFO: expected 6 pod replicas in namespace 'kube-system', 5 are Running and Ready.
Oct  4 06:40:05.081: INFO: POD                       NODE  PHASE    GRACE  CONDITIONS
Oct  4 06:40:05.081: INFO: coredns-7c949f49d5-p6f2z        Pending         [{PodScheduled False 0001-01-01 00:00:00 +0000 UTC 2019-05-15 03:24:15 +0000 UTC Unschedulable 0/1 nodes are available: 1 node(s) didn't match pod affinity/anti-affinity, 1 node(s) didn't satisfy existing pods anti-affinity rules.}]
Oct  4 06:40:05.081: INFO: 
Oct  4 06:40:07.089: INFO: The status of Pod coredns-7c949f49d5-p6f2z is Pending (Ready = false), waiting for it to be either Running (with Ready = true) or Failed
Oct  4 06:40:07.089: INFO: 10 / 11 pods in namespace 'kube-system' are running and ready (216 seconds elapsed)
Oct  4 06:40:07.089: INFO: expected 6 pod replicas in namespace 'kube-system', 5 are Running and Ready.
Oct  4 06:40:07.089: INFO: POD                       NODE  PHASE    GRACE  CONDITIONS
Oct  4 06:40:07.089: INFO: coredns-7c949f49d5-p6f2z        Pending         [{PodScheduled False 0001-01-01 00:00:00 +0000 UTC 2019-05-15 03:24:15 +0000 UTC Unschedulable 0/1 nodes are available: 1 node(s) didn't match pod affinity/anti-affinity, 1 node(s) didn't satisfy existing pods anti-affinity rules.}]
Oct  4 06:40:07.089: INFO: 
Oct  4 06:40:09.105: INFO: The status of Pod coredns-7c949f49d5-p6f2z is Pending (Ready = false), waiting for it to be either Running (with Ready = true) or Failed
Oct  4 06:40:09.105: INFO: 10 / 11 pods in namespace 'kube-system' are running and ready (218 seconds elapsed)
Oct  4 06:40:09.105: INFO: expected 6 pod replicas in namespace 'kube-system', 5 are Running and Ready.
Oct  4 06:40:09.105: INFO: POD                       NODE  PHASE    GRACE  CONDITIONS
Oct  4 06:40:09.105: INFO: coredns-7c949f49d5-p6f2z        Pending         [{PodScheduled False 0001-01-01 00:00:00 +0000 UTC 2019-05-15 03:24:15 +0000 UTC Unschedulable 0/1 nodes are available: 1 node(s) didn't match pod affinity/anti-affinity, 1 node(s) didn't satisfy existing pods anti-affinity rules.}]
Oct  4 06:40:09.105: INFO: 
Oct  4 06:40:11.093: INFO: The status of Pod coredns-7c949f49d5-p6f2z is Pending (Ready = false), waiting for it to be either Running (with Ready = true) or Failed
Oct  4 06:40:11.093: INFO: 10 / 11 pods in namespace 'kube-system' are running and ready (220 seconds elapsed)
Oct  4 06:40:11.093: INFO: expected 6 pod replicas in namespace 'kube-system', 5 are Running and Ready.
Oct  4 06:40:11.093: INFO: POD                       NODE  PHASE    GRACE  CONDITIONS
Oct  4 06:40:11.093: INFO: coredns-7c949f49d5-p6f2z        Pending         [{PodScheduled False 0001-01-01 00:00:00 +0000 UTC 2019-05-15 03:24:15 +0000 UTC Unschedulable 0/1 nodes are available: 1 node(s) didn't match pod affinity/anti-affinity, 1 node(s) didn't satisfy existing pods anti-affinity rules.}]
Oct  4 06:40:11.094: INFO: 
Oct  4 06:40:13.089: INFO: The status of Pod coredns-7c949f49d5-p6f2z is Pending (Ready = false), waiting for it to be either Running (with Ready = true) or Failed
Oct  4 06:40:13.089: INFO: 10 / 11 pods in namespace 'kube-system' are running and ready (222 seconds elapsed)
Oct  4 06:40:13.089: INFO: expected 6 pod replicas in namespace 'kube-system', 5 are Running and Ready.
Oct  4 06:40:13.089: INFO: POD                       NODE  PHASE    GRACE  CONDITIONS
Oct  4 06:40:13.089: INFO: coredns-7c949f49d5-p6f2z        Pending         [{PodScheduled False 0001-01-01 00:00:00 +0000 UTC 2019-05-15 03:24:15 +0000 UTC Unschedulable 0/1 nodes are available: 1 node(s) didn't match pod affinity/anti-affinity, 1 node(s) didn't satisfy existing pods anti-affinity rules.}]
Oct  4 06:40:13.089: INFO: 
Oct  4 06:40:15.090: INFO: The status of Pod coredns-7c949f49d5-p6f2z is Pending (Ready = false), waiting for it to be either Running (with Ready = true) or Failed
Oct  4 06:40:15.090: INFO: 10 / 11 pods in namespace 'kube-system' are running and ready (224 seconds elapsed)
Oct  4 06:40:15.090: INFO: expected 6 pod replicas in namespace 'kube-system', 5 are Running and Ready.
Oct  4 06:40:15.090: INFO: POD                       NODE  PHASE    GRACE  CONDITIONS
Oct  4 06:40:15.090: INFO: coredns-7c949f49d5-p6f2z        Pending         [{PodScheduled False 0001-01-01 00:00:00 +0000 UTC 2019-05-15 03:24:15 +0000 UTC Unschedulable 0/1 nodes are available: 1 node(s) didn't match pod affinity/anti-affinity, 1 node(s) didn't satisfy existing pods anti-affinity rules.}]
Oct  4 06:40:15.090: INFO: 
Oct  4 06:40:17.081: INFO: The status of Pod coredns-7c949f49d5-p6f2z is Pending (Ready = false), waiting for it to be either Running (with Ready = true) or Failed
Oct  4 06:40:17.081: INFO: 10 / 11 pods in namespace 'kube-system' are running and ready (226 seconds elapsed)
Oct  4 06:40:17.081: INFO: expected 6 pod replicas in namespace 'kube-system', 5 are Running and Ready.
Oct  4 06:40:17.081: INFO: POD                       NODE  PHASE    GRACE  CONDITIONS
Oct  4 06:40:17.081: INFO: coredns-7c949f49d5-p6f2z        Pending         [{PodScheduled False 0001-01-01 00:00:00 +0000 UTC 2019-05-15 03:24:15 +0000 UTC Unschedulable 0/1 nodes are available: 1 node(s) didn't match pod affinity/anti-affinity, 1 node(s) didn't satisfy existing pods anti-affinity rules.}]
Oct  4 06:40:17.081: INFO: 
Oct  4 06:40:19.085: INFO: The status of Pod coredns-7c949f49d5-p6f2z is Pending (Ready = false), waiting for it to be either Running (with Ready = true) or Failed
Oct  4 06:40:19.085: INFO: 10 / 11 pods in namespace 'kube-system' are running and ready (228 seconds elapsed)
Oct  4 06:40:19.085: INFO: expected 6 pod replicas in namespace 'kube-system', 5 are Running and Ready.
Oct  4 06:40:19.085: INFO: POD                       NODE  PHASE    GRACE  CONDITIONS
Oct  4 06:40:19.085: INFO: coredns-7c949f49d5-p6f2z        Pending         [{PodScheduled False 0001-01-01 00:00:00 +0000 UTC 2019-05-15 03:24:15 +0000 UTC Unschedulable 0/1 nodes are available: 1 node(s) didn't match pod affinity/anti-affinity, 1 node(s) didn't satisfy existing pods anti-affinity rules.}]
Oct  4 06:40:19.085: INFO: 
Oct  4 06:40:21.091: INFO: The status of Pod coredns-7c949f49d5-p6f2z is Pending (Ready = false), waiting for it to be either Running (with Ready = true) or Failed
Oct  4 06:40:21.091: INFO: 10 / 11 pods in namespace 'kube-system' are running and ready (230 seconds elapsed)
Oct  4 06:40:21.091: INFO: expected 6 pod replicas in namespace 'kube-system', 5 are Running and Ready.
Oct  4 06:40:21.091: INFO: POD                       NODE  PHASE    GRACE  CONDITIONS
Oct  4 06:40:21.091: INFO: coredns-7c949f49d5-p6f2z        Pending         [{PodScheduled False 0001-01-01 00:00:00 +0000 UTC 2019-05-15 03:24:15 +0000 UTC Unschedulable 0/1 nodes are available: 1 node(s) didn't match pod affinity/anti-affinity, 1 node(s) didn't satisfy existing pods anti-affinity rules.}]
Oct  4 06:40:21.091: INFO: 
Oct  4 06:40:23.091: INFO: The status of Pod coredns-7c949f49d5-p6f2z is Pending (Ready = false), waiting for it to be either Running (with Ready = true) or Failed
Oct  4 06:40:23.091: INFO: 10 / 11 pods in namespace 'kube-system' are running and ready (232 seconds elapsed)
Oct  4 06:40:23.091: INFO: expected 6 pod replicas in namespace 'kube-system', 5 are Running and Ready.
Oct  4 06:40:23.091: INFO: POD                       NODE  PHASE    GRACE  CONDITIONS
Oct  4 06:40:23.091: INFO: coredns-7c949f49d5-p6f2z        Pending         [{PodScheduled False 0001-01-01 00:00:00 +0000 UTC 2019-05-15 03:24:15 +0000 UTC Unschedulable 0/1 nodes are available: 1 node(s) didn't match pod affinity/anti-affinity, 1 node(s) didn't satisfy existing pods anti-affinity rules.}]
Oct  4 06:40:23.091: INFO: 
Oct  4 06:40:25.091: INFO: The status of Pod coredns-7c949f49d5-p6f2z is Pending (Ready = false), waiting for it to be either Running (with Ready = true) or Failed
Oct  4 06:40:25.091: INFO: 10 / 11 pods in namespace 'kube-system' are running and ready (234 seconds elapsed)
Oct  4 06:40:25.091: INFO: expected 6 pod replicas in namespace 'kube-system', 5 are Running and Ready.
Oct  4 06:40:25.091: INFO: POD                       NODE  PHASE    GRACE  CONDITIONS
Oct  4 06:40:25.091: INFO: coredns-7c949f49d5-p6f2z        Pending         [{PodScheduled False 0001-01-01 00:00:00 +0000 UTC 2019-05-15 03:24:15 +0000 UTC Unschedulable 0/1 nodes are available: 1 node(s) didn't match pod affinity/anti-affinity, 1 node(s) didn't satisfy existing pods anti-affinity rules.}]
Oct  4 06:40:25.091: INFO: 
Oct  4 06:40:27.081: INFO: The status of Pod coredns-7c949f49d5-p6f2z is Pending (Ready = false), waiting for it to be either Running (with Ready = true) or Failed
Oct  4 06:40:27.081: INFO: 10 / 11 pods in namespace 'kube-system' are running and ready (236 seconds elapsed)
Oct  4 06:40:27.081: INFO: expected 6 pod replicas in namespace 'kube-system', 5 are Running and Ready.
Oct  4 06:40:27.081: INFO: POD                       NODE  PHASE    GRACE  CONDITIONS
Oct  4 06:40:27.081: INFO: coredns-7c949f49d5-p6f2z        Pending         [{PodScheduled False 0001-01-01 00:00:00 +0000 UTC 2019-05-15 03:24:15 +0000 UTC Unschedulable 0/1 nodes are available: 1 node(s) didn't match pod affinity/anti-affinity, 1 node(s) didn't satisfy existing pods anti-affinity rules.}]
Oct  4 06:40:27.081: INFO: 
Oct  4 06:40:29.175: INFO: The status of Pod coredns-7c949f49d5-p6f2z is Pending (Ready = false), waiting for it to be either Running (with Ready = true) or Failed
Oct  4 06:40:29.175: INFO: 10 / 11 pods in namespace 'kube-system' are running and ready (238 seconds elapsed)
Oct  4 06:40:29.175: INFO: expected 6 pod replicas in namespace 'kube-system', 5 are Running and Ready.
Oct  4 06:40:29.175: INFO: POD                       NODE  PHASE    GRACE  CONDITIONS
Oct  4 06:40:29.175: INFO: coredns-7c949f49d5-p6f2z        Pending         [{PodScheduled False 0001-01-01 00:00:00 +0000 UTC 2019-05-15 03:24:15 +0000 UTC Unschedulable 0/1 nodes are available: 1 node(s) didn't match pod affinity/anti-affinity, 1 node(s) didn't satisfy existing pods anti-affinity rules.}]
Oct  4 06:40:29.175: INFO: 
Oct  4 06:40:31.081: INFO: The status of Pod coredns-7c949f49d5-p6f2z is Pending (Ready = false), waiting for it to be either Running (with Ready = true) or Failed
Oct  4 06:40:31.081: INFO: 10 / 11 pods in namespace 'kube-system' are running and ready (240 seconds elapsed)
Oct  4 06:40:31.081: INFO: expected 6 pod replicas in namespace 'kube-system', 5 are Running and Ready.
Oct  4 06:40:31.081: INFO: POD                       NODE  PHASE    GRACE  CONDITIONS
Oct  4 06:40:31.081: INFO: coredns-7c949f49d5-p6f2z        Pending         [{PodScheduled False 0001-01-01 00:00:00 +0000 UTC 2019-05-15 03:24:15 +0000 UTC Unschedulable 0/1 nodes are available: 1 node(s) didn't match pod affinity/anti-affinity, 1 node(s) didn't satisfy existing pods anti-affinity rules.}]
Oct  4 06:40:31.081: INFO: 
Oct  4 06:40:33.445: INFO: The status of Pod coredns-7c949f49d5-p6f2z is Pending (Ready = false), waiting for it to be either Running (with Ready = true) or Failed
Oct  4 06:40:33.445: INFO: 10 / 11 pods in namespace 'kube-system' are running and ready (242 seconds elapsed)
Oct  4 06:40:33.445: INFO: expected 6 pod replicas in namespace 'kube-system', 5 are Running and Ready.
Oct  4 06:40:33.445: INFO: POD                       NODE  PHASE    GRACE  CONDITIONS
Oct  4 06:40:33.445: INFO: coredns-7c949f49d5-p6f2z        Pending         [{PodScheduled False 0001-01-01 00:00:00 +0000 UTC 2019-05-15 03:24:15 +0000 UTC Unschedulable 0/1 nodes are available: 1 node(s) didn't match pod affinity/anti-affinity, 1 node(s) didn't satisfy existing pods anti-affinity rules.}]
Oct  4 06:40:33.445: INFO: 
Oct  4 06:40:35.095: INFO: The status of Pod coredns-7c949f49d5-p6f2z is Pending (Ready = false), waiting for it to be either Running (with Ready = true) or Failed
Oct  4 06:40:35.095: INFO: 10 / 11 pods in namespace 'kube-system' are running and ready (244 seconds elapsed)
Oct  4 06:40:35.095: INFO: expected 6 pod replicas in namespace 'kube-system', 5 are Running and Ready.
Oct  4 06:40:35.095: INFO: POD                       NODE  PHASE    GRACE  CONDITIONS
Oct  4 06:40:35.095: INFO: coredns-7c949f49d5-p6f2z        Pending         [{PodScheduled False 0001-01-01 00:00:00 +0000 UTC 2019-05-15 03:24:15 +0000 UTC Unschedulable 0/1 nodes are available: 1 node(s) didn't match pod affinity/anti-affinity, 1 node(s) didn't satisfy existing pods anti-affinity rules.}]
Oct  4 06:40:35.095: INFO: 
Oct  4 06:40:37.180: INFO: The status of Pod coredns-7c949f49d5-p6f2z is Pending (Ready = false), waiting for it to be either Running (with Ready = true) or Failed
Oct  4 06:40:37.180: INFO: 10 / 11 pods in namespace 'kube-system' are running and ready (246 seconds elapsed)
Oct  4 06:40:37.180: INFO: expected 6 pod replicas in namespace 'kube-system', 5 are Running and Ready.
Oct  4 06:40:37.180: INFO: POD                       NODE  PHASE    GRACE  CONDITIONS
Oct  4 06:40:37.180: INFO: coredns-7c949f49d5-p6f2z        Pending         [{PodScheduled False 0001-01-01 00:00:00 +0000 UTC 2019-05-15 03:24:15 +0000 UTC Unschedulable 0/1 nodes are available: 1 node(s) didn't match pod affinity/anti-affinity, 1 node(s) didn't satisfy existing pods anti-affinity rules.}]
Oct  4 06:40:37.180: INFO: 
Oct  4 06:40:39.090: INFO: The status of Pod coredns-7c949f49d5-p6f2z is Pending (Ready = false), waiting for it to be either Running (with Ready = true) or Failed
Oct  4 06:40:39.090: INFO: 10 / 11 pods in namespace 'kube-system' are running and ready (248 seconds elapsed)
Oct  4 06:40:39.090: INFO: expected 6 pod replicas in namespace 'kube-system', 5 are Running and Ready.
Oct  4 06:40:39.090: INFO: POD                       NODE  PHASE    GRACE  CONDITIONS
Oct  4 06:40:39.090: INFO: coredns-7c949f49d5-p6f2z        Pending         [{PodScheduled False 0001-01-01 00:00:00 +0000 UTC 2019-05-15 03:24:15 +0000 UTC Unschedulable 0/1 nodes are available: 1 node(s) didn't match pod affinity/anti-affinity, 1 node(s) didn't satisfy existing pods anti-affinity rules.}]
Oct  4 06:40:39.090: INFO: 
Oct  4 06:40:41.092: INFO: The status of Pod coredns-7c949f49d5-p6f2z is Pending (Ready = false), waiting for it to be either Running (with Ready = true) or Failed
Oct  4 06:40:41.092: INFO: 10 / 11 pods in namespace 'kube-system' are running and ready (250 seconds elapsed)
Oct  4 06:40:41.092: INFO: expected 6 pod replicas in namespace 'kube-system', 5 are Running and Ready.
Oct  4 06:40:41.092: INFO: POD                       NODE  PHASE    GRACE  CONDITIONS
Oct  4 06:40:41.092: INFO: coredns-7c949f49d5-p6f2z        Pending         [{PodScheduled False 0001-01-01 00:00:00 +0000 UTC 2019-05-15 03:24:15 +0000 UTC Unschedulable 0/1 nodes are available: 1 node(s) didn't match pod affinity/anti-affinity, 1 node(s) didn't satisfy existing pods anti-affinity rules.}]
Oct  4 06:40:41.092: INFO: 
Oct  4 06:40:43.090: INFO: The status of Pod coredns-7c949f49d5-p6f2z is Pending (Ready = false), waiting for it to be either Running (with Ready = true) or Failed
Oct  4 06:40:43.090: INFO: 10 / 11 pods in namespace 'kube-system' are running and ready (252 seconds elapsed)
Oct  4 06:40:43.090: INFO: expected 6 pod replicas in namespace 'kube-system', 5 are Running and Ready.
Oct  4 06:40:43.090: INFO: POD                       NODE  PHASE    GRACE  CONDITIONS
Oct  4 06:40:43.090: INFO: coredns-7c949f49d5-p6f2z        Pending         [{PodScheduled False 0001-01-01 00:00:00 +0000 UTC 2019-05-15 03:24:15 +0000 UTC Unschedulable 0/1 nodes are available: 1 node(s) didn't match pod affinity/anti-affinity, 1 node(s) didn't satisfy existing pods anti-affinity rules.}]
Oct  4 06:40:43.090: INFO: 
Oct  4 06:40:45.081: INFO: The status of Pod coredns-7c949f49d5-p6f2z is Pending (Ready = false), waiting for it to be either Running (with Ready = true) or Failed
Oct  4 06:40:45.081: INFO: 10 / 11 pods in namespace 'kube-system' are running and ready (254 seconds elapsed)
Oct  4 06:40:45.081: INFO: expected 6 pod replicas in namespace 'kube-system', 5 are Running and Ready.
Oct  4 06:40:45.081: INFO: POD                       NODE  PHASE    GRACE  CONDITIONS
Oct  4 06:40:45.081: INFO: coredns-7c949f49d5-p6f2z        Pending         [{PodScheduled False 0001-01-01 00:00:00 +0000 UTC 2019-05-15 03:24:15 +0000 UTC Unschedulable 0/1 nodes are available: 1 node(s) didn't match pod affinity/anti-affinity, 1 node(s) didn't satisfy existing pods anti-affinity rules.}]
Oct  4 06:40:45.082: INFO: 
Oct  4 06:40:47.082: INFO: The status of Pod coredns-7c949f49d5-p6f2z is Pending (Ready = false), waiting for it to be either Running (with Ready = true) or Failed
Oct  4 06:40:47.082: INFO: 10 / 11 pods in namespace 'kube-system' are running and ready (256 seconds elapsed)
Oct  4 06:40:47.082: INFO: expected 6 pod replicas in namespace 'kube-system', 5 are Running and Ready.
Oct  4 06:40:47.082: INFO: POD                       NODE  PHASE    GRACE  CONDITIONS
Oct  4 06:40:47.082: INFO: coredns-7c949f49d5-p6f2z        Pending         [{PodScheduled False 0001-01-01 00:00:00 +0000 UTC 2019-05-15 03:24:15 +0000 UTC Unschedulable 0/1 nodes are available: 1 node(s) didn't match pod affinity/anti-affinity, 1 node(s) didn't satisfy existing pods anti-affinity rules.}]
Oct  4 06:40:47.082: INFO: 
Oct  4 06:40:49.088: INFO: The status of Pod coredns-7c949f49d5-p6f2z is Pending (Ready = false), waiting for it to be either Running (with Ready = true) or Failed
Oct  4 06:40:49.088: INFO: 10 / 11 pods in namespace 'kube-system' are running and ready (258 seconds elapsed)
Oct  4 06:40:49.088: INFO: expected 6 pod replicas in namespace 'kube-system', 5 are Running and Ready.
Oct  4 06:40:49.088: INFO: POD                       NODE  PHASE    GRACE  CONDITIONS
Oct  4 06:40:49.088: INFO: coredns-7c949f49d5-p6f2z        Pending         [{PodScheduled False 0001-01-01 00:00:00 +0000 UTC 2019-05-15 03:24:15 +0000 UTC Unschedulable 0/1 nodes are available: 1 node(s) didn't match pod affinity/anti-affinity, 1 node(s) didn't satisfy existing pods anti-affinity rules.}]
Oct  4 06:40:49.088: INFO: 
Oct  4 06:40:51.091: INFO: The status of Pod coredns-7c949f49d5-p6f2z is Pending (Ready = false), waiting for it to be either Running (with Ready = true) or Failed
Oct  4 06:40:51.091: INFO: 10 / 11 pods in namespace 'kube-system' are running and ready (260 seconds elapsed)
Oct  4 06:40:51.091: INFO: expected 6 pod replicas in namespace 'kube-system', 5 are Running and Ready.
Oct  4 06:40:51.091: INFO: POD                       NODE  PHASE    GRACE  CONDITIONS
Oct  4 06:40:51.091: INFO: coredns-7c949f49d5-p6f2z        Pending         [{PodScheduled False 0001-01-01 00:00:00 +0000 UTC 2019-05-15 03:24:15 +0000 UTC Unschedulable 0/1 nodes are available: 1 node(s) didn't match pod affinity/anti-affinity, 1 node(s) didn't satisfy existing pods anti-affinity rules.}]
Oct  4 06:40:51.091: INFO: 
Oct  4 06:40:53.091: INFO: The status of Pod coredns-7c949f49d5-p6f2z is Pending (Ready = false), waiting for it to be either Running (with Ready = true) or Failed
Oct  4 06:40:53.091: INFO: 10 / 11 pods in namespace 'kube-system' are running and ready (262 seconds elapsed)
Oct  4 06:40:53.091: INFO: expected 6 pod replicas in namespace 'kube-system', 5 are Running and Ready.
Oct  4 06:40:53.091: INFO: POD                       NODE  PHASE    GRACE  CONDITIONS
Oct  4 06:40:53.091: INFO: coredns-7c949f49d5-p6f2z        Pending         [{PodScheduled False 0001-01-01 00:00:00 +0000 UTC 2019-05-15 03:24:15 +0000 UTC Unschedulable 0/1 nodes are available: 1 node(s) didn't match pod affinity/anti-affinity, 1 node(s) didn't satisfy existing pods anti-affinity rules.}]
Oct  4 06:40:53.091: INFO: 
Oct  4 06:40:55.257: INFO: The status of Pod coredns-7c949f49d5-p6f2z is Pending (Ready = false), waiting for it to be either Running (with Ready = true) or Failed
Oct  4 06:40:55.257: INFO: 10 / 11 pods in namespace 'kube-system' are running and ready (264 seconds elapsed)
Oct  4 06:40:55.257: INFO: expected 6 pod replicas in namespace 'kube-system', 5 are Running and Ready.
Oct  4 06:40:55.257: INFO: POD                       NODE  PHASE    GRACE  CONDITIONS
Oct  4 06:40:55.257: INFO: coredns-7c949f49d5-p6f2z        Pending         [{PodScheduled False 0001-01-01 00:00:00 +0000 UTC 2019-05-15 03:24:15 +0000 UTC Unschedulable 0/1 nodes are available: 1 node(s) didn't match pod affinity/anti-affinity, 1 node(s) didn't satisfy existing pods anti-affinity rules.}]
Oct  4 06:40:55.257: INFO: 
Oct  4 06:40:57.081: INFO: The status of Pod coredns-7c949f49d5-p6f2z is Pending (Ready = false), waiting for it to be either Running (with Ready = true) or Failed
Oct  4 06:40:57.081: INFO: 10 / 11 pods in namespace 'kube-system' are running and ready (266 seconds elapsed)
Oct  4 06:40:57.081: INFO: expected 6 pod replicas in namespace 'kube-system', 5 are Running and Ready.
Oct  4 06:40:57.081: INFO: POD                       NODE  PHASE    GRACE  CONDITIONS
Oct  4 06:40:57.081: INFO: coredns-7c949f49d5-p6f2z        Pending         [{PodScheduled False 0001-01-01 00:00:00 +0000 UTC 2019-05-15 03:24:15 +0000 UTC Unschedulable 0/1 nodes are available: 1 node(s) didn't match pod affinity/anti-affinity, 1 node(s) didn't satisfy existing pods anti-affinity rules.}]
Oct  4 06:40:57.081: INFO: 
Oct  4 06:40:59.088: INFO: The status of Pod coredns-7c949f49d5-p6f2z is Pending (Ready = false), waiting for it to be either Running (with Ready = true) or Failed
Oct  4 06:40:59.088: INFO: 10 / 11 pods in namespace 'kube-system' are running and ready (268 seconds elapsed)
Oct  4 06:40:59.088: INFO: expected 6 pod replicas in namespace 'kube-system', 5 are Running and Ready.
Oct  4 06:40:59.088: INFO: POD                       NODE  PHASE    GRACE  CONDITIONS
Oct  4 06:40:59.088: INFO: coredns-7c949f49d5-p6f2z        Pending         [{PodScheduled False 0001-01-01 00:00:00 +0000 UTC 2019-05-15 03:24:15 +0000 UTC Unschedulable 0/1 nodes are available: 1 node(s) didn't match pod affinity/anti-affinity, 1 node(s) didn't satisfy existing pods anti-affinity rules.}]
Oct  4 06:40:59.089: INFO: 
Oct  4 06:41:01.088: INFO: The status of Pod coredns-7c949f49d5-p6f2z is Pending (Ready = false), waiting for it to be either Running (with Ready = true) or Failed
Oct  4 06:41:01.088: INFO: 10 / 11 pods in namespace 'kube-system' are running and ready (270 seconds elapsed)
Oct  4 06:41:01.088: INFO: expected 6 pod replicas in namespace 'kube-system', 5 are Running and Ready.
Oct  4 06:41:01.088: INFO: POD                       NODE  PHASE    GRACE  CONDITIONS
Oct  4 06:41:01.088: INFO: coredns-7c949f49d5-p6f2z        Pending         [{PodScheduled False 0001-01-01 00:00:00 +0000 UTC 2019-05-15 03:24:15 +0000 UTC Unschedulable 0/1 nodes are available: 1 node(s) didn't match pod affinity/anti-affinity, 1 node(s) didn't satisfy existing pods anti-affinity rules.}]
Oct  4 06:41:01.088: INFO: 
Oct  4 06:41:03.091: INFO: The status of Pod coredns-7c949f49d5-p6f2z is Pending (Ready = false), waiting for it to be either Running (with Ready = true) or Failed
Oct  4 06:41:03.091: INFO: 10 / 11 pods in namespace 'kube-system' are running and ready (272 seconds elapsed)
Oct  4 06:41:03.091: INFO: expected 6 pod replicas in namespace 'kube-system', 5 are Running and Ready.
Oct  4 06:41:03.091: INFO: POD                       NODE  PHASE    GRACE  CONDITIONS
Oct  4 06:41:03.091: INFO: coredns-7c949f49d5-p6f2z        Pending         [{PodScheduled False 0001-01-01 00:00:00 +0000 UTC 2019-05-15 03:24:15 +0000 UTC Unschedulable 0/1 nodes are available: 1 node(s) didn't match pod affinity/anti-affinity, 1 node(s) didn't satisfy existing pods anti-affinity rules.}]
Oct  4 06:41:03.091: INFO: 
Oct  4 06:41:05.081: INFO: The status of Pod coredns-7c949f49d5-p6f2z is Pending (Ready = false), waiting for it to be either Running (with Ready = true) or Failed
Oct  4 06:41:05.081: INFO: 10 / 11 pods in namespace 'kube-system' are running and ready (274 seconds elapsed)
Oct  4 06:41:05.081: INFO: expected 6 pod replicas in namespace 'kube-system', 5 are Running and Ready.
Oct  4 06:41:05.081: INFO: POD                       NODE  PHASE    GRACE  CONDITIONS
Oct  4 06:41:05.081: INFO: coredns-7c949f49d5-p6f2z        Pending         [{PodScheduled False 0001-01-01 00:00:00 +0000 UTC 2019-05-15 03:24:15 +0000 UTC Unschedulable 0/1 nodes are available: 1 node(s) didn't match pod affinity/anti-affinity, 1 node(s) didn't satisfy existing pods anti-affinity rules.}]
Oct  4 06:41:05.081: INFO: 
Oct  4 06:41:07.081: INFO: The status of Pod coredns-7c949f49d5-p6f2z is Pending (Ready = false), waiting for it to be either Running (with Ready = true) or Failed
Oct  4 06:41:07.081: INFO: 10 / 11 pods in namespace 'kube-system' are running and ready (276 seconds elapsed)
Oct  4 06:41:07.081: INFO: expected 6 pod replicas in namespace 'kube-system', 5 are Running and Ready.
Oct  4 06:41:07.081: INFO: POD                       NODE  PHASE    GRACE  CONDITIONS
Oct  4 06:41:07.081: INFO: coredns-7c949f49d5-p6f2z        Pending         [{PodScheduled False 0001-01-01 00:00:00 +0000 UTC 2019-05-15 03:24:15 +0000 UTC Unschedulable 0/1 nodes are available: 1 node(s) didn't match pod affinity/anti-affinity, 1 node(s) didn't satisfy existing pods anti-affinity rules.}]
Oct  4 06:41:07.081: INFO: 
Oct  4 06:41:09.082: INFO: The status of Pod coredns-7c949f49d5-p6f2z is Pending (Ready = false), waiting for it to be either Running (with Ready = true) or Failed
Oct  4 06:41:09.082: INFO: 10 / 11 pods in namespace 'kube-system' are running and ready (278 seconds elapsed)
Oct  4 06:41:09.082: INFO: expected 6 pod replicas in namespace 'kube-system', 5 are Running and Ready.
Oct  4 06:41:09.082: INFO: POD                       NODE  PHASE    GRACE  CONDITIONS
Oct  4 06:41:09.082: INFO: coredns-7c949f49d5-p6f2z        Pending         [{PodScheduled False 0001-01-01 00:00:00 +0000 UTC 2019-05-15 03:24:15 +0000 UTC Unschedulable 0/1 nodes are available: 1 node(s) didn't match pod affinity/anti-affinity, 1 node(s) didn't satisfy existing pods anti-affinity rules.}]
Oct  4 06:41:09.082: INFO: 
Oct  4 06:41:11.091: INFO: The status of Pod coredns-7c949f49d5-p6f2z is Pending (Ready = false), waiting for it to be either Running (with Ready = true) or Failed
Oct  4 06:41:11.091: INFO: 10 / 11 pods in namespace 'kube-system' are running and ready (280 seconds elapsed)
Oct  4 06:41:11.091: INFO: expected 6 pod replicas in namespace 'kube-system', 5 are Running and Ready.
Oct  4 06:41:11.091: INFO: POD                       NODE  PHASE    GRACE  CONDITIONS
Oct  4 06:41:11.091: INFO: coredns-7c949f49d5-p6f2z        Pending         [{PodScheduled False 0001-01-01 00:00:00 +0000 UTC 2019-05-15 03:24:15 +0000 UTC Unschedulable 0/1 nodes are available: 1 node(s) didn't match pod affinity/anti-affinity, 1 node(s) didn't satisfy existing pods anti-affinity rules.}]
Oct  4 06:41:11.091: INFO: 
Oct  4 06:41:13.115: INFO: The status of Pod coredns-7c949f49d5-p6f2z is Pending (Ready = false), waiting for it to be either Running (with Ready = true) or Failed
Oct  4 06:41:13.115: INFO: 10 / 11 pods in namespace 'kube-system' are running and ready (282 seconds elapsed)
Oct  4 06:41:13.115: INFO: expected 6 pod replicas in namespace 'kube-system', 5 are Running and Ready.
Oct  4 06:41:13.115: INFO: POD                       NODE  PHASE    GRACE  CONDITIONS
Oct  4 06:41:13.115: INFO: coredns-7c949f49d5-p6f2z        Pending         [{PodScheduled False 0001-01-01 00:00:00 +0000 UTC 2019-05-15 03:24:15 +0000 UTC Unschedulable 0/1 nodes are available: 1 node(s) didn't match pod affinity/anti-affinity, 1 node(s) didn't satisfy existing pods anti-affinity rules.}]
Oct  4 06:41:13.115: INFO: 
Oct  4 06:41:15.082: INFO: The status of Pod coredns-7c949f49d5-p6f2z is Pending (Ready = false), waiting for it to be either Running (with Ready = true) or Failed
Oct  4 06:41:15.082: INFO: 10 / 11 pods in namespace 'kube-system' are running and ready (284 seconds elapsed)
Oct  4 06:41:15.082: INFO: expected 6 pod replicas in namespace 'kube-system', 5 are Running and Ready.
Oct  4 06:41:15.082: INFO: POD                       NODE  PHASE    GRACE  CONDITIONS
Oct  4 06:41:15.082: INFO: coredns-7c949f49d5-p6f2z        Pending         [{PodScheduled False 0001-01-01 00:00:00 +0000 UTC 2019-05-15 03:24:15 +0000 UTC Unschedulable 0/1 nodes are available: 1 node(s) didn't match pod affinity/anti-affinity, 1 node(s) didn't satisfy existing pods anti-affinity rules.}]
Oct  4 06:41:15.082: INFO: 
Oct  4 06:41:17.091: INFO: The status of Pod coredns-7c949f49d5-p6f2z is Pending (Ready = false), waiting for it to be either Running (with Ready = true) or Failed
Oct  4 06:41:17.091: INFO: 10 / 11 pods in namespace 'kube-system' are running and ready (286 seconds elapsed)
Oct  4 06:41:17.091: INFO: expected 6 pod replicas in namespace 'kube-system', 5 are Running and Ready.
Oct  4 06:41:17.091: INFO: POD                       NODE  PHASE    GRACE  CONDITIONS
Oct  4 06:41:17.091: INFO: coredns-7c949f49d5-p6f2z        Pending         [{PodScheduled False 0001-01-01 00:00:00 +0000 UTC 2019-05-15 03:24:15 +0000 UTC Unschedulable 0/1 nodes are available: 1 node(s) didn't match pod affinity/anti-affinity, 1 node(s) didn't satisfy existing pods anti-affinity rules.}]
Oct  4 06:41:17.091: INFO: 
Oct  4 06:41:19.084: INFO: The status of Pod coredns-7c949f49d5-p6f2z is Pending (Ready = false), waiting for it to be either Running (with Ready = true) or Failed
Oct  4 06:41:19.084: INFO: 10 / 11 pods in namespace 'kube-system' are running and ready (288 seconds elapsed)
Oct  4 06:41:19.084: INFO: expected 6 pod replicas in namespace 'kube-system', 5 are Running and Ready.
Oct  4 06:41:19.084: INFO: POD                       NODE  PHASE    GRACE  CONDITIONS
Oct  4 06:41:19.084: INFO: coredns-7c949f49d5-p6f2z        Pending         [{PodScheduled False 0001-01-01 00:00:00 +0000 UTC 2019-05-15 03:24:15 +0000 UTC Unschedulable 0/1 nodes are available: 1 node(s) didn't match pod affinity/anti-affinity, 1 node(s) didn't satisfy existing pods anti-affinity rules.}]
Oct  4 06:41:19.084: INFO: 
Oct  4 06:41:21.090: INFO: The status of Pod coredns-7c949f49d5-p6f2z is Pending (Ready = false), waiting for it to be either Running (with Ready = true) or Failed
Oct  4 06:41:21.090: INFO: 10 / 11 pods in namespace 'kube-system' are running and ready (290 seconds elapsed)
Oct  4 06:41:21.090: INFO: expected 6 pod replicas in namespace 'kube-system', 5 are Running and Ready.
Oct  4 06:41:21.090: INFO: POD                       NODE  PHASE    GRACE  CONDITIONS
Oct  4 06:41:21.090: INFO: coredns-7c949f49d5-p6f2z        Pending         [{PodScheduled False 0001-01-01 00:00:00 +0000 UTC 2019-05-15 03:24:15 +0000 UTC Unschedulable 0/1 nodes are available: 1 node(s) didn't match pod affinity/anti-affinity, 1 node(s) didn't satisfy existing pods anti-affinity rules.}]
Oct  4 06:41:21.090: INFO: 
Oct  4 06:41:23.081: INFO: The status of Pod coredns-7c949f49d5-p6f2z is Pending (Ready = false), waiting for it to be either Running (with Ready = true) or Failed
Oct  4 06:41:23.081: INFO: 10 / 11 pods in namespace 'kube-system' are running and ready (292 seconds elapsed)
Oct  4 06:41:23.081: INFO: expected 6 pod replicas in namespace 'kube-system', 5 are Running and Ready.
Oct  4 06:41:23.081: INFO: POD                       NODE  PHASE    GRACE  CONDITIONS
Oct  4 06:41:23.081: INFO: coredns-7c949f49d5-p6f2z        Pending         [{PodScheduled False 0001-01-01 00:00:00 +0000 UTC 2019-05-15 03:24:15 +0000 UTC Unschedulable 0/1 nodes are available: 1 node(s) didn't match pod affinity/anti-affinity, 1 node(s) didn't satisfy existing pods anti-affinity rules.}]
Oct  4 06:41:23.081: INFO: 
Oct  4 06:41:25.081: INFO: The status of Pod coredns-7c949f49d5-p6f2z is Pending (Ready = false), waiting for it to be either Running (with Ready = true) or Failed
Oct  4 06:41:25.081: INFO: 10 / 11 pods in namespace 'kube-system' are running and ready (294 seconds elapsed)
Oct  4 06:41:25.081: INFO: expected 6 pod replicas in namespace 'kube-system', 5 are Running and Ready.
Oct  4 06:41:25.081: INFO: POD                       NODE  PHASE    GRACE  CONDITIONS
Oct  4 06:41:25.081: INFO: coredns-7c949f49d5-p6f2z        Pending         [{PodScheduled False 0001-01-01 00:00:00 +0000 UTC 2019-05-15 03:24:15 +0000 UTC Unschedulable 0/1 nodes are available: 1 node(s) didn't match pod affinity/anti-affinity, 1 node(s) didn't satisfy existing pods anti-affinity rules.}]
Oct  4 06:41:25.081: INFO: 
Oct  4 06:41:27.088: INFO: The status of Pod coredns-7c949f49d5-p6f2z is Pending (Ready = false), waiting for it to be either Running (with Ready = true) or Failed
Oct  4 06:41:27.088: INFO: 10 / 11 pods in namespace 'kube-system' are running and ready (296 seconds elapsed)
Oct  4 06:41:27.088: INFO: expected 6 pod replicas in namespace 'kube-system', 5 are Running and Ready.
Oct  4 06:41:27.088: INFO: POD                       NODE  PHASE    GRACE  CONDITIONS
Oct  4 06:41:27.088: INFO: coredns-7c949f49d5-p6f2z        Pending         [{PodScheduled False 0001-01-01 00:00:00 +0000 UTC 2019-05-15 03:24:15 +0000 UTC Unschedulable 0/1 nodes are available: 1 node(s) didn't match pod affinity/anti-affinity, 1 node(s) didn't satisfy existing pods anti-affinity rules.}]
Oct  4 06:41:27.088: INFO: 
Oct  4 06:41:29.097: INFO: The status of Pod coredns-7c949f49d5-p6f2z is Pending (Ready = false), waiting for it to be either Running (with Ready = true) or Failed
Oct  4 06:41:29.097: INFO: 10 / 11 pods in namespace 'kube-system' are running and ready (298 seconds elapsed)
Oct  4 06:41:29.097: INFO: expected 6 pod replicas in namespace 'kube-system', 5 are Running and Ready.
Oct  4 06:41:29.097: INFO: POD                       NODE  PHASE    GRACE  CONDITIONS
Oct  4 06:41:29.097: INFO: coredns-7c949f49d5-p6f2z        Pending         [{PodScheduled False 0001-01-01 00:00:00 +0000 UTC 2019-05-15 03:24:15 +0000 UTC Unschedulable 0/1 nodes are available: 1 node(s) didn't match pod affinity/anti-affinity, 1 node(s) didn't satisfy existing pods anti-affinity rules.}]
Oct  4 06:41:29.097: INFO: 
Oct  4 06:41:31.312: INFO: The status of Pod coredns-7c949f49d5-p6f2z is Pending (Ready = false), waiting for it to be either Running (with Ready = true) or Failed
Oct  4 06:41:31.312: INFO: 10 / 11 pods in namespace 'kube-system' are running and ready (300 seconds elapsed)
Oct  4 06:41:31.312: INFO: expected 6 pod replicas in namespace 'kube-system', 5 are Running and Ready.
Oct  4 06:41:31.312: INFO: POD                       NODE  PHASE    GRACE  CONDITIONS
Oct  4 06:41:31.312: INFO: coredns-7c949f49d5-p6f2z        Pending         [{PodScheduled False 0001-01-01 00:00:00 +0000 UTC 2019-05-15 03:24:15 +0000 UTC Unschedulable 0/1 nodes are available: 1 node(s) didn't match pod affinity/anti-affinity, 1 node(s) didn't satisfy existing pods anti-affinity rules.}]
Oct  4 06:41:31.312: INFO: 
Oct  4 06:41:33.088: INFO: The status of Pod coredns-7c949f49d5-p6f2z is Pending (Ready = false), waiting for it to be either Running (with Ready = true) or Failed
Oct  4 06:41:33.088: INFO: 10 / 11 pods in namespace 'kube-system' are running and ready (302 seconds elapsed)
Oct  4 06:41:33.088: INFO: expected 6 pod replicas in namespace 'kube-system', 5 are Running and Ready.
Oct  4 06:41:33.088: INFO: POD                       NODE  PHASE    GRACE  CONDITIONS
Oct  4 06:41:33.088: INFO: coredns-7c949f49d5-p6f2z        Pending         [{PodScheduled False 0001-01-01 00:00:00 +0000 UTC 2019-05-15 03:24:15 +0000 UTC Unschedulable 0/1 nodes are available: 1 node(s) didn't match pod affinity/anti-affinity, 1 node(s) didn't satisfy existing pods anti-affinity rules.}]
Oct  4 06:41:33.088: INFO: 
Oct  4 06:41:35.081: INFO: The status of Pod coredns-7c949f49d5-p6f2z is Pending (Ready = false), waiting for it to be either Running (with Ready = true) or Failed
Oct  4 06:41:35.081: INFO: 10 / 11 pods in namespace 'kube-system' are running and ready (304 seconds elapsed)
Oct  4 06:41:35.081: INFO: expected 6 pod replicas in namespace 'kube-system', 5 are Running and Ready.
Oct  4 06:41:35.081: INFO: POD                       NODE  PHASE    GRACE  CONDITIONS
Oct  4 06:41:35.081: INFO: coredns-7c949f49d5-p6f2z        Pending         [{PodScheduled False 0001-01-01 00:00:00 +0000 UTC 2019-05-15 03:24:15 +0000 UTC Unschedulable 0/1 nodes are available: 1 node(s) didn't match pod affinity/anti-affinity, 1 node(s) didn't satisfy existing pods anti-affinity rules.}]
Oct  4 06:41:35.081: INFO: 
Oct  4 06:41:37.574: INFO: The status of Pod coredns-7c949f49d5-p6f2z is Pending (Ready = false), waiting for it to be either Running (with Ready = true) or Failed
Oct  4 06:41:37.574: INFO: 10 / 11 pods in namespace 'kube-system' are running and ready (306 seconds elapsed)
Oct  4 06:41:37.574: INFO: expected 6 pod replicas in namespace 'kube-system', 5 are Running and Ready.
Oct  4 06:41:37.574: INFO: POD                       NODE  PHASE    GRACE  CONDITIONS
Oct  4 06:41:37.574: INFO: coredns-7c949f49d5-p6f2z        Pending         [{PodScheduled False 0001-01-01 00:00:00 +0000 UTC 2019-05-15 03:24:15 +0000 UTC Unschedulable 0/1 nodes are available: 1 node(s) didn't match pod affinity/anti-affinity, 1 node(s) didn't satisfy existing pods anti-affinity rules.}]
Oct  4 06:41:37.574: INFO: 
Oct  4 06:41:39.236: INFO: The status of Pod coredns-7c949f49d5-p6f2z is Pending (Ready = false), waiting for it to be either Running (with Ready = true) or Failed
Oct  4 06:41:39.236: INFO: 10 / 11 pods in namespace 'kube-system' are running and ready (308 seconds elapsed)
Oct  4 06:41:39.236: INFO: expected 6 pod replicas in namespace 'kube-system', 5 are Running and Ready.
Oct  4 06:41:39.236: INFO: POD                       NODE  PHASE    GRACE  CONDITIONS
Oct  4 06:41:39.236: INFO: coredns-7c949f49d5-p6f2z        Pending         [{PodScheduled False 0001-01-01 00:00:00 +0000 UTC 2019-05-15 03:24:15 +0000 UTC Unschedulable 0/1 nodes are available: 1 node(s) didn't match pod affinity/anti-affinity, 1 node(s) didn't satisfy existing pods anti-affinity rules.}]
Oct  4 06:41:39.236: INFO: 
Oct  4 06:41:41.082: INFO: The status of Pod coredns-7c949f49d5-p6f2z is Pending (Ready = false), waiting for it to be either Running (with Ready = true) or Failed
Oct  4 06:41:41.082: INFO: 10 / 11 pods in namespace 'kube-system' are running and ready (310 seconds elapsed)
Oct  4 06:41:41.082: INFO: expected 6 pod replicas in namespace 'kube-system', 5 are Running and Ready.
Oct  4 06:41:41.082: INFO: POD                       NODE  PHASE    GRACE  CONDITIONS
Oct  4 06:41:41.082: INFO: coredns-7c949f49d5-p6f2z        Pending         [{PodScheduled False 0001-01-01 00:00:00 +0000 UTC 2019-05-15 03:24:15 +0000 UTC Unschedulable 0/1 nodes are available: 1 node(s) didn't match pod affinity/anti-affinity, 1 node(s) didn't satisfy existing pods anti-affinity rules.}]
Oct  4 06:41:41.082: INFO: 
Oct  4 06:41:43.082: INFO: The status of Pod coredns-7c949f49d5-p6f2z is Pending (Ready = false), waiting for it to be either Running (with Ready = true) or Failed
Oct  4 06:41:43.082: INFO: 10 / 11 pods in namespace 'kube-system' are running and ready (312 seconds elapsed)
Oct  4 06:41:43.082: INFO: expected 6 pod replicas in namespace 'kube-system', 5 are Running and Ready.
Oct  4 06:41:43.082: INFO: POD                       NODE  PHASE    GRACE  CONDITIONS
Oct  4 06:41:43.082: INFO: coredns-7c949f49d5-p6f2z        Pending         [{PodScheduled False 0001-01-01 00:00:00 +0000 UTC 2019-05-15 03:24:15 +0000 UTC Unschedulable 0/1 nodes are available: 1 node(s) didn't match pod affinity/anti-affinity, 1 node(s) didn't satisfy existing pods anti-affinity rules.}]
Oct  4 06:41:43.082: INFO: 
Oct  4 06:41:45.116: INFO: The status of Pod coredns-7c949f49d5-p6f2z is Pending (Ready = false), waiting for it to be either Running (with Ready = true) or Failed
Oct  4 06:41:45.116: INFO: 10 / 11 pods in namespace 'kube-system' are running and ready (314 seconds elapsed)
Oct  4 06:41:45.116: INFO: expected 6 pod replicas in namespace 'kube-system', 5 are Running and Ready.
Oct  4 06:41:45.116: INFO: POD                       NODE  PHASE    GRACE  CONDITIONS
Oct  4 06:41:45.116: INFO: coredns-7c949f49d5-p6f2z        Pending         [{PodScheduled False 0001-01-01 00:00:00 +0000 UTC 2019-05-15 03:24:15 +0000 UTC Unschedulable 0/1 nodes are available: 1 node(s) didn't match pod affinity/anti-affinity, 1 node(s) didn't satisfy existing pods anti-affinity rules.}]
Oct  4 06:41:45.116: INFO: 
Oct  4 06:41:47.091: INFO: The status of Pod coredns-7c949f49d5-p6f2z is Pending (Ready = false), waiting for it to be either Running (with Ready = true) or Failed
Oct  4 06:41:47.091: INFO: 10 / 11 pods in namespace 'kube-system' are running and ready (316 seconds elapsed)
Oct  4 06:41:47.091: INFO: expected 6 pod replicas in namespace 'kube-system', 5 are Running and Ready.
Oct  4 06:41:47.091: INFO: POD                       NODE  PHASE    GRACE  CONDITIONS
Oct  4 06:41:47.091: INFO: coredns-7c949f49d5-p6f2z        Pending         [{PodScheduled False 0001-01-01 00:00:00 +0000 UTC 2019-05-15 03:24:15 +0000 UTC Unschedulable 0/1 nodes are available: 1 node(s) didn't match pod affinity/anti-affinity, 1 node(s) didn't satisfy existing pods anti-affinity rules.}]
Oct  4 06:41:47.091: INFO: 
Oct  4 06:41:49.091: INFO: The status of Pod coredns-7c949f49d5-p6f2z is Pending (Ready = false), waiting for it to be either Running (with Ready = true) or Failed
Oct  4 06:41:49.091: INFO: 10 / 11 pods in namespace 'kube-system' are running and ready (318 seconds elapsed)
Oct  4 06:41:49.091: INFO: expected 6 pod replicas in namespace 'kube-system', 5 are Running and Ready.
Oct  4 06:41:49.091: INFO: POD                       NODE  PHASE    GRACE  CONDITIONS
Oct  4 06:41:49.091: INFO: coredns-7c949f49d5-p6f2z        Pending         [{PodScheduled False 0001-01-01 00:00:00 +0000 UTC 2019-05-15 03:24:15 +0000 UTC Unschedulable 0/1 nodes are available: 1 node(s) didn't match pod affinity/anti-affinity, 1 node(s) didn't satisfy existing pods anti-affinity rules.}]
Oct  4 06:41:49.091: INFO: 
Oct  4 06:41:51.091: INFO: The status of Pod coredns-7c949f49d5-p6f2z is Pending (Ready = false), waiting for it to be either Running (with Ready = true) or Failed
Oct  4 06:41:51.091: INFO: 10 / 11 pods in namespace 'kube-system' are running and ready (320 seconds elapsed)
Oct  4 06:41:51.091: INFO: expected 6 pod replicas in namespace 'kube-system', 5 are Running and Ready.
Oct  4 06:41:51.091: INFO: POD                       NODE  PHASE    GRACE  CONDITIONS
Oct  4 06:41:51.091: INFO: coredns-7c949f49d5-p6f2z        Pending         [{PodScheduled False 0001-01-01 00:00:00 +0000 UTC 2019-05-15 03:24:15 +0000 UTC Unschedulable 0/1 nodes are available: 1 node(s) didn't match pod affinity/anti-affinity, 1 node(s) didn't satisfy existing pods anti-affinity rules.}]
Oct  4 06:41:51.091: INFO: 
Oct  4 06:41:53.239: INFO: The status of Pod coredns-7c949f49d5-p6f2z is Pending (Ready = false), waiting for it to be either Running (with Ready = true) or Failed
Oct  4 06:41:53.239: INFO: 10 / 11 pods in namespace 'kube-system' are running and ready (322 seconds elapsed)
Oct  4 06:41:53.239: INFO: expected 6 pod replicas in namespace 'kube-system', 5 are Running and Ready.
Oct  4 06:41:53.239: INFO: POD                       NODE  PHASE    GRACE  CONDITIONS
Oct  4 06:41:53.239: INFO: coredns-7c949f49d5-p6f2z        Pending         [{PodScheduled False 0001-01-01 00:00:00 +0000 UTC 2019-05-15 03:24:15 +0000 UTC Unschedulable 0/1 nodes are available: 1 node(s) didn't match pod affinity/anti-affinity, 1 node(s) didn't satisfy existing pods anti-affinity rules.}]
Oct  4 06:41:53.239: INFO: 
Oct  4 06:41:55.082: INFO: The status of Pod coredns-7c949f49d5-p6f2z is Pending (Ready = false), waiting for it to be either Running (with Ready = true) or Failed
Oct  4 06:41:55.082: INFO: 10 / 11 pods in namespace 'kube-system' are running and ready (324 seconds elapsed)
Oct  4 06:41:55.082: INFO: expected 6 pod replicas in namespace 'kube-system', 5 are Running and Ready.
Oct  4 06:41:55.082: INFO: POD                       NODE  PHASE    GRACE  CONDITIONS
Oct  4 06:41:55.082: INFO: coredns-7c949f49d5-p6f2z        Pending         [{PodScheduled False 0001-01-01 00:00:00 +0000 UTC 2019-05-15 03:24:15 +0000 UTC Unschedulable 0/1 nodes are available: 1 node(s) didn't match pod affinity/anti-affinity, 1 node(s) didn't satisfy existing pods anti-affinity rules.}]
Oct  4 06:41:55.082: INFO: 
Oct  4 06:41:57.090: INFO: The status of Pod coredns-7c949f49d5-p6f2z is Pending (Ready = false), waiting for it to be either Running (with Ready = true) or Failed
Oct  4 06:41:57.090: INFO: 10 / 11 pods in namespace 'kube-system' are running and ready (326 seconds elapsed)
Oct  4 06:41:57.090: INFO: expected 6 pod replicas in namespace 'kube-system', 5 are Running and Ready.
Oct  4 06:41:57.090: INFO: POD                       NODE  PHASE    GRACE  CONDITIONS
Oct  4 06:41:57.090: INFO: coredns-7c949f49d5-p6f2z        Pending         [{PodScheduled False 0001-01-01 00:00:00 +0000 UTC 2019-05-15 03:24:15 +0000 UTC Unschedulable 0/1 nodes are available: 1 node(s) didn't match pod affinity/anti-affinity, 1 node(s) didn't satisfy existing pods anti-affinity rules.}]
Oct  4 06:41:57.090: INFO: 
Oct  4 06:41:59.080: INFO: The status of Pod coredns-7c949f49d5-p6f2z is Pending (Ready = false), waiting for it to be either Running (with Ready = true) or Failed
Oct  4 06:41:59.080: INFO: 10 / 11 pods in namespace 'kube-system' are running and ready (328 seconds elapsed)
Oct  4 06:41:59.080: INFO: expected 6 pod replicas in namespace 'kube-system', 5 are Running and Ready.
Oct  4 06:41:59.080: INFO: POD                       NODE  PHASE    GRACE  CONDITIONS
Oct  4 06:41:59.080: INFO: coredns-7c949f49d5-p6f2z        Pending         [{PodScheduled False 0001-01-01 00:00:00 +0000 UTC 2019-05-15 03:24:15 +0000 UTC Unschedulable 0/1 nodes are available: 1 node(s) didn't match pod affinity/anti-affinity, 1 node(s) didn't satisfy existing pods anti-affinity rules.}]
Oct  4 06:41:59.080: INFO: 
Oct  4 06:42:01.093: INFO: The status of Pod coredns-7c949f49d5-p6f2z is Pending (Ready = false), waiting for it to be either Running (with Ready = true) or Failed
Oct  4 06:42:01.094: INFO: 10 / 11 pods in namespace 'kube-system' are running and ready (330 seconds elapsed)
Oct  4 06:42:01.094: INFO: expected 6 pod replicas in namespace 'kube-system', 5 are Running and Ready.
Oct  4 06:42:01.094: INFO: POD                       NODE  PHASE    GRACE  CONDITIONS
Oct  4 06:42:01.094: INFO: coredns-7c949f49d5-p6f2z        Pending         [{PodScheduled False 0001-01-01 00:00:00 +0000 UTC 2019-05-15 03:24:15 +0000 UTC Unschedulable 0/1 nodes are available: 1 node(s) didn't match pod affinity/anti-affinity, 1 node(s) didn't satisfy existing pods anti-affinity rules.}]
Oct  4 06:42:01.094: INFO: 
Oct  4 06:42:03.081: INFO: The status of Pod coredns-7c949f49d5-p6f2z is Pending (Ready = false), waiting for it to be either Running (with Ready = true) or Failed
Oct  4 06:42:03.081: INFO: 10 / 11 pods in namespace 'kube-system' are running and ready (332 seconds elapsed)
Oct  4 06:42:03.081: INFO: expected 6 pod replicas in namespace 'kube-system', 5 are Running and Ready.
Oct  4 06:42:03.081: INFO: POD                       NODE  PHASE    GRACE  CONDITIONS
Oct  4 06:42:03.081: INFO: coredns-7c949f49d5-p6f2z        Pending         [{PodScheduled False 0001-01-01 00:00:00 +0000 UTC 2019-05-15 03:24:15 +0000 UTC Unschedulable 0/1 nodes are available: 1 node(s) didn't match pod affinity/anti-affinity, 1 node(s) didn't satisfy existing pods anti-affinity rules.}]
Oct  4 06:42:03.081: INFO: 
Oct  4 06:42:05.185: INFO: The status of Pod coredns-7c949f49d5-p6f2z is Pending (Ready = false), waiting for it to be either Running (with Ready = true) or Failed
Oct  4 06:42:05.185: INFO: 10 / 11 pods in namespace 'kube-system' are running and ready (334 seconds elapsed)
Oct  4 06:42:05.185: INFO: expected 6 pod replicas in namespace 'kube-system', 5 are Running and Ready.
Oct  4 06:42:05.185: INFO: POD                       NODE  PHASE    GRACE  CONDITIONS
Oct  4 06:42:05.185: INFO: coredns-7c949f49d5-p6f2z        Pending         [{PodScheduled False 0001-01-01 00:00:00 +0000 UTC 2019-05-15 03:24:15 +0000 UTC Unschedulable 0/1 nodes are available: 1 node(s) didn't match pod affinity/anti-affinity, 1 node(s) didn't satisfy existing pods anti-affinity rules.}]
Oct  4 06:42:05.186: INFO: 
Oct  4 06:42:07.083: INFO: The status of Pod coredns-7c949f49d5-p6f2z is Pending (Ready = false), waiting for it to be either Running (with Ready = true) or Failed
Oct  4 06:42:07.083: INFO: 10 / 11 pods in namespace 'kube-system' are running and ready (336 seconds elapsed)
Oct  4 06:42:07.083: INFO: expected 6 pod replicas in namespace 'kube-system', 5 are Running and Ready.
Oct  4 06:42:07.083: INFO: POD                       NODE  PHASE    GRACE  CONDITIONS
Oct  4 06:42:07.083: INFO: coredns-7c949f49d5-p6f2z        Pending         [{PodScheduled False 0001-01-01 00:00:00 +0000 UTC 2019-05-15 03:24:15 +0000 UTC Unschedulable 0/1 nodes are available: 1 node(s) didn't match pod affinity/anti-affinity, 1 node(s) didn't satisfy existing pods anti-affinity rules.}]
Oct  4 06:42:07.083: INFO: 
Oct  4 06:42:09.082: INFO: The status of Pod coredns-7c949f49d5-p6f2z is Pending (Ready = false), waiting for it to be either Running (with Ready = true) or Failed
Oct  4 06:42:09.082: INFO: 10 / 11 pods in namespace 'kube-system' are running and ready (338 seconds elapsed)
Oct  4 06:42:09.082: INFO: expected 6 pod replicas in namespace 'kube-system', 5 are Running and Ready.
Oct  4 06:42:09.082: INFO: POD                       NODE  PHASE    GRACE  CONDITIONS
Oct  4 06:42:09.082: INFO: coredns-7c949f49d5-p6f2z        Pending         [{PodScheduled False 0001-01-01 00:00:00 +0000 UTC 2019-05-15 03:24:15 +0000 UTC Unschedulable 0/1 nodes are available: 1 node(s) didn't match pod affinity/anti-affinity, 1 node(s) didn't satisfy existing pods anti-affinity rules.}]
Oct  4 06:42:09.082: INFO: 
Oct  4 06:42:11.091: INFO: The status of Pod coredns-7c949f49d5-p6f2z is Pending (Ready = false), waiting for it to be either Running (with Ready = true) or Failed
Oct  4 06:42:11.091: INFO: 10 / 11 pods in namespace 'kube-system' are running and ready (340 seconds elapsed)
Oct  4 06:42:11.091: INFO: expected 6 pod replicas in namespace 'kube-system', 5 are Running and Ready.
Oct  4 06:42:11.091: INFO: POD                       NODE  PHASE    GRACE  CONDITIONS
Oct  4 06:42:11.091: INFO: coredns-7c949f49d5-p6f2z        Pending         [{PodScheduled False 0001-01-01 00:00:00 +0000 UTC 2019-05-15 03:24:15 +0000 UTC Unschedulable 0/1 nodes are available: 1 node(s) didn't match pod affinity/anti-affinity, 1 node(s) didn't satisfy existing pods anti-affinity rules.}]
Oct  4 06:42:11.091: INFO: 
Oct  4 06:42:13.081: INFO: The status of Pod coredns-7c949f49d5-p6f2z is Pending (Ready = false), waiting for it to be either Running (with Ready = true) or Failed
Oct  4 06:42:13.081: INFO: 10 / 11 pods in namespace 'kube-system' are running and ready (342 seconds elapsed)
Oct  4 06:42:13.081: INFO: expected 6 pod replicas in namespace 'kube-system', 5 are Running and Ready.
Oct  4 06:42:13.081: INFO: POD                       NODE  PHASE    GRACE  CONDITIONS
Oct  4 06:42:13.081: INFO: coredns-7c949f49d5-p6f2z        Pending         [{PodScheduled False 0001-01-01 00:00:00 +0000 UTC 2019-05-15 03:24:15 +0000 UTC Unschedulable 0/1 nodes are available: 1 node(s) didn't match pod affinity/anti-affinity, 1 node(s) didn't satisfy existing pods anti-affinity rules.}]
Oct  4 06:42:13.081: INFO: 
Oct  4 06:42:15.081: INFO: The status of Pod coredns-7c949f49d5-p6f2z is Pending (Ready = false), waiting for it to be either Running (with Ready = true) or Failed
Oct  4 06:42:15.081: INFO: 10 / 11 pods in namespace 'kube-system' are running and ready (344 seconds elapsed)
Oct  4 06:42:15.081: INFO: expected 6 pod replicas in namespace 'kube-system', 5 are Running and Ready.
Oct  4 06:42:15.081: INFO: POD                       NODE  PHASE    GRACE  CONDITIONS
Oct  4 06:42:15.081: INFO: coredns-7c949f49d5-p6f2z        Pending         [{PodScheduled False 0001-01-01 00:00:00 +0000 UTC 2019-05-15 03:24:15 +0000 UTC Unschedulable 0/1 nodes are available: 1 node(s) didn't match pod affinity/anti-affinity, 1 node(s) didn't satisfy existing pods anti-affinity rules.}]
Oct  4 06:42:15.081: INFO: 
Oct  4 06:42:17.090: INFO: The status of Pod coredns-7c949f49d5-p6f2z is Pending (Ready = false), waiting for it to be either Running (with Ready = true) or Failed
Oct  4 06:42:17.090: INFO: 10 / 11 pods in namespace 'kube-system' are running and ready (346 seconds elapsed)
Oct  4 06:42:17.090: INFO: expected 6 pod replicas in namespace 'kube-system', 5 are Running and Ready.
Oct  4 06:42:17.090: INFO: POD                       NODE  PHASE    GRACE  CONDITIONS
Oct  4 06:42:17.091: INFO: coredns-7c949f49d5-p6f2z        Pending         [{PodScheduled False 0001-01-01 00:00:00 +0000 UTC 2019-05-15 03:24:15 +0000 UTC Unschedulable 0/1 nodes are available: 1 node(s) didn't match pod affinity/anti-affinity, 1 node(s) didn't satisfy existing pods anti-affinity rules.}]
Oct  4 06:42:17.091: INFO: 
Oct  4 06:42:19.089: INFO: The status of Pod coredns-7c949f49d5-p6f2z is Pending (Ready = false), waiting for it to be either Running (with Ready = true) or Failed
Oct  4 06:42:19.089: INFO: 10 / 11 pods in namespace 'kube-system' are running and ready (348 seconds elapsed)
Oct  4 06:42:19.089: INFO: expected 6 pod replicas in namespace 'kube-system', 5 are Running and Ready.
Oct  4 06:42:19.089: INFO: POD                       NODE  PHASE    GRACE  CONDITIONS
Oct  4 06:42:19.089: INFO: coredns-7c949f49d5-p6f2z        Pending         [{PodScheduled False 0001-01-01 00:00:00 +0000 UTC 2019-05-15 03:24:15 +0000 UTC Unschedulable 0/1 nodes are available: 1 node(s) didn't match pod affinity/anti-affinity, 1 node(s) didn't satisfy existing pods anti-affinity rules.}]
Oct  4 06:42:19.089: INFO: 
Oct  4 06:42:21.090: INFO: The status of Pod coredns-7c949f49d5-p6f2z is Pending (Ready = false), waiting for it to be either Running (with Ready = true) or Failed
Oct  4 06:42:21.090: INFO: 10 / 11 pods in namespace 'kube-system' are running and ready (350 seconds elapsed)
Oct  4 06:42:21.090: INFO: expected 6 pod replicas in namespace 'kube-system', 5 are Running and Ready.
Oct  4 06:42:21.090: INFO: POD                       NODE  PHASE    GRACE  CONDITIONS
Oct  4 06:42:21.090: INFO: coredns-7c949f49d5-p6f2z        Pending         [{PodScheduled False 0001-01-01 00:00:00 +0000 UTC 2019-05-15 03:24:15 +0000 UTC Unschedulable 0/1 nodes are available: 1 node(s) didn't match pod affinity/anti-affinity, 1 node(s) didn't satisfy existing pods anti-affinity rules.}]
Oct  4 06:42:21.090: INFO: 
Oct  4 06:42:23.197: INFO: The status of Pod coredns-7c949f49d5-p6f2z is Pending (Ready = false), waiting for it to be either Running (with Ready = true) or Failed
Oct  4 06:42:23.197: INFO: 10 / 11 pods in namespace 'kube-system' are running and ready (352 seconds elapsed)
Oct  4 06:42:23.197: INFO: expected 6 pod replicas in namespace 'kube-system', 5 are Running and Ready.
Oct  4 06:42:23.197: INFO: POD                       NODE  PHASE    GRACE  CONDITIONS
Oct  4 06:42:23.197: INFO: coredns-7c949f49d5-p6f2z        Pending         [{PodScheduled False 0001-01-01 00:00:00 +0000 UTC 2019-05-15 03:24:15 +0000 UTC Unschedulable 0/1 nodes are available: 1 node(s) didn't match pod affinity/anti-affinity, 1 node(s) didn't satisfy existing pods anti-affinity rules.}]
Oct  4 06:42:23.197: INFO: 
Oct  4 06:42:25.082: INFO: The status of Pod coredns-7c949f49d5-p6f2z is Pending (Ready = false), waiting for it to be either Running (with Ready = true) or Failed
Oct  4 06:42:25.082: INFO: 10 / 11 pods in namespace 'kube-system' are running and ready (354 seconds elapsed)
Oct  4 06:42:25.082: INFO: expected 6 pod replicas in namespace 'kube-system', 5 are Running and Ready.
Oct  4 06:42:25.082: INFO: POD                       NODE  PHASE    GRACE  CONDITIONS
Oct  4 06:42:25.082: INFO: coredns-7c949f49d5-p6f2z        Pending         [{PodScheduled False 0001-01-01 00:00:00 +0000 UTC 2019-05-15 03:24:15 +0000 UTC Unschedulable 0/1 nodes are available: 1 node(s) didn't match pod affinity/anti-affinity, 1 node(s) didn't satisfy existing pods anti-affinity rules.}]
Oct  4 06:42:25.082: INFO: 
Oct  4 06:42:27.090: INFO: The status of Pod coredns-7c949f49d5-p6f2z is Pending (Ready = false), waiting for it to be either Running (with Ready = true) or Failed
Oct  4 06:42:27.090: INFO: 10 / 11 pods in namespace 'kube-system' are running and ready (356 seconds elapsed)
Oct  4 06:42:27.090: INFO: expected 6 pod replicas in namespace 'kube-system', 5 are Running and Ready.
Oct  4 06:42:27.090: INFO: POD                       NODE  PHASE    GRACE  CONDITIONS
Oct  4 06:42:27.090: INFO: coredns-7c949f49d5-p6f2z        Pending         [{PodScheduled False 0001-01-01 00:00:00 +0000 UTC 2019-05-15 03:24:15 +0000 UTC Unschedulable 0/1 nodes are available: 1 node(s) didn't match pod affinity/anti-affinity, 1 node(s) didn't satisfy existing pods anti-affinity rules.}]
Oct  4 06:42:27.090: INFO: 
Oct  4 06:42:29.089: INFO: The status of Pod coredns-7c949f49d5-p6f2z is Pending (Ready = false), waiting for it to be either Running (with Ready = true) or Failed
Oct  4 06:42:29.089: INFO: 10 / 11 pods in namespace 'kube-system' are running and ready (358 seconds elapsed)
Oct  4 06:42:29.089: INFO: expected 6 pod replicas in namespace 'kube-system', 5 are Running and Ready.
Oct  4 06:42:29.089: INFO: POD                       NODE  PHASE    GRACE  CONDITIONS
Oct  4 06:42:29.089: INFO: coredns-7c949f49d5-p6f2z        Pending         [{PodScheduled False 0001-01-01 00:00:00 +0000 UTC 2019-05-15 03:24:15 +0000 UTC Unschedulable 0/1 nodes are available: 1 node(s) didn't match pod affinity/anti-affinity, 1 node(s) didn't satisfy existing pods anti-affinity rules.}]
Oct  4 06:42:29.089: INFO: 
Oct  4 06:42:31.091: INFO: The status of Pod coredns-7c949f49d5-p6f2z is Pending (Ready = false), waiting for it to be either Running (with Ready = true) or Failed
Oct  4 06:42:31.092: INFO: 10 / 11 pods in namespace 'kube-system' are running and ready (360 seconds elapsed)
Oct  4 06:42:31.092: INFO: expected 6 pod replicas in namespace 'kube-system', 5 are Running and Ready.
Oct  4 06:42:31.092: INFO: POD                       NODE  PHASE    GRACE  CONDITIONS
Oct  4 06:42:31.092: INFO: coredns-7c949f49d5-p6f2z        Pending         [{PodScheduled False 0001-01-01 00:00:00 +0000 UTC 2019-05-15 03:24:15 +0000 UTC Unschedulable 0/1 nodes are available: 1 node(s) didn't match pod affinity/anti-affinity, 1 node(s) didn't satisfy existing pods anti-affinity rules.}]
Oct  4 06:42:31.092: INFO: 
Oct  4 06:42:33.123: INFO: The status of Pod coredns-7c949f49d5-p6f2z is Pending (Ready = false), waiting for it to be either Running (with Ready = true) or Failed
Oct  4 06:42:33.123: INFO: 10 / 11 pods in namespace 'kube-system' are running and ready (362 seconds elapsed)
Oct  4 06:42:33.123: INFO: expected 6 pod replicas in namespace 'kube-system', 5 are Running and Ready.
Oct  4 06:42:33.123: INFO: POD                       NODE  PHASE    GRACE  CONDITIONS
Oct  4 06:42:33.123: INFO: coredns-7c949f49d5-p6f2z        Pending         [{PodScheduled False 0001-01-01 00:00:00 +0000 UTC 2019-05-15 03:24:15 +0000 UTC Unschedulable 0/1 nodes are available: 1 node(s) didn't match pod affinity/anti-affinity, 1 node(s) didn't satisfy existing pods anti-affinity rules.}]
Oct  4 06:42:33.123: INFO: 
Oct  4 06:42:35.081: INFO: The status of Pod coredns-7c949f49d5-p6f2z is Pending (Ready = false), waiting for it to be either Running (with Ready = true) or Failed
Oct  4 06:42:35.081: INFO: 10 / 11 pods in namespace 'kube-system' are running and ready (364 seconds elapsed)
Oct  4 06:42:35.081: INFO: expected 6 pod replicas in namespace 'kube-system', 5 are Running and Ready.
Oct  4 06:42:35.081: INFO: POD                       NODE  PHASE    GRACE  CONDITIONS
Oct  4 06:42:35.081: INFO: coredns-7c949f49d5-p6f2z        Pending         [{PodScheduled False 0001-01-01 00:00:00 +0000 UTC 2019-05-15 03:24:15 +0000 UTC Unschedulable 0/1 nodes are available: 1 node(s) didn't match pod affinity/anti-affinity, 1 node(s) didn't satisfy existing pods anti-affinity rules.}]
Oct  4 06:42:35.081: INFO: 
Oct  4 06:42:37.091: INFO: The status of Pod coredns-7c949f49d5-p6f2z is Pending (Ready = false), waiting for it to be either Running (with Ready = true) or Failed
Oct  4 06:42:37.091: INFO: 10 / 11 pods in namespace 'kube-system' are running and ready (366 seconds elapsed)
Oct  4 06:42:37.091: INFO: expected 6 pod replicas in namespace 'kube-system', 5 are Running and Ready.
Oct  4 06:42:37.091: INFO: POD                       NODE  PHASE    GRACE  CONDITIONS
Oct  4 06:42:37.091: INFO: coredns-7c949f49d5-p6f2z        Pending         [{PodScheduled False 0001-01-01 00:00:00 +0000 UTC 2019-05-15 03:24:15 +0000 UTC Unschedulable 0/1 nodes are available: 1 node(s) didn't match pod affinity/anti-affinity, 1 node(s) didn't satisfy existing pods anti-affinity rules.}]
Oct  4 06:42:37.091: INFO: 
Oct  4 06:42:39.091: INFO: The status of Pod coredns-7c949f49d5-p6f2z is Pending (Ready = false), waiting for it to be either Running (with Ready = true) or Failed
Oct  4 06:42:39.091: INFO: 10 / 11 pods in namespace 'kube-system' are running and ready (368 seconds elapsed)
Oct  4 06:42:39.091: INFO: expected 6 pod replicas in namespace 'kube-system', 5 are Running and Ready.
Oct  4 06:42:39.091: INFO: POD                       NODE  PHASE    GRACE  CONDITIONS
Oct  4 06:42:39.091: INFO: coredns-7c949f49d5-p6f2z        Pending         [{PodScheduled False 0001-01-01 00:00:00 +0000 UTC 2019-05-15 03:24:15 +0000 UTC Unschedulable 0/1 nodes are available: 1 node(s) didn't match pod affinity/anti-affinity, 1 node(s) didn't satisfy existing pods anti-affinity rules.}]
Oct  4 06:42:39.091: INFO: 
Oct  4 06:42:41.168: INFO: The status of Pod coredns-7c949f49d5-p6f2z is Pending (Ready = false), waiting for it to be either Running (with Ready = true) or Failed
Oct  4 06:42:41.168: INFO: 10 / 11 pods in namespace 'kube-system' are running and ready (370 seconds elapsed)
Oct  4 06:42:41.168: INFO: expected 6 pod replicas in namespace 'kube-system', 5 are Running and Ready.
Oct  4 06:42:41.168: INFO: POD                       NODE  PHASE    GRACE  CONDITIONS
Oct  4 06:42:41.168: INFO: coredns-7c949f49d5-p6f2z        Pending         [{PodScheduled False 0001-01-01 00:00:00 +0000 UTC 2019-05-15 03:24:15 +0000 UTC Unschedulable 0/1 nodes are available: 1 node(s) didn't match pod affinity/anti-affinity, 1 node(s) didn't satisfy existing pods anti-affinity rules.}]
Oct  4 06:42:41.168: INFO: 
Oct  4 06:42:43.315: INFO: The status of Pod coredns-7c949f49d5-p6f2z is Pending (Ready = false), waiting for it to be either Running (with Ready = true) or Failed
Oct  4 06:42:43.315: INFO: 10 / 11 pods in namespace 'kube-system' are running and ready (372 seconds elapsed)
Oct  4 06:42:43.315: INFO: expected 6 pod replicas in namespace 'kube-system', 5 are Running and Ready.
Oct  4 06:42:43.315: INFO: POD                       NODE  PHASE    GRACE  CONDITIONS
Oct  4 06:42:43.315: INFO: coredns-7c949f49d5-p6f2z        Pending         [{PodScheduled False 0001-01-01 00:00:00 +0000 UTC 2019-05-15 03:24:15 +0000 UTC Unschedulable 0/1 nodes are available: 1 node(s) didn't match pod affinity/anti-affinity, 1 node(s) didn't satisfy existing pods anti-affinity rules.}]
Oct  4 06:42:43.315: INFO: 
Oct  4 06:42:45.151: INFO: The status of Pod coredns-7c949f49d5-p6f2z is Pending (Ready = false), waiting for it to be either Running (with Ready = true) or Failed
Oct  4 06:42:45.151: INFO: 10 / 11 pods in namespace 'kube-system' are running and ready (374 seconds elapsed)
Oct  4 06:42:45.151: INFO: expected 6 pod replicas in namespace 'kube-system', 5 are Running and Ready.
Oct  4 06:42:45.151: INFO: POD                       NODE  PHASE    GRACE  CONDITIONS
Oct  4 06:42:45.151: INFO: coredns-7c949f49d5-p6f2z        Pending         [{PodScheduled False 0001-01-01 00:00:00 +0000 UTC 2019-05-15 03:24:15 +0000 UTC Unschedulable 0/1 nodes are available: 1 node(s) didn't match pod affinity/anti-affinity, 1 node(s) didn't satisfy existing pods anti-affinity rules.}]
Oct  4 06:42:45.151: INFO: 
Oct  4 06:42:47.081: INFO: The status of Pod coredns-7c949f49d5-p6f2z is Pending (Ready = false), waiting for it to be either Running (with Ready = true) or Failed
Oct  4 06:42:47.081: INFO: 10 / 11 pods in namespace 'kube-system' are running and ready (376 seconds elapsed)
Oct  4 06:42:47.081: INFO: expected 6 pod replicas in namespace 'kube-system', 5 are Running and Ready.
Oct  4 06:42:47.081: INFO: POD                       NODE  PHASE    GRACE  CONDITIONS
Oct  4 06:42:47.081: INFO: coredns-7c949f49d5-p6f2z        Pending         [{PodScheduled False 0001-01-01 00:00:00 +0000 UTC 2019-05-15 03:24:15 +0000 UTC Unschedulable 0/1 nodes are available: 1 node(s) didn't match pod affinity/anti-affinity, 1 node(s) didn't satisfy existing pods anti-affinity rules.}]
Oct  4 06:42:47.081: INFO: 
Oct  4 06:42:49.087: INFO: The status of Pod coredns-7c949f49d5-p6f2z is Pending (Ready = false), waiting for it to be either Running (with Ready = true) or Failed
Oct  4 06:42:49.087: INFO: 10 / 11 pods in namespace 'kube-system' are running and ready (378 seconds elapsed)
Oct  4 06:42:49.087: INFO: expected 6 pod replicas in namespace 'kube-system', 5 are Running and Ready.
Oct  4 06:42:49.087: INFO: POD                       NODE  PHASE    GRACE  CONDITIONS
Oct  4 06:42:49.087: INFO: coredns-7c949f49d5-p6f2z        Pending         [{PodScheduled False 0001-01-01 00:00:00 +0000 UTC 2019-05-15 03:24:15 +0000 UTC Unschedulable 0/1 nodes are available: 1 node(s) didn't match pod affinity/anti-affinity, 1 node(s) didn't satisfy existing pods anti-affinity rules.}]
Oct  4 06:42:49.087: INFO: 
Oct  4 06:42:51.092: INFO: The status of Pod coredns-7c949f49d5-p6f2z is Pending (Ready = false), waiting for it to be either Running (with Ready = true) or Failed
Oct  4 06:42:51.092: INFO: 10 / 11 pods in namespace 'kube-system' are running and ready (380 seconds elapsed)
Oct  4 06:42:51.092: INFO: expected 6 pod replicas in namespace 'kube-system', 5 are Running and Ready.
Oct  4 06:42:51.092: INFO: POD                       NODE  PHASE    GRACE  CONDITIONS
Oct  4 06:42:51.092: INFO: coredns-7c949f49d5-p6f2z        Pending         [{PodScheduled False 0001-01-01 00:00:00 +0000 UTC 2019-05-15 03:24:15 +0000 UTC Unschedulable 0/1 nodes are available: 1 node(s) didn't match pod affinity/anti-affinity, 1 node(s) didn't satisfy existing pods anti-affinity rules.}]
Oct  4 06:42:51.092: INFO: 
Oct  4 06:42:53.133: INFO: The status of Pod coredns-7c949f49d5-p6f2z is Pending (Ready = false), waiting for it to be either Running (with Ready = true) or Failed
Oct  4 06:42:53.134: INFO: 10 / 11 pods in namespace 'kube-system' are running and ready (382 seconds elapsed)
Oct  4 06:42:53.134: INFO: expected 6 pod replicas in namespace 'kube-system', 5 are Running and Ready.
Oct  4 06:42:53.134: INFO: POD                       NODE  PHASE    GRACE  CONDITIONS
Oct  4 06:42:53.134: INFO: coredns-7c949f49d5-p6f2z        Pending         [{PodScheduled False 0001-01-01 00:00:00 +0000 UTC 2019-05-15 03:24:15 +0000 UTC Unschedulable 0/1 nodes are available: 1 node(s) didn't match pod affinity/anti-affinity, 1 node(s) didn't satisfy existing pods anti-affinity rules.}]
Oct  4 06:42:53.134: INFO: 
Oct  4 06:42:55.090: INFO: The status of Pod coredns-7c949f49d5-p6f2z is Pending (Ready = false), waiting for it to be either Running (with Ready = true) or Failed
Oct  4 06:42:55.090: INFO: 10 / 11 pods in namespace 'kube-system' are running and ready (384 seconds elapsed)
Oct  4 06:42:55.090: INFO: expected 6 pod replicas in namespace 'kube-system', 5 are Running and Ready.
Oct  4 06:42:55.090: INFO: POD                       NODE  PHASE    GRACE  CONDITIONS
Oct  4 06:42:55.090: INFO: coredns-7c949f49d5-p6f2z        Pending         [{PodScheduled False 0001-01-01 00:00:00 +0000 UTC 2019-05-15 03:24:15 +0000 UTC Unschedulable 0/1 nodes are available: 1 node(s) didn't match pod affinity/anti-affinity, 1 node(s) didn't satisfy existing pods anti-affinity rules.}]
Oct  4 06:42:55.090: INFO: 
Oct  4 06:42:57.148: INFO: The status of Pod coredns-7c949f49d5-p6f2z is Pending (Ready = false), waiting for it to be either Running (with Ready = true) or Failed
Oct  4 06:42:57.148: INFO: 10 / 11 pods in namespace 'kube-system' are running and ready (386 seconds elapsed)
Oct  4 06:42:57.148: INFO: expected 6 pod replicas in namespace 'kube-system', 5 are Running and Ready.
Oct  4 06:42:57.148: INFO: POD                       NODE  PHASE    GRACE  CONDITIONS
Oct  4 06:42:57.148: INFO: coredns-7c949f49d5-p6f2z        Pending         [{PodScheduled False 0001-01-01 00:00:00 +0000 UTC 2019-05-15 03:24:15 +0000 UTC Unschedulable 0/1 nodes are available: 1 node(s) didn't match pod affinity/anti-affinity, 1 node(s) didn't satisfy existing pods anti-affinity rules.}]
Oct  4 06:42:57.148: INFO: 
Oct  4 06:42:59.091: INFO: The status of Pod coredns-7c949f49d5-p6f2z is Pending (Ready = false), waiting for it to be either Running (with Ready = true) or Failed
Oct  4 06:42:59.091: INFO: 10 / 11 pods in namespace 'kube-system' are running and ready (388 seconds elapsed)
Oct  4 06:42:59.091: INFO: expected 6 pod replicas in namespace 'kube-system', 5 are Running and Ready.
Oct  4 06:42:59.091: INFO: POD                       NODE  PHASE    GRACE  CONDITIONS
Oct  4 06:42:59.091: INFO: coredns-7c949f49d5-p6f2z        Pending         [{PodScheduled False 0001-01-01 00:00:00 +0000 UTC 2019-05-15 03:24:15 +0000 UTC Unschedulable 0/1 nodes are available: 1 node(s) didn't match pod affinity/anti-affinity, 1 node(s) didn't satisfy existing pods anti-affinity rules.}]
Oct  4 06:42:59.091: INFO: 
Oct  4 06:43:01.081: INFO: The status of Pod coredns-7c949f49d5-p6f2z is Pending (Ready = false), waiting for it to be either Running (with Ready = true) or Failed
Oct  4 06:43:01.081: INFO: 10 / 11 pods in namespace 'kube-system' are running and ready (390 seconds elapsed)
Oct  4 06:43:01.081: INFO: expected 6 pod replicas in namespace 'kube-system', 5 are Running and Ready.
Oct  4 06:43:01.081: INFO: POD                       NODE  PHASE    GRACE  CONDITIONS
Oct  4 06:43:01.081: INFO: coredns-7c949f49d5-p6f2z        Pending         [{PodScheduled False 0001-01-01 00:00:00 +0000 UTC 2019-05-15 03:24:15 +0000 UTC Unschedulable 0/1 nodes are available: 1 node(s) didn't match pod affinity/anti-affinity, 1 node(s) didn't satisfy existing pods anti-affinity rules.}]
Oct  4 06:43:01.081: INFO: 
Oct  4 06:43:03.225: INFO: The status of Pod coredns-7c949f49d5-p6f2z is Pending (Ready = false), waiting for it to be either Running (with Ready = true) or Failed
Oct  4 06:43:03.225: INFO: 10 / 11 pods in namespace 'kube-system' are running and ready (392 seconds elapsed)
Oct  4 06:43:03.225: INFO: expected 6 pod replicas in namespace 'kube-system', 5 are Running and Ready.
Oct  4 06:43:03.225: INFO: POD                       NODE  PHASE    GRACE  CONDITIONS
Oct  4 06:43:03.225: INFO: coredns-7c949f49d5-p6f2z        Pending         [{PodScheduled False 0001-01-01 00:00:00 +0000 UTC 2019-05-15 03:24:15 +0000 UTC Unschedulable 0/1 nodes are available: 1 node(s) didn't match pod affinity/anti-affinity, 1 node(s) didn't satisfy existing pods anti-affinity rules.}]
Oct  4 06:43:03.225: INFO: 
Oct  4 06:43:05.081: INFO: The status of Pod coredns-7c949f49d5-p6f2z is Pending (Ready = false), waiting for it to be either Running (with Ready = true) or Failed
Oct  4 06:43:05.081: INFO: 10 / 11 pods in namespace 'kube-system' are running and ready (394 seconds elapsed)
Oct  4 06:43:05.081: INFO: expected 6 pod replicas in namespace 'kube-system', 5 are Running and Ready.
Oct  4 06:43:05.081: INFO: POD                       NODE  PHASE    GRACE  CONDITIONS
Oct  4 06:43:05.081: INFO: coredns-7c949f49d5-p6f2z        Pending         [{PodScheduled False 0001-01-01 00:00:00 +0000 UTC 2019-05-15 03:24:15 +0000 UTC Unschedulable 0/1 nodes are available: 1 node(s) didn't match pod affinity/anti-affinity, 1 node(s) didn't satisfy existing pods anti-affinity rules.}]
Oct  4 06:43:05.081: INFO: 
Oct  4 06:43:07.089: INFO: The status of Pod coredns-7c949f49d5-p6f2z is Pending (Ready = false), waiting for it to be either Running (with Ready = true) or Failed
Oct  4 06:43:07.089: INFO: 10 / 11 pods in namespace 'kube-system' are running and ready (396 seconds elapsed)
Oct  4 06:43:07.089: INFO: expected 6 pod replicas in namespace 'kube-system', 5 are Running and Ready.
Oct  4 06:43:07.089: INFO: POD                       NODE  PHASE    GRACE  CONDITIONS
Oct  4 06:43:07.089: INFO: coredns-7c949f49d5-p6f2z        Pending         [{PodScheduled False 0001-01-01 00:00:00 +0000 UTC 2019-05-15 03:24:15 +0000 UTC Unschedulable 0/1 nodes are available: 1 node(s) didn't match pod affinity/anti-affinity, 1 node(s) didn't satisfy existing pods anti-affinity rules.}]
Oct  4 06:43:07.089: INFO: 
Oct  4 06:43:09.082: INFO: The status of Pod coredns-7c949f49d5-p6f2z is Pending (Ready = false), waiting for it to be either Running (with Ready = true) or Failed
Oct  4 06:43:09.082: INFO: 10 / 11 pods in namespace 'kube-system' are running and ready (398 seconds elapsed)
Oct  4 06:43:09.082: INFO: expected 6 pod replicas in namespace 'kube-system', 5 are Running and Ready.
Oct  4 06:43:09.082: INFO: POD                       NODE  PHASE    GRACE  CONDITIONS
Oct  4 06:43:09.082: INFO: coredns-7c949f49d5-p6f2z        Pending         [{PodScheduled False 0001-01-01 00:00:00 +0000 UTC 2019-05-15 03:24:15 +0000 UTC Unschedulable 0/1 nodes are available: 1 node(s) didn't match pod affinity/anti-affinity, 1 node(s) didn't satisfy existing pods anti-affinity rules.}]
Oct  4 06:43:09.082: INFO: 
Oct  4 06:43:11.081: INFO: The status of Pod coredns-7c949f49d5-p6f2z is Pending (Ready = false), waiting for it to be either Running (with Ready = true) or Failed
Oct  4 06:43:11.081: INFO: 10 / 11 pods in namespace 'kube-system' are running and ready (400 seconds elapsed)
Oct  4 06:43:11.081: INFO: expected 6 pod replicas in namespace 'kube-system', 5 are Running and Ready.
Oct  4 06:43:11.081: INFO: POD                       NODE  PHASE    GRACE  CONDITIONS
Oct  4 06:43:11.081: INFO: coredns-7c949f49d5-p6f2z        Pending         [{PodScheduled False 0001-01-01 00:00:00 +0000 UTC 2019-05-15 03:24:15 +0000 UTC Unschedulable 0/1 nodes are available: 1 node(s) didn't match pod affinity/anti-affinity, 1 node(s) didn't satisfy existing pods anti-affinity rules.}]
Oct  4 06:43:11.081: INFO: 
Oct  4 06:43:13.092: INFO: The status of Pod coredns-7c949f49d5-p6f2z is Pending (Ready = false), waiting for it to be either Running (with Ready = true) or Failed
Oct  4 06:43:13.092: INFO: 10 / 11 pods in namespace 'kube-system' are running and ready (402 seconds elapsed)
Oct  4 06:43:13.092: INFO: expected 6 pod replicas in namespace 'kube-system', 5 are Running and Ready.
Oct  4 06:43:13.092: INFO: POD                       NODE  PHASE    GRACE  CONDITIONS
Oct  4 06:43:13.092: INFO: coredns-7c949f49d5-p6f2z        Pending         [{PodScheduled False 0001-01-01 00:00:00 +0000 UTC 2019-05-15 03:24:15 +0000 UTC Unschedulable 0/1 nodes are available: 1 node(s) didn't match pod affinity/anti-affinity, 1 node(s) didn't satisfy existing pods anti-affinity rules.}]
Oct  4 06:43:13.092: INFO: 
Oct  4 06:43:15.099: INFO: The status of Pod coredns-7c949f49d5-p6f2z is Pending (Ready = false), waiting for it to be either Running (with Ready = true) or Failed
Oct  4 06:43:15.099: INFO: 10 / 11 pods in namespace 'kube-system' are running and ready (404 seconds elapsed)
Oct  4 06:43:15.099: INFO: expected 6 pod replicas in namespace 'kube-system', 5 are Running and Ready.
Oct  4 06:43:15.100: INFO: POD                       NODE  PHASE    GRACE  CONDITIONS
Oct  4 06:43:15.100: INFO: coredns-7c949f49d5-p6f2z        Pending         [{PodScheduled False 0001-01-01 00:00:00 +0000 UTC 2019-05-15 03:24:15 +0000 UTC Unschedulable 0/1 nodes are available: 1 node(s) didn't match pod affinity/anti-affinity, 1 node(s) didn't satisfy existing pods anti-affinity rules.}]
Oct  4 06:43:15.100: INFO: 
Oct  4 06:43:17.092: INFO: The status of Pod coredns-7c949f49d5-p6f2z is Pending (Ready = false), waiting for it to be either Running (with Ready = true) or Failed
Oct  4 06:43:17.092: INFO: 10 / 11 pods in namespace 'kube-system' are running and ready (406 seconds elapsed)
Oct  4 06:43:17.092: INFO: expected 6 pod replicas in namespace 'kube-system', 5 are Running and Ready.
Oct  4 06:43:17.092: INFO: POD                       NODE  PHASE    GRACE  CONDITIONS
Oct  4 06:43:17.092: INFO: coredns-7c949f49d5-p6f2z        Pending         [{PodScheduled False 0001-01-01 00:00:00 +0000 UTC 2019-05-15 03:24:15 +0000 UTC Unschedulable 0/1 nodes are available: 1 node(s) didn't match pod affinity/anti-affinity, 1 node(s) didn't satisfy existing pods anti-affinity rules.}]
Oct  4 06:43:17.092: INFO: 
Oct  4 06:43:19.081: INFO: The status of Pod coredns-7c949f49d5-p6f2z is Pending (Ready = false), waiting for it to be either Running (with Ready = true) or Failed
Oct  4 06:43:19.081: INFO: 10 / 11 pods in namespace 'kube-system' are running and ready (408 seconds elapsed)
Oct  4 06:43:19.081: INFO: expected 6 pod replicas in namespace 'kube-system', 5 are Running and Ready.
Oct  4 06:43:19.081: INFO: POD                       NODE  PHASE    GRACE  CONDITIONS
Oct  4 06:43:19.081: INFO: coredns-7c949f49d5-p6f2z        Pending         [{PodScheduled False 0001-01-01 00:00:00 +0000 UTC 2019-05-15 03:24:15 +0000 UTC Unschedulable 0/1 nodes are available: 1 node(s) didn't match pod affinity/anti-affinity, 1 node(s) didn't satisfy existing pods anti-affinity rules.}]
Oct  4 06:43:19.081: INFO: 
Oct  4 06:43:21.091: INFO: The status of Pod coredns-7c949f49d5-p6f2z is Pending (Ready = false), waiting for it to be either Running (with Ready = true) or Failed
Oct  4 06:43:21.091: INFO: 10 / 11 pods in namespace 'kube-system' are running and ready (410 seconds elapsed)
Oct  4 06:43:21.091: INFO: expected 6 pod replicas in namespace 'kube-system', 5 are Running and Ready.
Oct  4 06:43:21.091: INFO: POD                       NODE  PHASE    GRACE  CONDITIONS
Oct  4 06:43:21.091: INFO: coredns-7c949f49d5-p6f2z        Pending         [{PodScheduled False 0001-01-01 00:00:00 +0000 UTC 2019-05-15 03:24:15 +0000 UTC Unschedulable 0/1 nodes are available: 1 node(s) didn't match pod affinity/anti-affinity, 1 node(s) didn't satisfy existing pods anti-affinity rules.}]
Oct  4 06:43:21.091: INFO: 
Oct  4 06:43:23.081: INFO: The status of Pod coredns-7c949f49d5-p6f2z is Pending (Ready = false), waiting for it to be either Running (with Ready = true) or Failed
Oct  4 06:43:23.081: INFO: 10 / 11 pods in namespace 'kube-system' are running and ready (412 seconds elapsed)
Oct  4 06:43:23.081: INFO: expected 6 pod replicas in namespace 'kube-system', 5 are Running and Ready.
Oct  4 06:43:23.081: INFO: POD                       NODE  PHASE    GRACE  CONDITIONS
Oct  4 06:43:23.081: INFO: coredns-7c949f49d5-p6f2z        Pending         [{PodScheduled False 0001-01-01 00:00:00 +0000 UTC 2019-05-15 03:24:15 +0000 UTC Unschedulable 0/1 nodes are available: 1 node(s) didn't match pod affinity/anti-affinity, 1 node(s) didn't satisfy existing pods anti-affinity rules.}]
Oct  4 06:43:23.081: INFO: 
Oct  4 06:43:25.092: INFO: The status of Pod coredns-7c949f49d5-p6f2z is Pending (Ready = false), waiting for it to be either Running (with Ready = true) or Failed
Oct  4 06:43:25.092: INFO: 10 / 11 pods in namespace 'kube-system' are running and ready (414 seconds elapsed)
Oct  4 06:43:25.092: INFO: expected 6 pod replicas in namespace 'kube-system', 5 are Running and Ready.
Oct  4 06:43:25.092: INFO: POD                       NODE  PHASE    GRACE  CONDITIONS
Oct  4 06:43:25.092: INFO: coredns-7c949f49d5-p6f2z        Pending         [{PodScheduled False 0001-01-01 00:00:00 +0000 UTC 2019-05-15 03:24:15 +0000 UTC Unschedulable 0/1 nodes are available: 1 node(s) didn't match pod affinity/anti-affinity, 1 node(s) didn't satisfy existing pods anti-affinity rules.}]
Oct  4 06:43:25.092: INFO: 
Oct  4 06:43:27.083: INFO: The status of Pod coredns-7c949f49d5-p6f2z is Pending (Ready = false), waiting for it to be either Running (with Ready = true) or Failed
Oct  4 06:43:27.083: INFO: 10 / 11 pods in namespace 'kube-system' are running and ready (416 seconds elapsed)
Oct  4 06:43:27.083: INFO: expected 6 pod replicas in namespace 'kube-system', 5 are Running and Ready.
Oct  4 06:43:27.083: INFO: POD                       NODE  PHASE    GRACE  CONDITIONS
Oct  4 06:43:27.083: INFO: coredns-7c949f49d5-p6f2z        Pending         [{PodScheduled False 0001-01-01 00:00:00 +0000 UTC 2019-05-15 03:24:15 +0000 UTC Unschedulable 0/1 nodes are available: 1 node(s) didn't match pod affinity/anti-affinity, 1 node(s) didn't satisfy existing pods anti-affinity rules.}]
Oct  4 06:43:27.083: INFO: 
Oct  4 06:43:29.084: INFO: The status of Pod coredns-7c949f49d5-p6f2z is Pending (Ready = false), waiting for it to be either Running (with Ready = true) or Failed
Oct  4 06:43:29.084: INFO: 10 / 11 pods in namespace 'kube-system' are running and ready (418 seconds elapsed)
Oct  4 06:43:29.084: INFO: expected 6 pod replicas in namespace 'kube-system', 5 are Running and Ready.
Oct  4 06:43:29.084: INFO: POD                       NODE  PHASE    GRACE  CONDITIONS
Oct  4 06:43:29.084: INFO: coredns-7c949f49d5-p6f2z        Pending         [{PodScheduled False 0001-01-01 00:00:00 +0000 UTC 2019-05-15 03:24:15 +0000 UTC Unschedulable 0/1 nodes are available: 1 node(s) didn't match pod affinity/anti-affinity, 1 node(s) didn't satisfy existing pods anti-affinity rules.}]
Oct  4 06:43:29.084: INFO: 
Oct  4 06:43:31.082: INFO: The status of Pod coredns-7c949f49d5-p6f2z is Pending (Ready = false), waiting for it to be either Running (with Ready = true) or Failed
Oct  4 06:43:31.082: INFO: 10 / 11 pods in namespace 'kube-system' are running and ready (420 seconds elapsed)
Oct  4 06:43:31.082: INFO: expected 6 pod replicas in namespace 'kube-system', 5 are Running and Ready.
Oct  4 06:43:31.082: INFO: POD                       NODE  PHASE    GRACE  CONDITIONS
Oct  4 06:43:31.082: INFO: coredns-7c949f49d5-p6f2z        Pending         [{PodScheduled False 0001-01-01 00:00:00 +0000 UTC 2019-05-15 03:24:15 +0000 UTC Unschedulable 0/1 nodes are available: 1 node(s) didn't match pod affinity/anti-affinity, 1 node(s) didn't satisfy existing pods anti-affinity rules.}]
Oct  4 06:43:31.082: INFO: 
Oct  4 06:43:33.407: INFO: The status of Pod coredns-7c949f49d5-p6f2z is Pending (Ready = false), waiting for it to be either Running (with Ready = true) or Failed
Oct  4 06:43:33.407: INFO: 10 / 11 pods in namespace 'kube-system' are running and ready (422 seconds elapsed)
Oct  4 06:43:33.407: INFO: expected 6 pod replicas in namespace 'kube-system', 5 are Running and Ready.
Oct  4 06:43:33.407: INFO: POD                       NODE  PHASE    GRACE  CONDITIONS
Oct  4 06:43:33.407: INFO: coredns-7c949f49d5-p6f2z        Pending         [{PodScheduled False 0001-01-01 00:00:00 +0000 UTC 2019-05-15 03:24:15 +0000 UTC Unschedulable 0/1 nodes are available: 1 node(s) didn't match pod affinity/anti-affinity, 1 node(s) didn't satisfy existing pods anti-affinity rules.}]
Oct  4 06:43:33.407: INFO: 
Oct  4 06:43:35.090: INFO: The status of Pod coredns-7c949f49d5-p6f2z is Pending (Ready = false), waiting for it to be either Running (with Ready = true) or Failed
Oct  4 06:43:35.090: INFO: 10 / 11 pods in namespace 'kube-system' are running and ready (424 seconds elapsed)
Oct  4 06:43:35.090: INFO: expected 6 pod replicas in namespace 'kube-system', 5 are Running and Ready.
Oct  4 06:43:35.090: INFO: POD                       NODE  PHASE    GRACE  CONDITIONS
Oct  4 06:43:35.090: INFO: coredns-7c949f49d5-p6f2z        Pending         [{PodScheduled False 0001-01-01 00:00:00 +0000 UTC 2019-05-15 03:24:15 +0000 UTC Unschedulable 0/1 nodes are available: 1 node(s) didn't match pod affinity/anti-affinity, 1 node(s) didn't satisfy existing pods anti-affinity rules.}]
Oct  4 06:43:35.090: INFO: 
Oct  4 06:43:37.093: INFO: The status of Pod coredns-7c949f49d5-p6f2z is Pending (Ready = false), waiting for it to be either Running (with Ready = true) or Failed
Oct  4 06:43:37.093: INFO: 10 / 11 pods in namespace 'kube-system' are running and ready (426 seconds elapsed)
Oct  4 06:43:37.093: INFO: expected 6 pod replicas in namespace 'kube-system', 5 are Running and Ready.
Oct  4 06:43:37.093: INFO: POD                       NODE  PHASE    GRACE  CONDITIONS
Oct  4 06:43:37.093: INFO: coredns-7c949f49d5-p6f2z        Pending         [{PodScheduled False 0001-01-01 00:00:00 +0000 UTC 2019-05-15 03:24:15 +0000 UTC Unschedulable 0/1 nodes are available: 1 node(s) didn't match pod affinity/anti-affinity, 1 node(s) didn't satisfy existing pods anti-affinity rules.}]
Oct  4 06:43:37.093: INFO: 
Oct  4 06:43:39.081: INFO: The status of Pod coredns-7c949f49d5-p6f2z is Pending (Ready = false), waiting for it to be either Running (with Ready = true) or Failed
Oct  4 06:43:39.081: INFO: 10 / 11 pods in namespace 'kube-system' are running and ready (428 seconds elapsed)
Oct  4 06:43:39.081: INFO: expected 6 pod replicas in namespace 'kube-system', 5 are Running and Ready.
Oct  4 06:43:39.081: INFO: POD                       NODE  PHASE    GRACE  CONDITIONS
Oct  4 06:43:39.081: INFO: coredns-7c949f49d5-p6f2z        Pending         [{PodScheduled False 0001-01-01 00:00:00 +0000 UTC 2019-05-15 03:24:15 +0000 UTC Unschedulable 0/1 nodes are available: 1 node(s) didn't match pod affinity/anti-affinity, 1 node(s) didn't satisfy existing pods anti-affinity rules.}]
Oct  4 06:43:39.081: INFO: 
Oct  4 06:43:41.081: INFO: The status of Pod coredns-7c949f49d5-p6f2z is Pending (Ready = false), waiting for it to be either Running (with Ready = true) or Failed
Oct  4 06:43:41.081: INFO: 10 / 11 pods in namespace 'kube-system' are running and ready (430 seconds elapsed)
Oct  4 06:43:41.081: INFO: expected 6 pod replicas in namespace 'kube-system', 5 are Running and Ready.
Oct  4 06:43:41.081: INFO: POD                       NODE  PHASE    GRACE  CONDITIONS
Oct  4 06:43:41.081: INFO: coredns-7c949f49d5-p6f2z        Pending         [{PodScheduled False 0001-01-01 00:00:00 +0000 UTC 2019-05-15 03:24:15 +0000 UTC Unschedulable 0/1 nodes are available: 1 node(s) didn't match pod affinity/anti-affinity, 1 node(s) didn't satisfy existing pods anti-affinity rules.}]
Oct  4 06:43:41.081: INFO: 
Oct  4 06:43:43.092: INFO: The status of Pod coredns-7c949f49d5-p6f2z is Pending (Ready = false), waiting for it to be either Running (with Ready = true) or Failed
Oct  4 06:43:43.092: INFO: 10 / 11 pods in namespace 'kube-system' are running and ready (432 seconds elapsed)
Oct  4 06:43:43.092: INFO: expected 6 pod replicas in namespace 'kube-system', 5 are Running and Ready.
Oct  4 06:43:43.092: INFO: POD                       NODE  PHASE    GRACE  CONDITIONS
Oct  4 06:43:43.092: INFO: coredns-7c949f49d5-p6f2z        Pending         [{PodScheduled False 0001-01-01 00:00:00 +0000 UTC 2019-05-15 03:24:15 +0000 UTC Unschedulable 0/1 nodes are available: 1 node(s) didn't match pod affinity/anti-affinity, 1 node(s) didn't satisfy existing pods anti-affinity rules.}]
Oct  4 06:43:43.092: INFO: 
Oct  4 06:43:45.091: INFO: The status of Pod coredns-7c949f49d5-p6f2z is Pending (Ready = false), waiting for it to be either Running (with Ready = true) or Failed
Oct  4 06:43:45.091: INFO: 10 / 11 pods in namespace 'kube-system' are running and ready (434 seconds elapsed)
Oct  4 06:43:45.091: INFO: expected 6 pod replicas in namespace 'kube-system', 5 are Running and Ready.
Oct  4 06:43:45.091: INFO: POD                       NODE  PHASE    GRACE  CONDITIONS
Oct  4 06:43:45.091: INFO: coredns-7c949f49d5-p6f2z        Pending         [{PodScheduled False 0001-01-01 00:00:00 +0000 UTC 2019-05-15 03:24:15 +0000 UTC Unschedulable 0/1 nodes are available: 1 node(s) didn't match pod affinity/anti-affinity, 1 node(s) didn't satisfy existing pods anti-affinity rules.}]
Oct  4 06:43:45.091: INFO: 
Oct  4 06:43:47.090: INFO: The status of Pod coredns-7c949f49d5-p6f2z is Pending (Ready = false), waiting for it to be either Running (with Ready = true) or Failed
Oct  4 06:43:47.090: INFO: 10 / 11 pods in namespace 'kube-system' are running and ready (436 seconds elapsed)
Oct  4 06:43:47.090: INFO: expected 6 pod replicas in namespace 'kube-system', 5 are Running and Ready.
Oct  4 06:43:47.090: INFO: POD                       NODE  PHASE    GRACE  CONDITIONS
Oct  4 06:43:47.090: INFO: coredns-7c949f49d5-p6f2z        Pending         [{PodScheduled False 0001-01-01 00:00:00 +0000 UTC 2019-05-15 03:24:15 +0000 UTC Unschedulable 0/1 nodes are available: 1 node(s) didn't match pod affinity/anti-affinity, 1 node(s) didn't satisfy existing pods anti-affinity rules.}]
Oct  4 06:43:47.090: INFO: 
Oct  4 06:43:49.118: INFO: The status of Pod coredns-7c949f49d5-p6f2z is Pending (Ready = false), waiting for it to be either Running (with Ready = true) or Failed
Oct  4 06:43:49.118: INFO: 10 / 11 pods in namespace 'kube-system' are running and ready (438 seconds elapsed)
Oct  4 06:43:49.118: INFO: expected 6 pod replicas in namespace 'kube-system', 5 are Running and Ready.
Oct  4 06:43:49.118: INFO: POD                       NODE  PHASE    GRACE  CONDITIONS
Oct  4 06:43:49.118: INFO: coredns-7c949f49d5-p6f2z        Pending         [{PodScheduled False 0001-01-01 00:00:00 +0000 UTC 2019-05-15 03:24:15 +0000 UTC Unschedulable 0/1 nodes are available: 1 node(s) didn't match pod affinity/anti-affinity, 1 node(s) didn't satisfy existing pods anti-affinity rules.}]
Oct  4 06:43:49.118: INFO: 
Oct  4 06:43:51.081: INFO: The status of Pod coredns-7c949f49d5-p6f2z is Pending (Ready = false), waiting for it to be either Running (with Ready = true) or Failed
Oct  4 06:43:51.081: INFO: 10 / 11 pods in namespace 'kube-system' are running and ready (440 seconds elapsed)
Oct  4 06:43:51.081: INFO: expected 6 pod replicas in namespace 'kube-system', 5 are Running and Ready.
Oct  4 06:43:51.081: INFO: POD                       NODE  PHASE    GRACE  CONDITIONS
Oct  4 06:43:51.081: INFO: coredns-7c949f49d5-p6f2z        Pending         [{PodScheduled False 0001-01-01 00:00:00 +0000 UTC 2019-05-15 03:24:15 +0000 UTC Unschedulable 0/1 nodes are available: 1 node(s) didn't match pod affinity/anti-affinity, 1 node(s) didn't satisfy existing pods anti-affinity rules.}]
Oct  4 06:43:51.081: INFO: 
Oct  4 06:43:53.092: INFO: The status of Pod coredns-7c949f49d5-p6f2z is Pending (Ready = false), waiting for it to be either Running (with Ready = true) or Failed
Oct  4 06:43:53.092: INFO: 10 / 11 pods in namespace 'kube-system' are running and ready (442 seconds elapsed)
Oct  4 06:43:53.092: INFO: expected 6 pod replicas in namespace 'kube-system', 5 are Running and Ready.
Oct  4 06:43:53.092: INFO: POD                       NODE  PHASE    GRACE  CONDITIONS
Oct  4 06:43:53.092: INFO: coredns-7c949f49d5-p6f2z        Pending         [{PodScheduled False 0001-01-01 00:00:00 +0000 UTC 2019-05-15 03:24:15 +0000 UTC Unschedulable 0/1 nodes are available: 1 node(s) didn't match pod affinity/anti-affinity, 1 node(s) didn't satisfy existing pods anti-affinity rules.}]
Oct  4 06:43:53.092: INFO: 
Oct  4 06:43:55.087: INFO: The status of Pod coredns-7c949f49d5-p6f2z is Pending (Ready = false), waiting for it to be either Running (with Ready = true) or Failed
Oct  4 06:43:55.087: INFO: 10 / 11 pods in namespace 'kube-system' are running and ready (444 seconds elapsed)
Oct  4 06:43:55.087: INFO: expected 6 pod replicas in namespace 'kube-system', 5 are Running and Ready.
Oct  4 06:43:55.087: INFO: POD                       NODE  PHASE    GRACE  CONDITIONS
Oct  4 06:43:55.087: INFO: coredns-7c949f49d5-p6f2z        Pending         [{PodScheduled False 0001-01-01 00:00:00 +0000 UTC 2019-05-15 03:24:15 +0000 UTC Unschedulable 0/1 nodes are available: 1 node(s) didn't match pod affinity/anti-affinity, 1 node(s) didn't satisfy existing pods anti-affinity rules.}]
Oct  4 06:43:55.087: INFO: 
Oct  4 06:43:57.092: INFO: The status of Pod coredns-7c949f49d5-p6f2z is Pending (Ready = false), waiting for it to be either Running (with Ready = true) or Failed
Oct  4 06:43:57.092: INFO: 10 / 11 pods in namespace 'kube-system' are running and ready (446 seconds elapsed)
Oct  4 06:43:57.092: INFO: expected 6 pod replicas in namespace 'kube-system', 5 are Running and Ready.
Oct  4 06:43:57.092: INFO: POD                       NODE  PHASE    GRACE  CONDITIONS
Oct  4 06:43:57.092: INFO: coredns-7c949f49d5-p6f2z        Pending         [{PodScheduled False 0001-01-01 00:00:00 +0000 UTC 2019-05-15 03:24:15 +0000 UTC Unschedulable 0/1 nodes are available: 1 node(s) didn't match pod affinity/anti-affinity, 1 node(s) didn't satisfy existing pods anti-affinity rules.}]
Oct  4 06:43:57.092: INFO: 
Oct  4 06:43:59.116: INFO: The status of Pod coredns-7c949f49d5-p6f2z is Pending (Ready = false), waiting for it to be either Running (with Ready = true) or Failed
Oct  4 06:43:59.116: INFO: 10 / 11 pods in namespace 'kube-system' are running and ready (448 seconds elapsed)
Oct  4 06:43:59.116: INFO: expected 6 pod replicas in namespace 'kube-system', 5 are Running and Ready.
Oct  4 06:43:59.116: INFO: POD                       NODE  PHASE    GRACE  CONDITIONS
Oct  4 06:43:59.116: INFO: coredns-7c949f49d5-p6f2z        Pending         [{PodScheduled False 0001-01-01 00:00:00 +0000 UTC 2019-05-15 03:24:15 +0000 UTC Unschedulable 0/1 nodes are available: 1 node(s) didn't match pod affinity/anti-affinity, 1 node(s) didn't satisfy existing pods anti-affinity rules.}]
Oct  4 06:43:59.116: INFO: 
Oct  4 06:44:01.105: INFO: The status of Pod coredns-7c949f49d5-p6f2z is Pending (Ready = false), waiting for it to be either Running (with Ready = true) or Failed
Oct  4 06:44:01.105: INFO: 10 / 11 pods in namespace 'kube-system' are running and ready (450 seconds elapsed)
Oct  4 06:44:01.105: INFO: expected 6 pod replicas in namespace 'kube-system', 5 are Running and Ready.
Oct  4 06:44:01.105: INFO: POD                       NODE  PHASE    GRACE  CONDITIONS
Oct  4 06:44:01.105: INFO: coredns-7c949f49d5-p6f2z        Pending         [{PodScheduled False 0001-01-01 00:00:00 +0000 UTC 2019-05-15 03:24:15 +0000 UTC Unschedulable 0/1 nodes are available: 1 node(s) didn't match pod affinity/anti-affinity, 1 node(s) didn't satisfy existing pods anti-affinity rules.}]
Oct  4 06:44:01.105: INFO: 
Oct  4 06:44:03.096: INFO: The status of Pod coredns-7c949f49d5-p6f2z is Pending (Ready = false), waiting for it to be either Running (with Ready = true) or Failed
Oct  4 06:44:03.096: INFO: 10 / 11 pods in namespace 'kube-system' are running and ready (452 seconds elapsed)
Oct  4 06:44:03.096: INFO: expected 6 pod replicas in namespace 'kube-system', 5 are Running and Ready.
Oct  4 06:44:03.096: INFO: POD                       NODE  PHASE    GRACE  CONDITIONS
Oct  4 06:44:03.096: INFO: coredns-7c949f49d5-p6f2z        Pending         [{PodScheduled False 0001-01-01 00:00:00 +0000 UTC 2019-05-15 03:24:15 +0000 UTC Unschedulable 0/1 nodes are available: 1 node(s) didn't match pod affinity/anti-affinity, 1 node(s) didn't satisfy existing pods anti-affinity rules.}]
Oct  4 06:44:03.096: INFO: 
Oct  4 06:44:05.091: INFO: The status of Pod coredns-7c949f49d5-p6f2z is Pending (Ready = false), waiting for it to be either Running (with Ready = true) or Failed
Oct  4 06:44:05.091: INFO: 10 / 11 pods in namespace 'kube-system' are running and ready (454 seconds elapsed)
Oct  4 06:44:05.091: INFO: expected 6 pod replicas in namespace 'kube-system', 5 are Running and Ready.
Oct  4 06:44:05.091: INFO: POD                       NODE  PHASE    GRACE  CONDITIONS
Oct  4 06:44:05.091: INFO: coredns-7c949f49d5-p6f2z        Pending         [{PodScheduled False 0001-01-01 00:00:00 +0000 UTC 2019-05-15 03:24:15 +0000 UTC Unschedulable 0/1 nodes are available: 1 node(s) didn't match pod affinity/anti-affinity, 1 node(s) didn't satisfy existing pods anti-affinity rules.}]
Oct  4 06:44:05.091: INFO: 
Oct  4 06:44:07.168: INFO: The status of Pod coredns-7c949f49d5-p6f2z is Pending (Ready = false), waiting for it to be either Running (with Ready = true) or Failed
Oct  4 06:44:07.168: INFO: 10 / 11 pods in namespace 'kube-system' are running and ready (456 seconds elapsed)
Oct  4 06:44:07.168: INFO: expected 6 pod replicas in namespace 'kube-system', 5 are Running and Ready.
Oct  4 06:44:07.168: INFO: POD                       NODE  PHASE    GRACE  CONDITIONS
Oct  4 06:44:07.168: INFO: coredns-7c949f49d5-p6f2z        Pending         [{PodScheduled False 0001-01-01 00:00:00 +0000 UTC 2019-05-15 03:24:15 +0000 UTC Unschedulable 0/1 nodes are available: 1 node(s) didn't match pod affinity/anti-affinity, 1 node(s) didn't satisfy existing pods anti-affinity rules.}]
Oct  4 06:44:07.168: INFO: 
Oct  4 06:44:09.082: INFO: The status of Pod coredns-7c949f49d5-p6f2z is Pending (Ready = false), waiting for it to be either Running (with Ready = true) or Failed
Oct  4 06:44:09.082: INFO: 10 / 11 pods in namespace 'kube-system' are running and ready (458 seconds elapsed)
Oct  4 06:44:09.082: INFO: expected 6 pod replicas in namespace 'kube-system', 5 are Running and Ready.
Oct  4 06:44:09.082: INFO: POD                       NODE  PHASE    GRACE  CONDITIONS
Oct  4 06:44:09.082: INFO: coredns-7c949f49d5-p6f2z        Pending         [{PodScheduled False 0001-01-01 00:00:00 +0000 UTC 2019-05-15 03:24:15 +0000 UTC Unschedulable 0/1 nodes are available: 1 node(s) didn't match pod affinity/anti-affinity, 1 node(s) didn't satisfy existing pods anti-affinity rules.}]
Oct  4 06:44:09.082: INFO: 
Oct  4 06:44:11.213: INFO: The status of Pod coredns-7c949f49d5-p6f2z is Pending (Ready = false), waiting for it to be either Running (with Ready = true) or Failed
Oct  4 06:44:11.213: INFO: 10 / 11 pods in namespace 'kube-system' are running and ready (460 seconds elapsed)
Oct  4 06:44:11.213: INFO: expected 6 pod replicas in namespace 'kube-system', 5 are Running and Ready.
Oct  4 06:44:11.213: INFO: POD                       NODE  PHASE    GRACE  CONDITIONS
Oct  4 06:44:11.213: INFO: coredns-7c949f49d5-p6f2z        Pending         [{PodScheduled False 0001-01-01 00:00:00 +0000 UTC 2019-05-15 03:24:15 +0000 UTC Unschedulable 0/1 nodes are available: 1 node(s) didn't match pod affinity/anti-affinity, 1 node(s) didn't satisfy existing pods anti-affinity rules.}]
Oct  4 06:44:11.213: INFO: 
Oct  4 06:44:13.157: INFO: The status of Pod coredns-7c949f49d5-p6f2z is Pending (Ready = false), waiting for it to be either Running (with Ready = true) or Failed
Oct  4 06:44:13.157: INFO: 10 / 11 pods in namespace 'kube-system' are running and ready (462 seconds elapsed)
Oct  4 06:44:13.157: INFO: expected 6 pod replicas in namespace 'kube-system', 5 are Running and Ready.
Oct  4 06:44:13.157: INFO: POD                       NODE  PHASE    GRACE  CONDITIONS
Oct  4 06:44:13.157: INFO: coredns-7c949f49d5-p6f2z        Pending         [{PodScheduled False 0001-01-01 00:00:00 +0000 UTC 2019-05-15 03:24:15 +0000 UTC Unschedulable 0/1 nodes are available: 1 node(s) didn't match pod affinity/anti-affinity, 1 node(s) didn't satisfy existing pods anti-affinity rules.}]
Oct  4 06:44:13.157: INFO: 
Oct  4 06:44:15.081: INFO: The status of Pod coredns-7c949f49d5-p6f2z is Pending (Ready = false), waiting for it to be either Running (with Ready = true) or Failed
Oct  4 06:44:15.081: INFO: 10 / 11 pods in namespace 'kube-system' are running and ready (464 seconds elapsed)
Oct  4 06:44:15.081: INFO: expected 6 pod replicas in namespace 'kube-system', 5 are Running and Ready.
Oct  4 06:44:15.081: INFO: POD                       NODE  PHASE    GRACE  CONDITIONS
Oct  4 06:44:15.081: INFO: coredns-7c949f49d5-p6f2z        Pending         [{PodScheduled False 0001-01-01 00:00:00 +0000 UTC 2019-05-15 03:24:15 +0000 UTC Unschedulable 0/1 nodes are available: 1 node(s) didn't match pod affinity/anti-affinity, 1 node(s) didn't satisfy existing pods anti-affinity rules.}]
Oct  4 06:44:15.081: INFO: 
Oct  4 06:44:17.140: INFO: The status of Pod coredns-7c949f49d5-p6f2z is Pending (Ready = false), waiting for it to be either Running (with Ready = true) or Failed
Oct  4 06:44:17.140: INFO: 10 / 11 pods in namespace 'kube-system' are running and ready (466 seconds elapsed)
Oct  4 06:44:17.140: INFO: expected 6 pod replicas in namespace 'kube-system', 5 are Running and Ready.
Oct  4 06:44:17.140: INFO: POD                       NODE  PHASE    GRACE  CONDITIONS
Oct  4 06:44:17.140: INFO: coredns-7c949f49d5-p6f2z        Pending         [{PodScheduled False 0001-01-01 00:00:00 +0000 UTC 2019-05-15 03:24:15 +0000 UTC Unschedulable 0/1 nodes are available: 1 node(s) didn't match pod affinity/anti-affinity, 1 node(s) didn't satisfy existing pods anti-affinity rules.}]
Oct  4 06:44:17.140: INFO: 
Oct  4 06:44:19.120: INFO: The status of Pod coredns-7c949f49d5-p6f2z is Pending (Ready = false), waiting for it to be either Running (with Ready = true) or Failed
Oct  4 06:44:19.120: INFO: 10 / 11 pods in namespace 'kube-system' are running and ready (468 seconds elapsed)
Oct  4 06:44:19.120: INFO: expected 6 pod replicas in namespace 'kube-system', 5 are Running and Ready.
Oct  4 06:44:19.120: INFO: POD                       NODE  PHASE    GRACE  CONDITIONS
Oct  4 06:44:19.120: INFO: coredns-7c949f49d5-p6f2z        Pending         [{PodScheduled False 0001-01-01 00:00:00 +0000 UTC 2019-05-15 03:24:15 +0000 UTC Unschedulable 0/1 nodes are available: 1 node(s) didn't match pod affinity/anti-affinity, 1 node(s) didn't satisfy existing pods anti-affinity rules.}]
Oct  4 06:44:19.120: INFO: 
Oct  4 06:44:21.099: INFO: The status of Pod coredns-7c949f49d5-p6f2z is Pending (Ready = false), waiting for it to be either Running (with Ready = true) or Failed
Oct  4 06:44:21.099: INFO: 10 / 11 pods in namespace 'kube-system' are running and ready (470 seconds elapsed)
Oct  4 06:44:21.099: INFO: expected 6 pod replicas in namespace 'kube-system', 5 are Running and Ready.
Oct  4 06:44:21.099: INFO: POD                       NODE  PHASE    GRACE  CONDITIONS
Oct  4 06:44:21.099: INFO: coredns-7c949f49d5-p6f2z        Pending         [{PodScheduled False 0001-01-01 00:00:00 +0000 UTC 2019-05-15 03:24:15 +0000 UTC Unschedulable 0/1 nodes are available: 1 node(s) didn't match pod affinity/anti-affinity, 1 node(s) didn't satisfy existing pods anti-affinity rules.}]
Oct  4 06:44:21.099: INFO: 
Oct  4 06:44:23.201: INFO: The status of Pod coredns-7c949f49d5-p6f2z is Pending (Ready = false), waiting for it to be either Running (with Ready = true) or Failed
Oct  4 06:44:23.201: INFO: 10 / 11 pods in namespace 'kube-system' are running and ready (472 seconds elapsed)
Oct  4 06:44:23.201: INFO: expected 6 pod replicas in namespace 'kube-system', 5 are Running and Ready.
Oct  4 06:44:23.201: INFO: POD                       NODE  PHASE    GRACE  CONDITIONS
Oct  4 06:44:23.201: INFO: coredns-7c949f49d5-p6f2z        Pending         [{PodScheduled False 0001-01-01 00:00:00 +0000 UTC 2019-05-15 03:24:15 +0000 UTC Unschedulable 0/1 nodes are available: 1 node(s) didn't match pod affinity/anti-affinity, 1 node(s) didn't satisfy existing pods anti-affinity rules.}]
Oct  4 06:44:23.201: INFO: 
Oct  4 06:44:25.101: INFO: The status of Pod coredns-7c949f49d5-p6f2z is Pending (Ready = false), waiting for it to be either Running (with Ready = true) or Failed
Oct  4 06:44:25.101: INFO: 10 / 11 pods in namespace 'kube-system' are running and ready (474 seconds elapsed)
Oct  4 06:44:25.101: INFO: expected 6 pod replicas in namespace 'kube-system', 5 are Running and Ready.
Oct  4 06:44:25.101: INFO: POD                       NODE  PHASE    GRACE  CONDITIONS
Oct  4 06:44:25.101: INFO: coredns-7c949f49d5-p6f2z        Pending         [{PodScheduled False 0001-01-01 00:00:00 +0000 UTC 2019-05-15 03:24:15 +0000 UTC Unschedulable 0/1 nodes are available: 1 node(s) didn't match pod affinity/anti-affinity, 1 node(s) didn't satisfy existing pods anti-affinity rules.}]
Oct  4 06:44:25.101: INFO: 
Oct  4 06:44:27.091: INFO: The status of Pod coredns-7c949f49d5-p6f2z is Pending (Ready = false), waiting for it to be either Running (with Ready = true) or Failed
Oct  4 06:44:27.091: INFO: 10 / 11 pods in namespace 'kube-system' are running and ready (476 seconds elapsed)
Oct  4 06:44:27.091: INFO: expected 6 pod replicas in namespace 'kube-system', 5 are Running and Ready.
Oct  4 06:44:27.091: INFO: POD                       NODE  PHASE    GRACE  CONDITIONS
Oct  4 06:44:27.091: INFO: coredns-7c949f49d5-p6f2z        Pending         [{PodScheduled False 0001-01-01 00:00:00 +0000 UTC 2019-05-15 03:24:15 +0000 UTC Unschedulable 0/1 nodes are available: 1 node(s) didn't match pod affinity/anti-affinity, 1 node(s) didn't satisfy existing pods anti-affinity rules.}]
Oct  4 06:44:27.091: INFO: 
Oct  4 06:44:29.104: INFO: The status of Pod coredns-7c949f49d5-p6f2z is Pending (Ready = false), waiting for it to be either Running (with Ready = true) or Failed
Oct  4 06:44:29.104: INFO: 10 / 11 pods in namespace 'kube-system' are running and ready (478 seconds elapsed)
Oct  4 06:44:29.104: INFO: expected 6 pod replicas in namespace 'kube-system', 5 are Running and Ready.
Oct  4 06:44:29.104: INFO: POD                       NODE  PHASE    GRACE  CONDITIONS
Oct  4 06:44:29.104: INFO: coredns-7c949f49d5-p6f2z        Pending         [{PodScheduled False 0001-01-01 00:00:00 +0000 UTC 2019-05-15 03:24:15 +0000 UTC Unschedulable 0/1 nodes are available: 1 node(s) didn't match pod affinity/anti-affinity, 1 node(s) didn't satisfy existing pods anti-affinity rules.}]
Oct  4 06:44:29.104: INFO: 
Oct  4 06:44:31.088: INFO: The status of Pod coredns-7c949f49d5-p6f2z is Pending (Ready = false), waiting for it to be either Running (with Ready = true) or Failed
Oct  4 06:44:31.088: INFO: 10 / 11 pods in namespace 'kube-system' are running and ready (480 seconds elapsed)
Oct  4 06:44:31.088: INFO: expected 6 pod replicas in namespace 'kube-system', 5 are Running and Ready.
Oct  4 06:44:31.088: INFO: POD                       NODE  PHASE    GRACE  CONDITIONS
Oct  4 06:44:31.088: INFO: coredns-7c949f49d5-p6f2z        Pending         [{PodScheduled False 0001-01-01 00:00:00 +0000 UTC 2019-05-15 03:24:15 +0000 UTC Unschedulable 0/1 nodes are available: 1 node(s) didn't match pod affinity/anti-affinity, 1 node(s) didn't satisfy existing pods anti-affinity rules.}]
Oct  4 06:44:31.088: INFO: 
Oct  4 06:44:33.230: INFO: The status of Pod coredns-7c949f49d5-p6f2z is Pending (Ready = false), waiting for it to be either Running (with Ready = true) or Failed
Oct  4 06:44:33.230: INFO: 10 / 11 pods in namespace 'kube-system' are running and ready (482 seconds elapsed)
Oct  4 06:44:33.230: INFO: expected 6 pod replicas in namespace 'kube-system', 5 are Running and Ready.
Oct  4 06:44:33.230: INFO: POD                       NODE  PHASE    GRACE  CONDITIONS
Oct  4 06:44:33.230: INFO: coredns-7c949f49d5-p6f2z        Pending         [{PodScheduled False 0001-01-01 00:00:00 +0000 UTC 2019-05-15 03:24:15 +0000 UTC Unschedulable 0/1 nodes are available: 1 node(s) didn't match pod affinity/anti-affinity, 1 node(s) didn't satisfy existing pods anti-affinity rules.}]
Oct  4 06:44:33.230: INFO: 
Oct  4 06:44:35.085: INFO: The status of Pod coredns-7c949f49d5-p6f2z is Pending (Ready = false), waiting for it to be either Running (with Ready = true) or Failed
Oct  4 06:44:35.085: INFO: 10 / 11 pods in namespace 'kube-system' are running and ready (484 seconds elapsed)
Oct  4 06:44:35.085: INFO: expected 6 pod replicas in namespace 'kube-system', 5 are Running and Ready.
Oct  4 06:44:35.085: INFO: POD                       NODE  PHASE    GRACE  CONDITIONS
Oct  4 06:44:35.085: INFO: coredns-7c949f49d5-p6f2z        Pending         [{PodScheduled False 0001-01-01 00:00:00 +0000 UTC 2019-05-15 03:24:15 +0000 UTC Unschedulable 0/1 nodes are available: 1 node(s) didn't match pod affinity/anti-affinity, 1 node(s) didn't satisfy existing pods anti-affinity rules.}]
Oct  4 06:44:35.085: INFO: 
Oct  4 06:44:37.091: INFO: The status of Pod coredns-7c949f49d5-p6f2z is Pending (Ready = false), waiting for it to be either Running (with Ready = true) or Failed
Oct  4 06:44:37.091: INFO: 10 / 11 pods in namespace 'kube-system' are running and ready (486 seconds elapsed)
Oct  4 06:44:37.091: INFO: expected 6 pod replicas in namespace 'kube-system', 5 are Running and Ready.
Oct  4 06:44:37.091: INFO: POD                       NODE  PHASE    GRACE  CONDITIONS
Oct  4 06:44:37.091: INFO: coredns-7c949f49d5-p6f2z        Pending         [{PodScheduled False 0001-01-01 00:00:00 +0000 UTC 2019-05-15 03:24:15 +0000 UTC Unschedulable 0/1 nodes are available: 1 node(s) didn't match pod affinity/anti-affinity, 1 node(s) didn't satisfy existing pods anti-affinity rules.}]
Oct  4 06:44:37.091: INFO: 
Oct  4 06:44:39.081: INFO: The status of Pod coredns-7c949f49d5-p6f2z is Pending (Ready = false), waiting for it to be either Running (with Ready = true) or Failed
Oct  4 06:44:39.081: INFO: 10 / 11 pods in namespace 'kube-system' are running and ready (488 seconds elapsed)
Oct  4 06:44:39.081: INFO: expected 6 pod replicas in namespace 'kube-system', 5 are Running and Ready.
Oct  4 06:44:39.081: INFO: POD                       NODE  PHASE    GRACE  CONDITIONS
Oct  4 06:44:39.081: INFO: coredns-7c949f49d5-p6f2z        Pending         [{PodScheduled False 0001-01-01 00:00:00 +0000 UTC 2019-05-15 03:24:15 +0000 UTC Unschedulable 0/1 nodes are available: 1 node(s) didn't match pod affinity/anti-affinity, 1 node(s) didn't satisfy existing pods anti-affinity rules.}]
Oct  4 06:44:39.081: INFO: 
Oct  4 06:44:41.081: INFO: The status of Pod coredns-7c949f49d5-p6f2z is Pending (Ready = false), waiting for it to be either Running (with Ready = true) or Failed
Oct  4 06:44:41.081: INFO: 10 / 11 pods in namespace 'kube-system' are running and ready (490 seconds elapsed)
Oct  4 06:44:41.081: INFO: expected 6 pod replicas in namespace 'kube-system', 5 are Running and Ready.
Oct  4 06:44:41.081: INFO: POD                       NODE  PHASE    GRACE  CONDITIONS
Oct  4 06:44:41.081: INFO: coredns-7c949f49d5-p6f2z        Pending         [{PodScheduled False 0001-01-01 00:00:00 +0000 UTC 2019-05-15 03:24:15 +0000 UTC Unschedulable 0/1 nodes are available: 1 node(s) didn't match pod affinity/anti-affinity, 1 node(s) didn't satisfy existing pods anti-affinity rules.}]
Oct  4 06:44:41.081: INFO: 
Oct  4 06:44:43.093: INFO: The status of Pod coredns-7c949f49d5-p6f2z is Pending (Ready = false), waiting for it to be either Running (with Ready = true) or Failed
Oct  4 06:44:43.093: INFO: 10 / 11 pods in namespace 'kube-system' are running and ready (492 seconds elapsed)
Oct  4 06:44:43.093: INFO: expected 6 pod replicas in namespace 'kube-system', 5 are Running and Ready.
Oct  4 06:44:43.093: INFO: POD                       NODE  PHASE    GRACE  CONDITIONS
Oct  4 06:44:43.093: INFO: coredns-7c949f49d5-p6f2z        Pending         [{PodScheduled False 0001-01-01 00:00:00 +0000 UTC 2019-05-15 03:24:15 +0000 UTC Unschedulable 0/1 nodes are available: 1 node(s) didn't match pod affinity/anti-affinity, 1 node(s) didn't satisfy existing pods anti-affinity rules.}]
Oct  4 06:44:43.093: INFO: 
Oct  4 06:44:45.091: INFO: The status of Pod coredns-7c949f49d5-p6f2z is Pending (Ready = false), waiting for it to be either Running (with Ready = true) or Failed
Oct  4 06:44:45.091: INFO: 10 / 11 pods in namespace 'kube-system' are running and ready (494 seconds elapsed)
Oct  4 06:44:45.091: INFO: expected 6 pod replicas in namespace 'kube-system', 5 are Running and Ready.
Oct  4 06:44:45.091: INFO: POD                       NODE  PHASE    GRACE  CONDITIONS
Oct  4 06:44:45.091: INFO: coredns-7c949f49d5-p6f2z        Pending         [{PodScheduled False 0001-01-01 00:00:00 +0000 UTC 2019-05-15 03:24:15 +0000 UTC Unschedulable 0/1 nodes are available: 1 node(s) didn't match pod affinity/anti-affinity, 1 node(s) didn't satisfy existing pods anti-affinity rules.}]
Oct  4 06:44:45.091: INFO: 
Oct  4 06:44:47.091: INFO: The status of Pod coredns-7c949f49d5-p6f2z is Pending (Ready = false), waiting for it to be either Running (with Ready = true) or Failed
Oct  4 06:44:47.091: INFO: 10 / 11 pods in namespace 'kube-system' are running and ready (496 seconds elapsed)
Oct  4 06:44:47.091: INFO: expected 6 pod replicas in namespace 'kube-system', 5 are Running and Ready.
Oct  4 06:44:47.091: INFO: POD                       NODE  PHASE    GRACE  CONDITIONS
Oct  4 06:44:47.091: INFO: coredns-7c949f49d5-p6f2z        Pending         [{PodScheduled False 0001-01-01 00:00:00 +0000 UTC 2019-05-15 03:24:15 +0000 UTC Unschedulable 0/1 nodes are available: 1 node(s) didn't match pod affinity/anti-affinity, 1 node(s) didn't satisfy existing pods anti-affinity rules.}]
Oct  4 06:44:47.091: INFO: 
Oct  4 06:44:49.081: INFO: The status of Pod coredns-7c949f49d5-p6f2z is Pending (Ready = false), waiting for it to be either Running (with Ready = true) or Failed
Oct  4 06:44:49.081: INFO: 10 / 11 pods in namespace 'kube-system' are running and ready (498 seconds elapsed)
Oct  4 06:44:49.081: INFO: expected 6 pod replicas in namespace 'kube-system', 5 are Running and Ready.
Oct  4 06:44:49.081: INFO: POD                       NODE  PHASE    GRACE  CONDITIONS
Oct  4 06:44:49.081: INFO: coredns-7c949f49d5-p6f2z        Pending         [{PodScheduled False 0001-01-01 00:00:00 +0000 UTC 2019-05-15 03:24:15 +0000 UTC Unschedulable 0/1 nodes are available: 1 node(s) didn't match pod affinity/anti-affinity, 1 node(s) didn't satisfy existing pods anti-affinity rules.}]
Oct  4 06:44:49.081: INFO: 
Oct  4 06:44:51.241: INFO: The status of Pod coredns-7c949f49d5-p6f2z is Pending (Ready = false), waiting for it to be either Running (with Ready = true) or Failed
Oct  4 06:44:51.241: INFO: 10 / 11 pods in namespace 'kube-system' are running and ready (500 seconds elapsed)
Oct  4 06:44:51.241: INFO: expected 6 pod replicas in namespace 'kube-system', 5 are Running and Ready.
Oct  4 06:44:51.241: INFO: POD                       NODE  PHASE    GRACE  CONDITIONS
Oct  4 06:44:51.241: INFO: coredns-7c949f49d5-p6f2z        Pending         [{PodScheduled False 0001-01-01 00:00:00 +0000 UTC 2019-05-15 03:24:15 +0000 UTC Unschedulable 0/1 nodes are available: 1 node(s) didn't match pod affinity/anti-affinity, 1 node(s) didn't satisfy existing pods anti-affinity rules.}]
Oct  4 06:44:51.241: INFO: 
Oct  4 06:44:53.091: INFO: The status of Pod coredns-7c949f49d5-p6f2z is Pending (Ready = false), waiting for it to be either Running (with Ready = true) or Failed
Oct  4 06:44:53.091: INFO: 10 / 11 pods in namespace 'kube-system' are running and ready (502 seconds elapsed)
Oct  4 06:44:53.091: INFO: expected 6 pod replicas in namespace 'kube-system', 5 are Running and Ready.
Oct  4 06:44:53.091: INFO: POD                       NODE  PHASE    GRACE  CONDITIONS
Oct  4 06:44:53.091: INFO: coredns-7c949f49d5-p6f2z        Pending         [{PodScheduled False 0001-01-01 00:00:00 +0000 UTC 2019-05-15 03:24:15 +0000 UTC Unschedulable 0/1 nodes are available: 1 node(s) didn't match pod affinity/anti-affinity, 1 node(s) didn't satisfy existing pods anti-affinity rules.}]
Oct  4 06:44:53.091: INFO: 
Oct  4 06:44:55.087: INFO: The status of Pod coredns-7c949f49d5-p6f2z is Pending (Ready = false), waiting for it to be either Running (with Ready = true) or Failed
Oct  4 06:44:55.087: INFO: 10 / 11 pods in namespace 'kube-system' are running and ready (504 seconds elapsed)
Oct  4 06:44:55.087: INFO: expected 6 pod replicas in namespace 'kube-system', 5 are Running and Ready.
Oct  4 06:44:55.087: INFO: POD                       NODE  PHASE    GRACE  CONDITIONS
Oct  4 06:44:55.087: INFO: coredns-7c949f49d5-p6f2z        Pending         [{PodScheduled False 0001-01-01 00:00:00 +0000 UTC 2019-05-15 03:24:15 +0000 UTC Unschedulable 0/1 nodes are available: 1 node(s) didn't match pod affinity/anti-affinity, 1 node(s) didn't satisfy existing pods anti-affinity rules.}]
Oct  4 06:44:55.087: INFO: 
Oct  4 06:44:57.091: INFO: The status of Pod coredns-7c949f49d5-p6f2z is Pending (Ready = false), waiting for it to be either Running (with Ready = true) or Failed
Oct  4 06:44:57.091: INFO: 10 / 11 pods in namespace 'kube-system' are running and ready (506 seconds elapsed)
Oct  4 06:44:57.091: INFO: expected 6 pod replicas in namespace 'kube-system', 5 are Running and Ready.
Oct  4 06:44:57.091: INFO: POD                       NODE  PHASE    GRACE  CONDITIONS
Oct  4 06:44:57.091: INFO: coredns-7c949f49d5-p6f2z        Pending         [{PodScheduled False 0001-01-01 00:00:00 +0000 UTC 2019-05-15 03:24:15 +0000 UTC Unschedulable 0/1 nodes are available: 1 node(s) didn't match pod affinity/anti-affinity, 1 node(s) didn't satisfy existing pods anti-affinity rules.}]
Oct  4 06:44:57.091: INFO: 
Oct  4 06:44:59.088: INFO: The status of Pod coredns-7c949f49d5-p6f2z is Pending (Ready = false), waiting for it to be either Running (with Ready = true) or Failed
Oct  4 06:44:59.088: INFO: 10 / 11 pods in namespace 'kube-system' are running and ready (508 seconds elapsed)
Oct  4 06:44:59.088: INFO: expected 6 pod replicas in namespace 'kube-system', 5 are Running and Ready.
Oct  4 06:44:59.088: INFO: POD                       NODE  PHASE    GRACE  CONDITIONS
Oct  4 06:44:59.088: INFO: coredns-7c949f49d5-p6f2z        Pending         [{PodScheduled False 0001-01-01 00:00:00 +0000 UTC 2019-05-15 03:24:15 +0000 UTC Unschedulable 0/1 nodes are available: 1 node(s) didn't match pod affinity/anti-affinity, 1 node(s) didn't satisfy existing pods anti-affinity rules.}]
Oct  4 06:44:59.088: INFO: 
Oct  4 06:45:01.507: INFO: The status of Pod coredns-7c949f49d5-p6f2z is Pending (Ready = false), waiting for it to be either Running (with Ready = true) or Failed
Oct  4 06:45:01.507: INFO: 10 / 11 pods in namespace 'kube-system' are running and ready (510 seconds elapsed)
Oct  4 06:45:01.507: INFO: expected 6 pod replicas in namespace 'kube-system', 5 are Running and Ready.
Oct  4 06:45:01.507: INFO: POD                       NODE  PHASE    GRACE  CONDITIONS
Oct  4 06:45:01.507: INFO: coredns-7c949f49d5-p6f2z        Pending         [{PodScheduled False 0001-01-01 00:00:00 +0000 UTC 2019-05-15 03:24:15 +0000 UTC Unschedulable 0/1 nodes are available: 1 node(s) didn't match pod affinity/anti-affinity, 1 node(s) didn't satisfy existing pods anti-affinity rules.}]
Oct  4 06:45:01.507: INFO: 
Oct  4 06:45:03.092: INFO: The status of Pod coredns-7c949f49d5-p6f2z is Pending (Ready = false), waiting for it to be either Running (with Ready = true) or Failed
Oct  4 06:45:03.092: INFO: 10 / 11 pods in namespace 'kube-system' are running and ready (512 seconds elapsed)
Oct  4 06:45:03.092: INFO: expected 6 pod replicas in namespace 'kube-system', 5 are Running and Ready.
Oct  4 06:45:03.092: INFO: POD                       NODE  PHASE    GRACE  CONDITIONS
Oct  4 06:45:03.092: INFO: coredns-7c949f49d5-p6f2z        Pending         [{PodScheduled False 0001-01-01 00:00:00 +0000 UTC 2019-05-15 03:24:15 +0000 UTC Unschedulable 0/1 nodes are available: 1 node(s) didn't match pod affinity/anti-affinity, 1 node(s) didn't satisfy existing pods anti-affinity rules.}]
Oct  4 06:45:03.092: INFO: 
Oct  4 06:45:05.090: INFO: The status of Pod coredns-7c949f49d5-p6f2z is Pending (Ready = false), waiting for it to be either Running (with Ready = true) or Failed
Oct  4 06:45:05.090: INFO: 10 / 11 pods in namespace 'kube-system' are running and ready (514 seconds elapsed)
Oct  4 06:45:05.090: INFO: expected 6 pod replicas in namespace 'kube-system', 5 are Running and Ready.
Oct  4 06:45:05.090: INFO: POD                       NODE  PHASE    GRACE  CONDITIONS
Oct  4 06:45:05.090: INFO: coredns-7c949f49d5-p6f2z        Pending         [{PodScheduled False 0001-01-01 00:00:00 +0000 UTC 2019-05-15 03:24:15 +0000 UTC Unschedulable 0/1 nodes are available: 1 node(s) didn't match pod affinity/anti-affinity, 1 node(s) didn't satisfy existing pods anti-affinity rules.}]
Oct  4 06:45:05.090: INFO: 
Oct  4 06:45:07.091: INFO: The status of Pod coredns-7c949f49d5-p6f2z is Pending (Ready = false), waiting for it to be either Running (with Ready = true) or Failed
Oct  4 06:45:07.091: INFO: 10 / 11 pods in namespace 'kube-system' are running and ready (516 seconds elapsed)
Oct  4 06:45:07.091: INFO: expected 6 pod replicas in namespace 'kube-system', 5 are Running and Ready.
Oct  4 06:45:07.091: INFO: POD                       NODE  PHASE    GRACE  CONDITIONS
Oct  4 06:45:07.091: INFO: coredns-7c949f49d5-p6f2z        Pending         [{PodScheduled False 0001-01-01 00:00:00 +0000 UTC 2019-05-15 03:24:15 +0000 UTC Unschedulable 0/1 nodes are available: 1 node(s) didn't match pod affinity/anti-affinity, 1 node(s) didn't satisfy existing pods anti-affinity rules.}]
Oct  4 06:45:07.091: INFO: 
Oct  4 06:45:09.083: INFO: The status of Pod coredns-7c949f49d5-p6f2z is Pending (Ready = false), waiting for it to be either Running (with Ready = true) or Failed
Oct  4 06:45:09.083: INFO: 10 / 11 pods in namespace 'kube-system' are running and ready (518 seconds elapsed)
Oct  4 06:45:09.083: INFO: expected 6 pod replicas in namespace 'kube-system', 5 are Running and Ready.
Oct  4 06:45:09.083: INFO: POD                       NODE  PHASE    GRACE  CONDITIONS
Oct  4 06:45:09.083: INFO: coredns-7c949f49d5-p6f2z        Pending         [{PodScheduled False 0001-01-01 00:00:00 +0000 UTC 2019-05-15 03:24:15 +0000 UTC Unschedulable 0/1 nodes are available: 1 node(s) didn't match pod affinity/anti-affinity, 1 node(s) didn't satisfy existing pods anti-affinity rules.}]
Oct  4 06:45:09.083: INFO: 
Oct  4 06:45:11.116: INFO: The status of Pod coredns-7c949f49d5-p6f2z is Pending (Ready = false), waiting for it to be either Running (with Ready = true) or Failed
Oct  4 06:45:11.116: INFO: 10 / 11 pods in namespace 'kube-system' are running and ready (520 seconds elapsed)
Oct  4 06:45:11.116: INFO: expected 6 pod replicas in namespace 'kube-system', 5 are Running and Ready.
Oct  4 06:45:11.116: INFO: POD                       NODE  PHASE    GRACE  CONDITIONS
Oct  4 06:45:11.116: INFO: coredns-7c949f49d5-p6f2z        Pending         [{PodScheduled False 0001-01-01 00:00:00 +0000 UTC 2019-05-15 03:24:15 +0000 UTC Unschedulable 0/1 nodes are available: 1 node(s) didn't match pod affinity/anti-affinity, 1 node(s) didn't satisfy existing pods anti-affinity rules.}]
Oct  4 06:45:11.116: INFO: 
Oct  4 06:45:13.092: INFO: The status of Pod coredns-7c949f49d5-p6f2z is Pending (Ready = false), waiting for it to be either Running (with Ready = true) or Failed
Oct  4 06:45:13.092: INFO: 10 / 11 pods in namespace 'kube-system' are running and ready (522 seconds elapsed)
Oct  4 06:45:13.092: INFO: expected 6 pod replicas in namespace 'kube-system', 5 are Running and Ready.
Oct  4 06:45:13.092: INFO: POD                       NODE  PHASE    GRACE  CONDITIONS
Oct  4 06:45:13.092: INFO: coredns-7c949f49d5-p6f2z        Pending         [{PodScheduled False 0001-01-01 00:00:00 +0000 UTC 2019-05-15 03:24:15 +0000 UTC Unschedulable 0/1 nodes are available: 1 node(s) didn't match pod affinity/anti-affinity, 1 node(s) didn't satisfy existing pods anti-affinity rules.}]
Oct  4 06:45:13.092: INFO: 
Oct  4 06:45:15.091: INFO: The status of Pod coredns-7c949f49d5-p6f2z is Pending (Ready = false), waiting for it to be either Running (with Ready = true) or Failed
Oct  4 06:45:15.091: INFO: 10 / 11 pods in namespace 'kube-system' are running and ready (524 seconds elapsed)
Oct  4 06:45:15.091: INFO: expected 6 pod replicas in namespace 'kube-system', 5 are Running and Ready.
Oct  4 06:45:15.091: INFO: POD                       NODE  PHASE    GRACE  CONDITIONS
Oct  4 06:45:15.091: INFO: coredns-7c949f49d5-p6f2z        Pending         [{PodScheduled False 0001-01-01 00:00:00 +0000 UTC 2019-05-15 03:24:15 +0000 UTC Unschedulable 0/1 nodes are available: 1 node(s) didn't match pod affinity/anti-affinity, 1 node(s) didn't satisfy existing pods anti-affinity rules.}]
Oct  4 06:45:15.091: INFO: 
Oct  4 06:45:17.091: INFO: The status of Pod coredns-7c949f49d5-p6f2z is Pending (Ready = false), waiting for it to be either Running (with Ready = true) or Failed
Oct  4 06:45:17.091: INFO: 10 / 11 pods in namespace 'kube-system' are running and ready (526 seconds elapsed)
Oct  4 06:45:17.091: INFO: expected 6 pod replicas in namespace 'kube-system', 5 are Running and Ready.
Oct  4 06:45:17.091: INFO: POD                       NODE  PHASE    GRACE  CONDITIONS
Oct  4 06:45:17.091: INFO: coredns-7c949f49d5-p6f2z        Pending         [{PodScheduled False 0001-01-01 00:00:00 +0000 UTC 2019-05-15 03:24:15 +0000 UTC Unschedulable 0/1 nodes are available: 1 node(s) didn't match pod affinity/anti-affinity, 1 node(s) didn't satisfy existing pods anti-affinity rules.}]
Oct  4 06:45:17.091: INFO: 
Oct  4 06:45:19.084: INFO: The status of Pod coredns-7c949f49d5-p6f2z is Pending (Ready = false), waiting for it to be either Running (with Ready = true) or Failed
Oct  4 06:45:19.084: INFO: 10 / 11 pods in namespace 'kube-system' are running and ready (528 seconds elapsed)
Oct  4 06:45:19.084: INFO: expected 6 pod replicas in namespace 'kube-system', 5 are Running and Ready.
Oct  4 06:45:19.084: INFO: POD                       NODE  PHASE    GRACE  CONDITIONS
Oct  4 06:45:19.084: INFO: coredns-7c949f49d5-p6f2z        Pending         [{PodScheduled False 0001-01-01 00:00:00 +0000 UTC 2019-05-15 03:24:15 +0000 UTC Unschedulable 0/1 nodes are available: 1 node(s) didn't match pod affinity/anti-affinity, 1 node(s) didn't satisfy existing pods anti-affinity rules.}]
Oct  4 06:45:19.084: INFO: 
Oct  4 06:45:21.081: INFO: The status of Pod coredns-7c949f49d5-p6f2z is Pending (Ready = false), waiting for it to be either Running (with Ready = true) or Failed
Oct  4 06:45:21.081: INFO: 10 / 11 pods in namespace 'kube-system' are running and ready (530 seconds elapsed)
Oct  4 06:45:21.081: INFO: expected 6 pod replicas in namespace 'kube-system', 5 are Running and Ready.
Oct  4 06:45:21.081: INFO: POD                       NODE  PHASE    GRACE  CONDITIONS
Oct  4 06:45:21.081: INFO: coredns-7c949f49d5-p6f2z        Pending         [{PodScheduled False 0001-01-01 00:00:00 +0000 UTC 2019-05-15 03:24:15 +0000 UTC Unschedulable 0/1 nodes are available: 1 node(s) didn't match pod affinity/anti-affinity, 1 node(s) didn't satisfy existing pods anti-affinity rules.}]
Oct  4 06:45:21.081: INFO: 
Oct  4 06:45:23.091: INFO: The status of Pod coredns-7c949f49d5-p6f2z is Pending (Ready = false), waiting for it to be either Running (with Ready = true) or Failed
Oct  4 06:45:23.091: INFO: 10 / 11 pods in namespace 'kube-system' are running and ready (532 seconds elapsed)
Oct  4 06:45:23.091: INFO: expected 6 pod replicas in namespace 'kube-system', 5 are Running and Ready.
Oct  4 06:45:23.091: INFO: POD                       NODE  PHASE    GRACE  CONDITIONS
Oct  4 06:45:23.091: INFO: coredns-7c949f49d5-p6f2z        Pending         [{PodScheduled False 0001-01-01 00:00:00 +0000 UTC 2019-05-15 03:24:15 +0000 UTC Unschedulable 0/1 nodes are available: 1 node(s) didn't match pod affinity/anti-affinity, 1 node(s) didn't satisfy existing pods anti-affinity rules.}]
Oct  4 06:45:23.091: INFO: 
Oct  4 06:45:25.091: INFO: The status of Pod coredns-7c949f49d5-p6f2z is Pending (Ready = false), waiting for it to be either Running (with Ready = true) or Failed
Oct  4 06:45:25.091: INFO: 10 / 11 pods in namespace 'kube-system' are running and ready (534 seconds elapsed)
Oct  4 06:45:25.091: INFO: expected 6 pod replicas in namespace 'kube-system', 5 are Running and Ready.
Oct  4 06:45:25.091: INFO: POD                       NODE  PHASE    GRACE  CONDITIONS
Oct  4 06:45:25.091: INFO: coredns-7c949f49d5-p6f2z        Pending         [{PodScheduled False 0001-01-01 00:00:00 +0000 UTC 2019-05-15 03:24:15 +0000 UTC Unschedulable 0/1 nodes are available: 1 node(s) didn't match pod affinity/anti-affinity, 1 node(s) didn't satisfy existing pods anti-affinity rules.}]
Oct  4 06:45:25.091: INFO: 
Oct  4 06:45:27.092: INFO: The status of Pod coredns-7c949f49d5-p6f2z is Pending (Ready = false), waiting for it to be either Running (with Ready = true) or Failed
Oct  4 06:45:27.092: INFO: 10 / 11 pods in namespace 'kube-system' are running and ready (536 seconds elapsed)
Oct  4 06:45:27.092: INFO: expected 6 pod replicas in namespace 'kube-system', 5 are Running and Ready.
Oct  4 06:45:27.092: INFO: POD                       NODE  PHASE    GRACE  CONDITIONS
Oct  4 06:45:27.092: INFO: coredns-7c949f49d5-p6f2z        Pending         [{PodScheduled False 0001-01-01 00:00:00 +0000 UTC 2019-05-15 03:24:15 +0000 UTC Unschedulable 0/1 nodes are available: 1 node(s) didn't match pod affinity/anti-affinity, 1 node(s) didn't satisfy existing pods anti-affinity rules.}]
Oct  4 06:45:27.092: INFO: 
Oct  4 06:45:29.081: INFO: The status of Pod coredns-7c949f49d5-p6f2z is Pending (Ready = false), waiting for it to be either Running (with Ready = true) or Failed
Oct  4 06:45:29.081: INFO: 10 / 11 pods in namespace 'kube-system' are running and ready (538 seconds elapsed)
Oct  4 06:45:29.081: INFO: expected 6 pod replicas in namespace 'kube-system', 5 are Running and Ready.
Oct  4 06:45:29.081: INFO: POD                       NODE  PHASE    GRACE  CONDITIONS
Oct  4 06:45:29.082: INFO: coredns-7c949f49d5-p6f2z        Pending         [{PodScheduled False 0001-01-01 00:00:00 +0000 UTC 2019-05-15 03:24:15 +0000 UTC Unschedulable 0/1 nodes are available: 1 node(s) didn't match pod affinity/anti-affinity, 1 node(s) didn't satisfy existing pods anti-affinity rules.}]
Oct  4 06:45:29.082: INFO: 
Oct  4 06:45:31.091: INFO: The status of Pod coredns-7c949f49d5-p6f2z is Pending (Ready = false), waiting for it to be either Running (with Ready = true) or Failed
Oct  4 06:45:31.091: INFO: 10 / 11 pods in namespace 'kube-system' are running and ready (540 seconds elapsed)
Oct  4 06:45:31.091: INFO: expected 6 pod replicas in namespace 'kube-system', 5 are Running and Ready.
Oct  4 06:45:31.091: INFO: POD                       NODE  PHASE    GRACE  CONDITIONS
Oct  4 06:45:31.091: INFO: coredns-7c949f49d5-p6f2z        Pending         [{PodScheduled False 0001-01-01 00:00:00 +0000 UTC 2019-05-15 03:24:15 +0000 UTC Unschedulable 0/1 nodes are available: 1 node(s) didn't match pod affinity/anti-affinity, 1 node(s) didn't satisfy existing pods anti-affinity rules.}]
Oct  4 06:45:31.091: INFO: 
Oct  4 06:45:33.091: INFO: The status of Pod coredns-7c949f49d5-p6f2z is Pending (Ready = false), waiting for it to be either Running (with Ready = true) or Failed
Oct  4 06:45:33.091: INFO: 10 / 11 pods in namespace 'kube-system' are running and ready (542 seconds elapsed)
Oct  4 06:45:33.091: INFO: expected 6 pod replicas in namespace 'kube-system', 5 are Running and Ready.
Oct  4 06:45:33.091: INFO: POD                       NODE  PHASE    GRACE  CONDITIONS
Oct  4 06:45:33.091: INFO: coredns-7c949f49d5-p6f2z        Pending         [{PodScheduled False 0001-01-01 00:00:00 +0000 UTC 2019-05-15 03:24:15 +0000 UTC Unschedulable 0/1 nodes are available: 1 node(s) didn't match pod affinity/anti-affinity, 1 node(s) didn't satisfy existing pods anti-affinity rules.}]
Oct  4 06:45:33.091: INFO: 
Oct  4 06:45:35.091: INFO: The status of Pod coredns-7c949f49d5-p6f2z is Pending (Ready = false), waiting for it to be either Running (with Ready = true) or Failed
Oct  4 06:45:35.091: INFO: 10 / 11 pods in namespace 'kube-system' are running and ready (544 seconds elapsed)
Oct  4 06:45:35.091: INFO: expected 6 pod replicas in namespace 'kube-system', 5 are Running and Ready.
Oct  4 06:45:35.091: INFO: POD                       NODE  PHASE    GRACE  CONDITIONS
Oct  4 06:45:35.091: INFO: coredns-7c949f49d5-p6f2z        Pending         [{PodScheduled False 0001-01-01 00:00:00 +0000 UTC 2019-05-15 03:24:15 +0000 UTC Unschedulable 0/1 nodes are available: 1 node(s) didn't match pod affinity/anti-affinity, 1 node(s) didn't satisfy existing pods anti-affinity rules.}]
Oct  4 06:45:35.091: INFO: 
Oct  4 06:45:37.081: INFO: The status of Pod coredns-7c949f49d5-p6f2z is Pending (Ready = false), waiting for it to be either Running (with Ready = true) or Failed
Oct  4 06:45:37.081: INFO: 10 / 11 pods in namespace 'kube-system' are running and ready (546 seconds elapsed)
Oct  4 06:45:37.081: INFO: expected 6 pod replicas in namespace 'kube-system', 5 are Running and Ready.
Oct  4 06:45:37.081: INFO: POD                       NODE  PHASE    GRACE  CONDITIONS
Oct  4 06:45:37.081: INFO: coredns-7c949f49d5-p6f2z        Pending         [{PodScheduled False 0001-01-01 00:00:00 +0000 UTC 2019-05-15 03:24:15 +0000 UTC Unschedulable 0/1 nodes are available: 1 node(s) didn't match pod affinity/anti-affinity, 1 node(s) didn't satisfy existing pods anti-affinity rules.}]
Oct  4 06:45:37.081: INFO: 
Oct  4 06:45:39.081: INFO: The status of Pod coredns-7c949f49d5-p6f2z is Pending (Ready = false), waiting for it to be either Running (with Ready = true) or Failed
Oct  4 06:45:39.081: INFO: 10 / 11 pods in namespace 'kube-system' are running and ready (548 seconds elapsed)
Oct  4 06:45:39.081: INFO: expected 6 pod replicas in namespace 'kube-system', 5 are Running and Ready.
Oct  4 06:45:39.081: INFO: POD                       NODE  PHASE    GRACE  CONDITIONS
Oct  4 06:45:39.081: INFO: coredns-7c949f49d5-p6f2z        Pending         [{PodScheduled False 0001-01-01 00:00:00 +0000 UTC 2019-05-15 03:24:15 +0000 UTC Unschedulable 0/1 nodes are available: 1 node(s) didn't match pod affinity/anti-affinity, 1 node(s) didn't satisfy existing pods anti-affinity rules.}]
Oct  4 06:45:39.081: INFO: 
Oct  4 06:45:41.082: INFO: The status of Pod coredns-7c949f49d5-p6f2z is Pending (Ready = false), waiting for it to be either Running (with Ready = true) or Failed
Oct  4 06:45:41.082: INFO: 10 / 11 pods in namespace 'kube-system' are running and ready (550 seconds elapsed)
Oct  4 06:45:41.082: INFO: expected 6 pod replicas in namespace 'kube-system', 5 are Running and Ready.
Oct  4 06:45:41.082: INFO: POD                       NODE  PHASE    GRACE  CONDITIONS
Oct  4 06:45:41.082: INFO: coredns-7c949f49d5-p6f2z        Pending         [{PodScheduled False 0001-01-01 00:00:00 +0000 UTC 2019-05-15 03:24:15 +0000 UTC Unschedulable 0/1 nodes are available: 1 node(s) didn't match pod affinity/anti-affinity, 1 node(s) didn't satisfy existing pods anti-affinity rules.}]
Oct  4 06:45:41.082: INFO: 
Oct  4 06:45:43.092: INFO: The status of Pod coredns-7c949f49d5-p6f2z is Pending (Ready = false), waiting for it to be either Running (with Ready = true) or Failed
Oct  4 06:45:43.092: INFO: 10 / 11 pods in namespace 'kube-system' are running and ready (552 seconds elapsed)
Oct  4 06:45:43.092: INFO: expected 6 pod replicas in namespace 'kube-system', 5 are Running and Ready.
Oct  4 06:45:43.092: INFO: POD                       NODE  PHASE    GRACE  CONDITIONS
Oct  4 06:45:43.092: INFO: coredns-7c949f49d5-p6f2z        Pending         [{PodScheduled False 0001-01-01 00:00:00 +0000 UTC 2019-05-15 03:24:15 +0000 UTC Unschedulable 0/1 nodes are available: 1 node(s) didn't match pod affinity/anti-affinity, 1 node(s) didn't satisfy existing pods anti-affinity rules.}]
Oct  4 06:45:43.092: INFO: 
Oct  4 06:45:45.091: INFO: The status of Pod coredns-7c949f49d5-p6f2z is Pending (Ready = false), waiting for it to be either Running (with Ready = true) or Failed
Oct  4 06:45:45.091: INFO: 10 / 11 pods in namespace 'kube-system' are running and ready (554 seconds elapsed)
Oct  4 06:45:45.091: INFO: expected 6 pod replicas in namespace 'kube-system', 5 are Running and Ready.
Oct  4 06:45:45.091: INFO: POD                       NODE  PHASE    GRACE  CONDITIONS
Oct  4 06:45:45.091: INFO: coredns-7c949f49d5-p6f2z        Pending         [{PodScheduled False 0001-01-01 00:00:00 +0000 UTC 2019-05-15 03:24:15 +0000 UTC Unschedulable 0/1 nodes are available: 1 node(s) didn't match pod affinity/anti-affinity, 1 node(s) didn't satisfy existing pods anti-affinity rules.}]
Oct  4 06:45:45.091: INFO: 
Oct  4 06:45:47.094: INFO: The status of Pod coredns-7c949f49d5-p6f2z is Pending (Ready = false), waiting for it to be either Running (with Ready = true) or Failed
Oct  4 06:45:47.094: INFO: 10 / 11 pods in namespace 'kube-system' are running and ready (556 seconds elapsed)
Oct  4 06:45:47.094: INFO: expected 6 pod replicas in namespace 'kube-system', 5 are Running and Ready.
Oct  4 06:45:47.094: INFO: POD                       NODE  PHASE    GRACE  CONDITIONS
Oct  4 06:45:47.094: INFO: coredns-7c949f49d5-p6f2z        Pending         [{PodScheduled False 0001-01-01 00:00:00 +0000 UTC 2019-05-15 03:24:15 +0000 UTC Unschedulable 0/1 nodes are available: 1 node(s) didn't match pod affinity/anti-affinity, 1 node(s) didn't satisfy existing pods anti-affinity rules.}]
Oct  4 06:45:47.094: INFO: 
Oct  4 06:45:49.081: INFO: The status of Pod coredns-7c949f49d5-p6f2z is Pending (Ready = false), waiting for it to be either Running (with Ready = true) or Failed
Oct  4 06:45:49.081: INFO: 10 / 11 pods in namespace 'kube-system' are running and ready (558 seconds elapsed)
Oct  4 06:45:49.081: INFO: expected 6 pod replicas in namespace 'kube-system', 5 are Running and Ready.
Oct  4 06:45:49.081: INFO: POD                       NODE  PHASE    GRACE  CONDITIONS
Oct  4 06:45:49.081: INFO: coredns-7c949f49d5-p6f2z        Pending         [{PodScheduled False 0001-01-01 00:00:00 +0000 UTC 2019-05-15 03:24:15 +0000 UTC Unschedulable 0/1 nodes are available: 1 node(s) didn't match pod affinity/anti-affinity, 1 node(s) didn't satisfy existing pods anti-affinity rules.}]
Oct  4 06:45:49.081: INFO: 
Oct  4 06:45:51.081: INFO: The status of Pod coredns-7c949f49d5-p6f2z is Pending (Ready = false), waiting for it to be either Running (with Ready = true) or Failed
Oct  4 06:45:51.081: INFO: 10 / 11 pods in namespace 'kube-system' are running and ready (560 seconds elapsed)
Oct  4 06:45:51.081: INFO: expected 6 pod replicas in namespace 'kube-system', 5 are Running and Ready.
Oct  4 06:45:51.081: INFO: POD                       NODE  PHASE    GRACE  CONDITIONS
Oct  4 06:45:51.081: INFO: coredns-7c949f49d5-p6f2z        Pending         [{PodScheduled False 0001-01-01 00:00:00 +0000 UTC 2019-05-15 03:24:15 +0000 UTC Unschedulable 0/1 nodes are available: 1 node(s) didn't match pod affinity/anti-affinity, 1 node(s) didn't satisfy existing pods anti-affinity rules.}]
Oct  4 06:45:51.081: INFO: 
Oct  4 06:45:53.090: INFO: The status of Pod coredns-7c949f49d5-p6f2z is Pending (Ready = false), waiting for it to be either Running (with Ready = true) or Failed
Oct  4 06:45:53.090: INFO: 10 / 11 pods in namespace 'kube-system' are running and ready (562 seconds elapsed)
Oct  4 06:45:53.090: INFO: expected 6 pod replicas in namespace 'kube-system', 5 are Running and Ready.
Oct  4 06:45:53.090: INFO: POD                       NODE  PHASE    GRACE  CONDITIONS
Oct  4 06:45:53.090: INFO: coredns-7c949f49d5-p6f2z        Pending         [{PodScheduled False 0001-01-01 00:00:00 +0000 UTC 2019-05-15 03:24:15 +0000 UTC Unschedulable 0/1 nodes are available: 1 node(s) didn't match pod affinity/anti-affinity, 1 node(s) didn't satisfy existing pods anti-affinity rules.}]
Oct  4 06:45:53.090: INFO: 
Oct  4 06:45:55.379: INFO: The status of Pod coredns-7c949f49d5-p6f2z is Pending (Ready = false), waiting for it to be either Running (with Ready = true) or Failed
Oct  4 06:45:55.379: INFO: 10 / 11 pods in namespace 'kube-system' are running and ready (564 seconds elapsed)
Oct  4 06:45:55.379: INFO: expected 6 pod replicas in namespace 'kube-system', 5 are Running and Ready.
Oct  4 06:45:55.379: INFO: POD                       NODE  PHASE    GRACE  CONDITIONS
Oct  4 06:45:55.379: INFO: coredns-7c949f49d5-p6f2z        Pending         [{PodScheduled False 0001-01-01 00:00:00 +0000 UTC 2019-05-15 03:24:15 +0000 UTC Unschedulable 0/1 nodes are available: 1 node(s) didn't match pod affinity/anti-affinity, 1 node(s) didn't satisfy existing pods anti-affinity rules.}]
Oct  4 06:45:55.379: INFO: 
Oct  4 06:45:57.319: INFO: The status of Pod coredns-7c949f49d5-p6f2z is Pending (Ready = false), waiting for it to be either Running (with Ready = true) or Failed
Oct  4 06:45:57.319: INFO: 10 / 11 pods in namespace 'kube-system' are running and ready (566 seconds elapsed)
Oct  4 06:45:57.319: INFO: expected 6 pod replicas in namespace 'kube-system', 5 are Running and Ready.
Oct  4 06:45:57.319: INFO: POD                       NODE  PHASE    GRACE  CONDITIONS
Oct  4 06:45:57.319: INFO: coredns-7c949f49d5-p6f2z        Pending         [{PodScheduled False 0001-01-01 00:00:00 +0000 UTC 2019-05-15 03:24:15 +0000 UTC Unschedulable 0/1 nodes are available: 1 node(s) didn't match pod affinity/anti-affinity, 1 node(s) didn't satisfy existing pods anti-affinity rules.}]
Oct  4 06:45:57.319: INFO: 
Oct  4 06:45:59.082: INFO: The status of Pod coredns-7c949f49d5-p6f2z is Pending (Ready = false), waiting for it to be either Running (with Ready = true) or Failed
Oct  4 06:45:59.082: INFO: 10 / 11 pods in namespace 'kube-system' are running and ready (568 seconds elapsed)
Oct  4 06:45:59.082: INFO: expected 6 pod replicas in namespace 'kube-system', 5 are Running and Ready.
Oct  4 06:45:59.082: INFO: POD                       NODE  PHASE    GRACE  CONDITIONS
Oct  4 06:45:59.082: INFO: coredns-7c949f49d5-p6f2z        Pending         [{PodScheduled False 0001-01-01 00:00:00 +0000 UTC 2019-05-15 03:24:15 +0000 UTC Unschedulable 0/1 nodes are available: 1 node(s) didn't match pod affinity/anti-affinity, 1 node(s) didn't satisfy existing pods anti-affinity rules.}]
Oct  4 06:45:59.082: INFO: 
Oct  4 06:46:01.081: INFO: The status of Pod coredns-7c949f49d5-p6f2z is Pending (Ready = false), waiting for it to be either Running (with Ready = true) or Failed
Oct  4 06:46:01.081: INFO: 10 / 11 pods in namespace 'kube-system' are running and ready (570 seconds elapsed)
Oct  4 06:46:01.081: INFO: expected 6 pod replicas in namespace 'kube-system', 5 are Running and Ready.
Oct  4 06:46:01.081: INFO: POD                       NODE  PHASE    GRACE  CONDITIONS
Oct  4 06:46:01.081: INFO: coredns-7c949f49d5-p6f2z        Pending         [{PodScheduled False 0001-01-01 00:00:00 +0000 UTC 2019-05-15 03:24:15 +0000 UTC Unschedulable 0/1 nodes are available: 1 node(s) didn't match pod affinity/anti-affinity, 1 node(s) didn't satisfy existing pods anti-affinity rules.}]
Oct  4 06:46:01.081: INFO: 
Oct  4 06:46:03.089: INFO: The status of Pod coredns-7c949f49d5-p6f2z is Pending (Ready = false), waiting for it to be either Running (with Ready = true) or Failed
Oct  4 06:46:03.089: INFO: 10 / 11 pods in namespace 'kube-system' are running and ready (572 seconds elapsed)
Oct  4 06:46:03.089: INFO: expected 6 pod replicas in namespace 'kube-system', 5 are Running and Ready.
Oct  4 06:46:03.089: INFO: POD                       NODE  PHASE    GRACE  CONDITIONS
Oct  4 06:46:03.089: INFO: coredns-7c949f49d5-p6f2z        Pending         [{PodScheduled False 0001-01-01 00:00:00 +0000 UTC 2019-05-15 03:24:15 +0000 UTC Unschedulable 0/1 nodes are available: 1 node(s) didn't match pod affinity/anti-affinity, 1 node(s) didn't satisfy existing pods anti-affinity rules.}]
Oct  4 06:46:03.089: INFO: 
Oct  4 06:46:05.116: INFO: The status of Pod coredns-7c949f49d5-p6f2z is Pending (Ready = false), waiting for it to be either Running (with Ready = true) or Failed
Oct  4 06:46:05.116: INFO: 10 / 11 pods in namespace 'kube-system' are running and ready (574 seconds elapsed)
Oct  4 06:46:05.116: INFO: expected 6 pod replicas in namespace 'kube-system', 5 are Running and Ready.
Oct  4 06:46:05.116: INFO: POD                       NODE  PHASE    GRACE  CONDITIONS
Oct  4 06:46:05.116: INFO: coredns-7c949f49d5-p6f2z        Pending         [{PodScheduled False 0001-01-01 00:00:00 +0000 UTC 2019-05-15 03:24:15 +0000 UTC Unschedulable 0/1 nodes are available: 1 node(s) didn't match pod affinity/anti-affinity, 1 node(s) didn't satisfy existing pods anti-affinity rules.}]
Oct  4 06:46:05.116: INFO: 
Oct  4 06:46:07.089: INFO: The status of Pod coredns-7c949f49d5-p6f2z is Pending (Ready = false), waiting for it to be either Running (with Ready = true) or Failed
Oct  4 06:46:07.089: INFO: 10 / 11 pods in namespace 'kube-system' are running and ready (576 seconds elapsed)
Oct  4 06:46:07.089: INFO: expected 6 pod replicas in namespace 'kube-system', 5 are Running and Ready.
Oct  4 06:46:07.089: INFO: POD                       NODE  PHASE    GRACE  CONDITIONS
Oct  4 06:46:07.089: INFO: coredns-7c949f49d5-p6f2z        Pending         [{PodScheduled False 0001-01-01 00:00:00 +0000 UTC 2019-05-15 03:24:15 +0000 UTC Unschedulable 0/1 nodes are available: 1 node(s) didn't match pod affinity/anti-affinity, 1 node(s) didn't satisfy existing pods anti-affinity rules.}]
Oct  4 06:46:07.089: INFO: 
Oct  4 06:46:09.081: INFO: The status of Pod coredns-7c949f49d5-p6f2z is Pending (Ready = false), waiting for it to be either Running (with Ready = true) or Failed
Oct  4 06:46:09.081: INFO: 10 / 11 pods in namespace 'kube-system' are running and ready (578 seconds elapsed)
Oct  4 06:46:09.081: INFO: expected 6 pod replicas in namespace 'kube-system', 5 are Running and Ready.
Oct  4 06:46:09.081: INFO: POD                       NODE  PHASE    GRACE  CONDITIONS
Oct  4 06:46:09.081: INFO: coredns-7c949f49d5-p6f2z        Pending         [{PodScheduled False 0001-01-01 00:00:00 +0000 UTC 2019-05-15 03:24:15 +0000 UTC Unschedulable 0/1 nodes are available: 1 node(s) didn't match pod affinity/anti-affinity, 1 node(s) didn't satisfy existing pods anti-affinity rules.}]
Oct  4 06:46:09.081: INFO: 
Oct  4 06:46:11.081: INFO: The status of Pod coredns-7c949f49d5-p6f2z is Pending (Ready = false), waiting for it to be either Running (with Ready = true) or Failed
Oct  4 06:46:11.081: INFO: 10 / 11 pods in namespace 'kube-system' are running and ready (580 seconds elapsed)
Oct  4 06:46:11.081: INFO: expected 6 pod replicas in namespace 'kube-system', 5 are Running and Ready.
Oct  4 06:46:11.081: INFO: POD                       NODE  PHASE    GRACE  CONDITIONS
Oct  4 06:46:11.081: INFO: coredns-7c949f49d5-p6f2z        Pending         [{PodScheduled False 0001-01-01 00:00:00 +0000 UTC 2019-05-15 03:24:15 +0000 UTC Unschedulable 0/1 nodes are available: 1 node(s) didn't match pod affinity/anti-affinity, 1 node(s) didn't satisfy existing pods anti-affinity rules.}]
Oct  4 06:46:11.081: INFO: 
Oct  4 06:46:13.088: INFO: The status of Pod coredns-7c949f49d5-p6f2z is Pending (Ready = false), waiting for it to be either Running (with Ready = true) or Failed
Oct  4 06:46:13.088: INFO: 10 / 11 pods in namespace 'kube-system' are running and ready (582 seconds elapsed)
Oct  4 06:46:13.088: INFO: expected 6 pod replicas in namespace 'kube-system', 5 are Running and Ready.
Oct  4 06:46:13.088: INFO: POD                       NODE  PHASE    GRACE  CONDITIONS
Oct  4 06:46:13.088: INFO: coredns-7c949f49d5-p6f2z        Pending         [{PodScheduled False 0001-01-01 00:00:00 +0000 UTC 2019-05-15 03:24:15 +0000 UTC Unschedulable 0/1 nodes are available: 1 node(s) didn't match pod affinity/anti-affinity, 1 node(s) didn't satisfy existing pods anti-affinity rules.}]
Oct  4 06:46:13.088: INFO: 
Oct  4 06:46:15.137: INFO: The status of Pod coredns-7c949f49d5-p6f2z is Pending (Ready = false), waiting for it to be either Running (with Ready = true) or Failed
Oct  4 06:46:15.137: INFO: 10 / 11 pods in namespace 'kube-system' are running and ready (584 seconds elapsed)
Oct  4 06:46:15.137: INFO: expected 6 pod replicas in namespace 'kube-system', 5 are Running and Ready.
Oct  4 06:46:15.137: INFO: POD                       NODE  PHASE    GRACE  CONDITIONS
Oct  4 06:46:15.137: INFO: coredns-7c949f49d5-p6f2z        Pending         [{PodScheduled False 0001-01-01 00:00:00 +0000 UTC 2019-05-15 03:24:15 +0000 UTC Unschedulable 0/1 nodes are available: 1 node(s) didn't match pod affinity/anti-affinity, 1 node(s) didn't satisfy existing pods anti-affinity rules.}]
Oct  4 06:46:15.137: INFO: 
Oct  4 06:46:17.105: INFO: The status of Pod coredns-7c949f49d5-p6f2z is Pending (Ready = false), waiting for it to be either Running (with Ready = true) or Failed
Oct  4 06:46:17.105: INFO: 10 / 11 pods in namespace 'kube-system' are running and ready (586 seconds elapsed)
Oct  4 06:46:17.105: INFO: expected 6 pod replicas in namespace 'kube-system', 5 are Running and Ready.
Oct  4 06:46:17.105: INFO: POD                       NODE  PHASE    GRACE  CONDITIONS
Oct  4 06:46:17.105: INFO: coredns-7c949f49d5-p6f2z        Pending         [{PodScheduled False 0001-01-01 00:00:00 +0000 UTC 2019-05-15 03:24:15 +0000 UTC Unschedulable 0/1 nodes are available: 1 node(s) didn't match pod affinity/anti-affinity, 1 node(s) didn't satisfy existing pods anti-affinity rules.}]
Oct  4 06:46:17.105: INFO: 
Oct  4 06:46:19.083: INFO: The status of Pod coredns-7c949f49d5-p6f2z is Pending (Ready = false), waiting for it to be either Running (with Ready = true) or Failed
Oct  4 06:46:19.083: INFO: 10 / 11 pods in namespace 'kube-system' are running and ready (588 seconds elapsed)
Oct  4 06:46:19.083: INFO: expected 6 pod replicas in namespace 'kube-system', 5 are Running and Ready.
Oct  4 06:46:19.083: INFO: POD                       NODE  PHASE    GRACE  CONDITIONS
Oct  4 06:46:19.083: INFO: coredns-7c949f49d5-p6f2z        Pending         [{PodScheduled False 0001-01-01 00:00:00 +0000 UTC 2019-05-15 03:24:15 +0000 UTC Unschedulable 0/1 nodes are available: 1 node(s) didn't match pod affinity/anti-affinity, 1 node(s) didn't satisfy existing pods anti-affinity rules.}]
Oct  4 06:46:19.083: INFO: 
Oct  4 06:46:21.081: INFO: The status of Pod coredns-7c949f49d5-p6f2z is Pending (Ready = false), waiting for it to be either Running (with Ready = true) or Failed
Oct  4 06:46:21.081: INFO: 10 / 11 pods in namespace 'kube-system' are running and ready (590 seconds elapsed)
Oct  4 06:46:21.081: INFO: expected 6 pod replicas in namespace 'kube-system', 5 are Running and Ready.
Oct  4 06:46:21.081: INFO: POD                       NODE  PHASE    GRACE  CONDITIONS
Oct  4 06:46:21.081: INFO: coredns-7c949f49d5-p6f2z        Pending         [{PodScheduled False 0001-01-01 00:00:00 +0000 UTC 2019-05-15 03:24:15 +0000 UTC Unschedulable 0/1 nodes are available: 1 node(s) didn't match pod affinity/anti-affinity, 1 node(s) didn't satisfy existing pods anti-affinity rules.}]
Oct  4 06:46:21.081: INFO: 
Oct  4 06:46:23.090: INFO: The status of Pod coredns-7c949f49d5-p6f2z is Pending (Ready = false), waiting for it to be either Running (with Ready = true) or Failed
Oct  4 06:46:23.090: INFO: 10 / 11 pods in namespace 'kube-system' are running and ready (592 seconds elapsed)
Oct  4 06:46:23.090: INFO: expected 6 pod replicas in namespace 'kube-system', 5 are Running and Ready.
Oct  4 06:46:23.090: INFO: POD                       NODE  PHASE    GRACE  CONDITIONS
Oct  4 06:46:23.090: INFO: coredns-7c949f49d5-p6f2z        Pending         [{PodScheduled False 0001-01-01 00:00:00 +0000 UTC 2019-05-15 03:24:15 +0000 UTC Unschedulable 0/1 nodes are available: 1 node(s) didn't match pod affinity/anti-affinity, 1 node(s) didn't satisfy existing pods anti-affinity rules.}]
Oct  4 06:46:23.090: INFO: 
Oct  4 06:46:25.127: INFO: The status of Pod coredns-7c949f49d5-p6f2z is Pending (Ready = false), waiting for it to be either Running (with Ready = true) or Failed
Oct  4 06:46:25.127: INFO: 10 / 11 pods in namespace 'kube-system' are running and ready (594 seconds elapsed)
Oct  4 06:46:25.127: INFO: expected 6 pod replicas in namespace 'kube-system', 5 are Running and Ready.
Oct  4 06:46:25.127: INFO: POD                       NODE  PHASE    GRACE  CONDITIONS
Oct  4 06:46:25.127: INFO: coredns-7c949f49d5-p6f2z        Pending         [{PodScheduled False 0001-01-01 00:00:00 +0000 UTC 2019-05-15 03:24:15 +0000 UTC Unschedulable 0/1 nodes are available: 1 node(s) didn't match pod affinity/anti-affinity, 1 node(s) didn't satisfy existing pods anti-affinity rules.}]
Oct  4 06:46:25.127: INFO: 
Oct  4 06:46:27.092: INFO: The status of Pod coredns-7c949f49d5-p6f2z is Pending (Ready = false), waiting for it to be either Running (with Ready = true) or Failed
Oct  4 06:46:27.092: INFO: 10 / 11 pods in namespace 'kube-system' are running and ready (596 seconds elapsed)
Oct  4 06:46:27.092: INFO: expected 6 pod replicas in namespace 'kube-system', 5 are Running and Ready.
Oct  4 06:46:27.092: INFO: POD                       NODE  PHASE    GRACE  CONDITIONS
Oct  4 06:46:27.092: INFO: coredns-7c949f49d5-p6f2z        Pending         [{PodScheduled False 0001-01-01 00:00:00 +0000 UTC 2019-05-15 03:24:15 +0000 UTC Unschedulable 0/1 nodes are available: 1 node(s) didn't match pod affinity/anti-affinity, 1 node(s) didn't satisfy existing pods anti-affinity rules.}]
Oct  4 06:46:27.092: INFO: 
Oct  4 06:46:29.083: INFO: The status of Pod coredns-7c949f49d5-p6f2z is Pending (Ready = false), waiting for it to be either Running (with Ready = true) or Failed
Oct  4 06:46:29.083: INFO: 10 / 11 pods in namespace 'kube-system' are running and ready (598 seconds elapsed)
Oct  4 06:46:29.083: INFO: expected 6 pod replicas in namespace 'kube-system', 5 are Running and Ready.
Oct  4 06:46:29.083: INFO: POD                       NODE  PHASE    GRACE  CONDITIONS
Oct  4 06:46:29.083: INFO: coredns-7c949f49d5-p6f2z        Pending         [{PodScheduled False 0001-01-01 00:00:00 +0000 UTC 2019-05-15 03:24:15 +0000 UTC Unschedulable 0/1 nodes are available: 1 node(s) didn't match pod affinity/anti-affinity, 1 node(s) didn't satisfy existing pods anti-affinity rules.}]
Oct  4 06:46:29.083: INFO: 
Oct  4 06:46:31.083: INFO: The status of Pod coredns-7c949f49d5-p6f2z is Pending (Ready = false), waiting for it to be either Running (with Ready = true) or Failed
Oct  4 06:46:31.083: INFO: 10 / 11 pods in namespace 'kube-system' are running and ready (600 seconds elapsed)
Oct  4 06:46:31.083: INFO: expected 6 pod replicas in namespace 'kube-system', 5 are Running and Ready.
Oct  4 06:46:31.083: INFO: POD                       NODE  PHASE    GRACE  CONDITIONS
Oct  4 06:46:31.083: INFO: coredns-7c949f49d5-p6f2z        Pending         [{PodScheduled False 0001-01-01 00:00:00 +0000 UTC 2019-05-15 03:24:15 +0000 UTC Unschedulable 0/1 nodes are available: 1 node(s) didn't match pod affinity/anti-affinity, 1 node(s) didn't satisfy existing pods anti-affinity rules.}]
Oct  4 06:46:31.083: INFO: 
Oct  4 06:46:31.089: INFO: The status of Pod coredns-7c949f49d5-p6f2z is Pending (Ready = false), waiting for it to be either Running (with Ready = true) or Failed
Oct  4 06:46:31.089: INFO: 10 / 11 pods in namespace 'kube-system' are running and ready (600 seconds elapsed)
Oct  4 06:46:31.089: INFO: expected 6 pod replicas in namespace 'kube-system', 5 are Running and Ready.
Oct  4 06:46:31.089: INFO: POD                       NODE  PHASE    GRACE  CONDITIONS
Oct  4 06:46:31.089: INFO: coredns-7c949f49d5-p6f2z        Pending         [{PodScheduled False 0001-01-01 00:00:00 +0000 UTC 2019-05-15 03:24:15 +0000 UTC Unschedulable 0/1 nodes are available: 1 node(s) didn't match pod affinity/anti-affinity, 1 node(s) didn't satisfy existing pods anti-affinity rules.}]
Oct  4 06:46:31.089: INFO: 
STEP: Collecting events from namespace "kube-system".
STEP: Found 1 events.
Oct  4 06:46:31.091: INFO: At 2019-10-02 03:37:26 +0000 UTC - event for coredns-7c949f49d5-p6f2z: {default-scheduler } FailedScheduling: 0/1 nodes are available: 1 node(s) didn't match pod affinity/anti-affinity, 1 node(s) didn't satisfy existing pods anti-affinity rules.
Oct  4 06:46:31.102: INFO: POD                                                          NODE    PHASE      GRACE  CONDITIONS
Oct  4 06:46:31.102: INFO: cattle-cluster-agent-76979d7d64-8hmwb                        k8s-m1  Running           [{Initialized True 0001-01-01 00:00:00 +0000 UTC 2019-06-10 05:40:32 +0000 UTC  } {Ready False 0001-01-01 00:00:00 +0000 UTC 2019-10-04 06:41:24 +0000 UTC ContainersNotReady containers with unready status: [cluster-register]} {ContainersReady False 0001-01-01 00:00:00 +0000 UTC 0001-01-01 00:00:00 +0000 UTC ContainersNotReady containers with unready status: [cluster-register]} {PodScheduled True 0001-01-01 00:00:00 +0000 UTC 2019-06-10 05:40:31 +0000 UTC  }]
Oct  4 06:46:31.102: INFO: cattle-node-agent-vdqgv                                      k8s-m1  Running           [{Initialized True 0001-01-01 00:00:00 +0000 UTC 2019-06-10 05:40:35 +0000 UTC  } {Ready False 0001-01-01 00:00:00 +0000 UTC 2019-10-04 06:43:28 +0000 UTC ContainersNotReady containers with unready status: [agent]} {ContainersReady False 0001-01-01 00:00:00 +0000 UTC 0001-01-01 00:00:00 +0000 UTC ContainersNotReady containers with unready status: [agent]} {PodScheduled True 0001-01-01 00:00:00 +0000 UTC 2019-06-10 05:40:35 +0000 UTC  }]
Oct  4 06:46:31.102: INFO: es-deviceon-portal-6886d46868-7hnrc                          k8s-m1  Running           [{Initialized True 0001-01-01 00:00:00 +0000 UTC 2019-10-02 07:25:11 +0000 UTC  } {Ready True 0001-01-01 00:00:00 +0000 UTC 2019-10-02 07:31:45 +0000 UTC  } {ContainersReady True 0001-01-01 00:00:00 +0000 UTC 0001-01-01 00:00:00 +0000 UTC  } {PodScheduled True 0001-01-01 00:00:00 +0000 UTC 2019-10-02 07:25:05 +0000 UTC  }]
Oct  4 06:46:31.102: INFO: es-deviceon-provisioning-6f5d74c9df-2vqzm                    k8s-m1  Running           [{Initialized True 0001-01-01 00:00:00 +0000 UTC 2019-10-02 07:25:13 +0000 UTC  } {Ready True 0001-01-01 00:00:00 +0000 UTC 2019-10-02 07:28:18 +0000 UTC  } {ContainersReady True 0001-01-01 00:00:00 +0000 UTC 0001-01-01 00:00:00 +0000 UTC  } {PodScheduled True 0001-01-01 00:00:00 +0000 UTC 2019-10-02 07:25:05 +0000 UTC  }]
Oct  4 06:46:31.102: INFO: es-deviceon-worker-78f8585bcd-q55nn                          k8s-m1  Running           [{Initialized True 0001-01-01 00:00:00 +0000 UTC 2019-10-02 07:25:18 +0000 UTC  } {Ready True 0001-01-01 00:00:00 +0000 UTC 2019-10-02 07:28:49 +0000 UTC  } {ContainersReady True 0001-01-01 00:00:00 +0000 UTC 0001-01-01 00:00:00 +0000 UTC  } {PodScheduled True 0001-01-01 00:00:00 +0000 UTC 2019-10-02 07:25:05 +0000 UTC  }]
Oct  4 06:46:31.102: INFO: es-edgesense-ota-966c7fb68-f9442                             k8s-m1  Running           [{Initialized True 0001-01-01 00:00:00 +0000 UTC 2019-10-02 07:45:55 +0000 UTC  } {Ready True 0001-01-01 00:00:00 +0000 UTC 2019-10-02 07:45:57 +0000 UTC  } {ContainersReady True 0001-01-01 00:00:00 +0000 UTC 0001-01-01 00:00:00 +0000 UTC  } {PodScheduled True 0001-01-01 00:00:00 +0000 UTC 2019-10-02 07:45:47 +0000 UTC  }]
Oct  4 06:46:31.102: INFO: es-edgesense-portal-76f5b54966-x2pfx                         k8s-m1  Running           [{Initialized True 0001-01-01 00:00:00 +0000 UTC 2019-10-02 07:45:54 +0000 UTC  } {Ready True 0001-01-01 00:00:00 +0000 UTC 2019-10-02 07:45:57 +0000 UTC  } {ContainersReady True 0001-01-01 00:00:00 +0000 UTC 0001-01-01 00:00:00 +0000 UTC  } {PodScheduled True 0001-01-01 00:00:00 +0000 UTC 2019-10-02 07:45:46 +0000 UTC  }]
Oct  4 06:46:31.102: INFO: es-edgesense-worker-5b6f55fc8d-56b8t                         k8s-m1  Running           [{Initialized True 0001-01-01 00:00:00 +0000 UTC 2019-10-02 07:45:58 +0000 UTC  } {Ready True 0001-01-01 00:00:00 +0000 UTC 2019-10-02 07:46:01 +0000 UTC  } {ContainersReady True 0001-01-01 00:00:00 +0000 UTC 0001-01-01 00:00:00 +0000 UTC  } {PodScheduled True 0001-01-01 00:00:00 +0000 UTC 2019-10-02 07:45:47 +0000 UTC  }]
Oct  4 06:46:31.102: INFO: es-minio-68fb8556cf-chg6g                                    k8s-m1  Running           [{Initialized True 0001-01-01 00:00:00 +0000 UTC 2019-09-27 08:58:22 +0000 UTC  } {Ready True 0001-01-01 00:00:00 +0000 UTC 2019-10-02 03:38:39 +0000 UTC  } {ContainersReady True 0001-01-01 00:00:00 +0000 UTC 0001-01-01 00:00:00 +0000 UTC  } {PodScheduled True 0001-01-01 00:00:00 +0000 UTC 2019-09-27 08:58:22 +0000 UTC  }]
Oct  4 06:46:31.102: INFO: es-mongo-7477b4bcf-5gtwr                                     k8s-m1  Running           [{Initialized True 0001-01-01 00:00:00 +0000 UTC 2019-09-17 06:23:48 +0000 UTC  } {Ready True 0001-01-01 00:00:00 +0000 UTC 2019-10-02 03:38:41 +0000 UTC  } {ContainersReady True 0001-01-01 00:00:00 +0000 UTC 0001-01-01 00:00:00 +0000 UTC  } {PodScheduled True 0001-01-01 00:00:00 +0000 UTC 2019-08-19 06:06:50 +0000 UTC  }]
Oct  4 06:46:31.102: INFO: es-postgres-d9448cc8c-qrx45                                  k8s-m1  Running           [{Initialized True 0001-01-01 00:00:00 +0000 UTC 2019-09-03 06:08:25 +0000 UTC  } {Ready True 0001-01-01 00:00:00 +0000 UTC 2019-10-02 03:38:35 +0000 UTC  } {ContainersReady True 0001-01-01 00:00:00 +0000 UTC 0001-01-01 00:00:00 +0000 UTC  } {PodScheduled True 0001-01-01 00:00:00 +0000 UTC 2019-09-03 06:08:25 +0000 UTC  }]
Oct  4 06:46:31.102: INFO: es-rabbitmq-68b84c55d5-9pph5                                 k8s-m1  Running           [{Initialized True 0001-01-01 00:00:00 +0000 UTC 2019-09-05 09:11:16 +0000 UTC  } {Ready True 0001-01-01 00:00:00 +0000 UTC 2019-10-02 03:38:21 +0000 UTC  } {ContainersReady True 0001-01-01 00:00:00 +0000 UTC 0001-01-01 00:00:00 +0000 UTC  } {PodScheduled True 0001-01-01 00:00:00 +0000 UTC 2019-09-05 09:11:16 +0000 UTC  }]
Oct  4 06:46:31.102: INFO: sonobuoy                                                     k8s-m1  Running           [{Initialized True 0001-01-01 00:00:00 +0000 UTC 2019-10-04 06:35:56 +0000 UTC  } {Ready True 0001-01-01 00:00:00 +0000 UTC 2019-10-04 06:36:05 +0000 UTC  } {ContainersReady True 0001-01-01 00:00:00 +0000 UTC 0001-01-01 00:00:00 +0000 UTC  } {PodScheduled True 0001-01-01 00:00:00 +0000 UTC 2019-10-04 06:35:56 +0000 UTC  }]
Oct  4 06:46:31.102: INFO: sonobuoy-e2e-job-5cf60ae935f841b1                            k8s-m1  Running           [{Initialized True 0001-01-01 00:00:00 +0000 UTC 2019-10-04 06:36:04 +0000 UTC  } {Ready True 0001-01-01 00:00:00 +0000 UTC 2019-10-04 06:36:42 +0000 UTC  } {ContainersReady True 0001-01-01 00:00:00 +0000 UTC 0001-01-01 00:00:00 +0000 UTC  } {PodScheduled True 0001-01-01 00:00:00 +0000 UTC 2019-10-04 06:36:04 +0000 UTC  }]
Oct  4 06:46:31.102: INFO: calico-kube-controllers-55fcdc5bdb-k2tpm                     k8s-m1  Running           [{Initialized True 0001-01-01 00:00:00 +0000 UTC 2019-05-15 03:23:56 +0000 UTC  } {Ready True 0001-01-01 00:00:00 +0000 UTC 2019-10-02 03:37:17 +0000 UTC  } {ContainersReady True 0001-01-01 00:00:00 +0000 UTC 0001-01-01 00:00:00 +0000 UTC  } {PodScheduled True 0001-01-01 00:00:00 +0000 UTC 2019-05-15 03:23:56 +0000 UTC  }]
Oct  4 06:46:31.102: INFO: calico-node-4p8hb                                            k8s-m1  Running           [{Initialized True 0001-01-01 00:00:00 +0000 UTC 2019-05-15 03:23:49 +0000 UTC  } {Ready True 0001-01-01 00:00:00 +0000 UTC 2019-10-02 03:37:35 +0000 UTC  } {ContainersReady True 0001-01-01 00:00:00 +0000 UTC 0001-01-01 00:00:00 +0000 UTC  } {PodScheduled True 0001-01-01 00:00:00 +0000 UTC 2019-05-15 03:23:49 +0000 UTC  }]
Oct  4 06:46:31.102: INFO: cert-manager-7d4bfc44ff-mcnqk                                k8s-m1  Running           [{Initialized True 0001-01-01 00:00:00 +0000 UTC 2019-06-17 05:59:03 +0000 UTC  } {Ready True 0001-01-01 00:00:00 +0000 UTC 2019-10-02 03:37:35 +0000 UTC  } {ContainersReady True 0001-01-01 00:00:00 +0000 UTC 0001-01-01 00:00:00 +0000 UTC  } {PodScheduled True 0001-01-01 00:00:00 +0000 UTC 2019-06-17 05:59:02 +0000 UTC  }]
Oct  4 06:46:31.102: INFO: coredns-7c949f49d5-m66dj                                     k8s-m1  Running           [{Initialized True 0001-01-01 00:00:00 +0000 UTC 2019-05-15 03:24:15 +0000 UTC  } {Ready True 0001-01-01 00:00:00 +0000 UTC 2019-10-02 03:37:26 +0000 UTC  } {ContainersReady True 0001-01-01 00:00:00 +0000 UTC 0001-01-01 00:00:00 +0000 UTC  } {PodScheduled True 0001-01-01 00:00:00 +0000 UTC 2019-05-15 03:24:15 +0000 UTC  }]
Oct  4 06:46:31.102: INFO: coredns-7c949f49d5-p6f2z                                             Pending           [{PodScheduled False 0001-01-01 00:00:00 +0000 UTC 2019-05-15 03:24:15 +0000 UTC Unschedulable 0/1 nodes are available: 1 node(s) didn't match pod affinity/anti-affinity, 1 node(s) didn't satisfy existing pods anti-affinity rules.}]
Oct  4 06:46:31.102: INFO: kube-apiserver-k8s-m1                                        k8s-m1  Running           [{Initialized True 0001-01-01 00:00:00 +0000 UTC 2019-09-17 06:19:38 +0000 UTC  } {Ready True 0001-01-01 00:00:00 +0000 UTC 2019-09-17 06:19:48 +0000 UTC  } {ContainersReady True 0001-01-01 00:00:00 +0000 UTC 0001-01-01 00:00:00 +0000 UTC  } {PodScheduled True 0001-01-01 00:00:00 +0000 UTC 2019-09-17 06:19:38 +0000 UTC  }]
Oct  4 06:46:31.102: INFO: kube-controller-manager-k8s-m1                               k8s-m1  Running           [{Initialized True 0001-01-01 00:00:00 +0000 UTC 2019-09-17 06:19:38 +0000 UTC  } {Ready True 0001-01-01 00:00:00 +0000 UTC 2019-09-17 06:19:49 +0000 UTC  } {ContainersReady True 0001-01-01 00:00:00 +0000 UTC 0001-01-01 00:00:00 +0000 UTC  } {PodScheduled True 0001-01-01 00:00:00 +0000 UTC 2019-09-17 06:19:38 +0000 UTC  }]
Oct  4 06:46:31.103: INFO: kube-proxy-k8s-m1                                            k8s-m1  Running           [{Initialized True 0001-01-01 00:00:00 +0000 UTC 2019-09-17 06:19:45 +0000 UTC  } {Ready True 0001-01-01 00:00:00 +0000 UTC 2019-09-17 06:19:49 +0000 UTC  } {ContainersReady True 0001-01-01 00:00:00 +0000 UTC 0001-01-01 00:00:00 +0000 UTC  } {PodScheduled True 0001-01-01 00:00:00 +0000 UTC 2019-09-17 06:19:45 +0000 UTC  }]
Oct  4 06:46:31.103: INFO: kube-scheduler-k8s-m1                                        k8s-m1  Running           [{Initialized True 0001-01-01 00:00:00 +0000 UTC 2019-09-17 06:19:38 +0000 UTC  } {Ready True 0001-01-01 00:00:00 +0000 UTC 2019-09-17 06:19:49 +0000 UTC  } {ContainersReady True 0001-01-01 00:00:00 +0000 UTC 0001-01-01 00:00:00 +0000 UTC  } {PodScheduled True 0001-01-01 00:00:00 +0000 UTC 2019-09-17 06:19:38 +0000 UTC  }]
Oct  4 06:46:31.103: INFO: kubernetes-dashboard-6c4587f67d-pm2wb                        k8s-m1  Running           [{Initialized True 0001-01-01 00:00:00 +0000 UTC 2019-06-17 01:52:27 +0000 UTC  } {Ready True 0001-01-01 00:00:00 +0000 UTC 2019-10-02 03:37:26 +0000 UTC  } {ContainersReady True 0001-01-01 00:00:00 +0000 UTC 0001-01-01 00:00:00 +0000 UTC  } {PodScheduled True 0001-01-01 00:00:00 +0000 UTC 2019-06-17 01:52:27 +0000 UTC  }]
Oct  4 06:46:31.103: INFO: tiller-deploy-7f554d9fd7-pzs8t                               k8s-m1  Running           [{Initialized True 0001-01-01 00:00:00 +0000 UTC 2019-07-01 08:58:05 +0000 UTC  } {Ready True 0001-01-01 00:00:00 +0000 UTC 2019-10-02 03:37:40 +0000 UTC  } {ContainersReady True 0001-01-01 00:00:00 +0000 UTC 0001-01-01 00:00:00 +0000 UTC  } {PodScheduled True 0001-01-01 00:00:00 +0000 UTC 2019-07-01 08:58:05 +0000 UTC  }]
Oct  4 06:46:31.103: INFO: apprepo-sync-chartmuseum-1570168800-jkshl                    k8s-m1  Succeeded         [{Initialized True 0001-01-01 00:00:00 +0000 UTC 2019-10-04 06:00:09 +0000 UTC PodCompleted } {Ready False 0001-01-01 00:00:00 +0000 UTC 2019-10-04 06:00:09 +0000 UTC PodCompleted } {ContainersReady False 0001-01-01 00:00:00 +0000 UTC 0001-01-01 00:00:00 +0000 UTC PodCompleted } {PodScheduled True 0001-01-01 00:00:00 +0000 UTC 2019-10-04 06:00:09 +0000 UTC  }]
Oct  4 06:46:31.103: INFO: apprepo-sync-chartmuseum-kl2qg-v78g9                         k8s-m1  Succeeded         [{Initialized True 0001-01-01 00:00:00 +0000 UTC 2019-10-04 05:35:27 +0000 UTC PodCompleted } {Ready False 0001-01-01 00:00:00 +0000 UTC 2019-10-04 05:36:05 +0000 UTC PodCompleted } {ContainersReady False 0001-01-01 00:00:00 +0000 UTC 0001-01-01 00:00:00 +0000 UTC PodCompleted } {PodScheduled True 0001-01-01 00:00:00 +0000 UTC 2019-10-04 05:35:27 +0000 UTC  }]
Oct  4 06:46:31.103: INFO: kubeapps-657dd57975-cphvv                                    k8s-m1  Running           [{Initialized True 0001-01-01 00:00:00 +0000 UTC 2019-10-04 05:35:18 +0000 UTC  } {Ready True 0001-01-01 00:00:00 +0000 UTC 2019-10-04 05:35:39 +0000 UTC  } {ContainersReady True 0001-01-01 00:00:00 +0000 UTC 0001-01-01 00:00:00 +0000 UTC  } {PodScheduled True 0001-01-01 00:00:00 +0000 UTC 2019-10-04 05:35:17 +0000 UTC  }]
Oct  4 06:46:31.103: INFO: kubeapps-internal-apprepository-controller-7897bc78cd-mbtxp  k8s-m1  Running           [{Initialized True 0001-01-01 00:00:00 +0000 UTC 2019-10-04 05:35:17 +0000 UTC  } {Ready True 0001-01-01 00:00:00 +0000 UTC 2019-10-04 05:35:28 +0000 UTC  } {ContainersReady True 0001-01-01 00:00:00 +0000 UTC 0001-01-01 00:00:00 +0000 UTC  } {PodScheduled True 0001-01-01 00:00:00 +0000 UTC 2019-10-04 05:35:17 +0000 UTC  }]
Oct  4 06:46:31.103: INFO: kubeapps-internal-chartsvc-6c5cf8955d-7nr9b                  k8s-m1  Running           [{Initialized True 0001-01-01 00:00:00 +0000 UTC 2019-10-04 05:35:18 +0000 UTC  } {Ready True 0001-01-01 00:00:00 +0000 UTC 2019-10-04 05:36:01 +0000 UTC  } {ContainersReady True 0001-01-01 00:00:00 +0000 UTC 0001-01-01 00:00:00 +0000 UTC  } {PodScheduled True 0001-01-01 00:00:00 +0000 UTC 2019-10-04 05:35:17 +0000 UTC  }]
Oct  4 06:46:31.103: INFO: kubeapps-internal-dashboard-78cb98dbf5-tkckk                 k8s-m1  Running           [{Initialized True 0001-01-01 00:00:00 +0000 UTC 2019-10-04 05:35:18 +0000 UTC  } {Ready True 0001-01-01 00:00:00 +0000 UTC 2019-10-04 05:35:32 +0000 UTC  } {ContainersReady True 0001-01-01 00:00:00 +0000 UTC 0001-01-01 00:00:00 +0000 UTC  } {PodScheduled True 0001-01-01 00:00:00 +0000 UTC 2019-10-04 05:35:17 +0000 UTC  }]
Oct  4 06:46:31.103: INFO: kubeapps-internal-tiller-proxy-67878879c9-92jsl              k8s-m1  Running           [{Initialized True 0001-01-01 00:00:00 +0000 UTC 2019-10-04 05:35:18 +0000 UTC  } {Ready True 0001-01-01 00:00:00 +0000 UTC 2019-10-04 05:35:31 +0000 UTC  } {ContainersReady True 0001-01-01 00:00:00 +0000 UTC 0001-01-01 00:00:00 +0000 UTC  } {PodScheduled True 0001-01-01 00:00:00 +0000 UTC 2019-10-04 05:35:17 +0000 UTC  }]
Oct  4 06:46:31.103: INFO: kubeapps-mongodb-797676494d-j5fv2                            k8s-m1  Running           [{Initialized True 0001-01-01 00:00:00 +0000 UTC 2019-10-04 05:35:18 +0000 UTC  } {Ready True 0001-01-01 00:00:00 +0000 UTC 2019-10-04 05:35:45 +0000 UTC  } {ContainersReady True 0001-01-01 00:00:00 +0000 UTC 0001-01-01 00:00:00 +0000 UTC  } {PodScheduled True 0001-01-01 00:00:00 +0000 UTC 2019-10-04 05:35:17 +0000 UTC  }]
Oct  4 06:46:31.103: INFO: metallb-controller-85bd6857c7-zkht6                          k8s-m1  Running           [{Initialized True 0001-01-01 00:00:00 +0000 UTC 2019-09-06 06:53:02 +0000 UTC  } {Ready True 0001-01-01 00:00:00 +0000 UTC 2019-10-02 03:37:46 +0000 UTC  } {ContainersReady True 0001-01-01 00:00:00 +0000 UTC 0001-01-01 00:00:00 +0000 UTC  } {PodScheduled True 0001-01-01 00:00:00 +0000 UTC 2019-09-06 06:53:02 +0000 UTC  }]
Oct  4 06:46:31.103: INFO: metallb-speaker-cpd7g                                        k8s-m1  Running           [{Initialized True 0001-01-01 00:00:00 +0000 UTC 2019-09-06 06:53:02 +0000 UTC  } {Ready True 0001-01-01 00:00:00 +0000 UTC 2019-10-02 03:37:32 +0000 UTC  } {ContainersReady True 0001-01-01 00:00:00 +0000 UTC 0001-01-01 00:00:00 +0000 UTC  } {PodScheduled True 0001-01-01 00:00:00 +0000 UTC 2019-09-06 06:53:02 +0000 UTC  }]
Oct  4 06:46:31.103: INFO: grafana-6779f4b4b9-22djb                                     k8s-m1  Running           [{Initialized True 0001-01-01 00:00:00 +0000 UTC 2019-08-29 05:38:27 +0000 UTC  } {Ready True 0001-01-01 00:00:00 +0000 UTC 2019-10-02 03:38:58 +0000 UTC  } {ContainersReady True 0001-01-01 00:00:00 +0000 UTC 0001-01-01 00:00:00 +0000 UTC  } {PodScheduled True 0001-01-01 00:00:00 +0000 UTC 2019-08-29 05:38:27 +0000 UTC  }]
Oct  4 06:46:31.103: INFO: helm-exporter-d4bdd4ffb-rp89d                                k8s-m1  Running           [{Initialized True 0001-01-01 00:00:00 +0000 UTC 2019-09-19 07:18:07 +0000 UTC  } {Ready True 0001-01-01 00:00:00 +0000 UTC 2019-10-02 03:39:53 +0000 UTC  } {ContainersReady True 0001-01-01 00:00:00 +0000 UTC 0001-01-01 00:00:00 +0000 UTC  } {PodScheduled True 0001-01-01 00:00:00 +0000 UTC 2019-09-19 07:18:07 +0000 UTC  }]
Oct  4 06:46:31.103: INFO: k8s-event-kubernetes-events-67c85c6f4d-px8hb                 k8s-m1  Running           [{Initialized True 0001-01-01 00:00:00 +0000 UTC 2019-09-25 02:56:47 +0000 UTC  } {Ready False 0001-01-01 00:00:00 +0000 UTC 2019-09-25 02:56:47 +0000 UTC ContainersNotReady containers with unready status: [kubernetes-events]} {ContainersReady False 0001-01-01 00:00:00 +0000 UTC 0001-01-01 00:00:00 +0000 UTC ContainersNotReady containers with unready status: [kubernetes-events]} {PodScheduled True 0001-01-01 00:00:00 +0000 UTC 2019-09-25 02:56:47 +0000 UTC  }]
Oct  4 06:46:31.103: INFO: mongodb-exporter-98d89d647-qrmqv                             k8s-m1  Running           [{Initialized True 0001-01-01 00:00:00 +0000 UTC 2019-09-16 08:56:11 +0000 UTC  } {Ready True 0001-01-01 00:00:00 +0000 UTC 2019-10-02 03:38:15 +0000 UTC  } {ContainersReady True 0001-01-01 00:00:00 +0000 UTC 0001-01-01 00:00:00 +0000 UTC  } {PodScheduled True 0001-01-01 00:00:00 +0000 UTC 2019-09-16 08:56:11 +0000 UTC  }]
Oct  4 06:46:31.103: INFO: postgres-exporter-dd675dbf5-mbjjt                            k8s-m1  Running           [{Initialized True 0001-01-01 00:00:00 +0000 UTC 2019-08-29 02:43:15 +0000 UTC  } {Ready True 0001-01-01 00:00:00 +0000 UTC 2019-10-02 03:38:32 +0000 UTC  } {ContainersReady True 0001-01-01 00:00:00 +0000 UTC 0001-01-01 00:00:00 +0000 UTC  } {PodScheduled True 0001-01-01 00:00:00 +0000 UTC 2019-08-29 02:43:15 +0000 UTC  }]
Oct  4 06:46:31.103: INFO: prometheus-alertmanager-568d7f969c-nmjrg                     k8s-m1  Running           [{Initialized True 0001-01-01 00:00:00 +0000 UTC 2019-09-23 07:20:03 +0000 UTC  } {Ready True 0001-01-01 00:00:00 +0000 UTC 2019-10-02 03:38:58 +0000 UTC  } {ContainersReady True 0001-01-01 00:00:00 +0000 UTC 0001-01-01 00:00:00 +0000 UTC  } {PodScheduled True 0001-01-01 00:00:00 +0000 UTC 2019-09-23 07:20:00 +0000 UTC  }]
Oct  4 06:46:31.103: INFO: prometheus-kube-state-metrics-545644b464-8g4tj               k8s-m1  Running           [{Initialized True 0001-01-01 00:00:00 +0000 UTC 2019-09-23 07:20:03 +0000 UTC  } {Ready True 0001-01-01 00:00:00 +0000 UTC 2019-10-02 03:38:26 +0000 UTC  } {ContainersReady True 0001-01-01 00:00:00 +0000 UTC 0001-01-01 00:00:00 +0000 UTC  } {PodScheduled True 0001-01-01 00:00:00 +0000 UTC 2019-09-23 07:20:00 +0000 UTC  }]
Oct  4 06:46:31.103: INFO: prometheus-node-exporter-sg8rh                               k8s-m1  Running           [{Initialized True 0001-01-01 00:00:00 +0000 UTC 2019-09-23 07:19:58 +0000 UTC  } {Ready True 0001-01-01 00:00:00 +0000 UTC 2019-10-02 03:38:13 +0000 UTC  } {ContainersReady True 0001-01-01 00:00:00 +0000 UTC 0001-01-01 00:00:00 +0000 UTC  } {PodScheduled True 0001-01-01 00:00:00 +0000 UTC 2019-09-23 07:19:58 +0000 UTC  }]
Oct  4 06:46:31.103: INFO: prometheus-pushgateway-79855c6d66-xxvkv                      k8s-m1  Running           [{Initialized True 0001-01-01 00:00:00 +0000 UTC 2019-09-23 07:20:02 +0000 UTC  } {Ready True 0001-01-01 00:00:00 +0000 UTC 2019-10-02 03:37:59 +0000 UTC  } {ContainersReady True 0001-01-01 00:00:00 +0000 UTC 0001-01-01 00:00:00 +0000 UTC  } {PodScheduled True 0001-01-01 00:00:00 +0000 UTC 2019-09-23 07:20:00 +0000 UTC  }]
Oct  4 06:46:31.103: INFO: prometheus-server-c9dfd57b5-v47rb                            k8s-m1  Running           [{Initialized True 0001-01-01 00:00:00 +0000 UTC 2019-09-23 07:20:50 +0000 UTC  } {Ready True 0001-01-01 00:00:00 +0000 UTC 2019-10-02 03:40:48 +0000 UTC  } {ContainersReady True 0001-01-01 00:00:00 +0000 UTC 0001-01-01 00:00:00 +0000 UTC  } {PodScheduled True 0001-01-01 00:00:00 +0000 UTC 2019-09-23 07:20:00 +0000 UTC  }]
Oct  4 06:46:31.103: INFO: rabbitmq-exporter-554cbf5dd6-qgrn5                           k8s-m1  Running           [{Initialized True 0001-01-01 00:00:00 +0000 UTC 2019-09-16 06:32:55 +0000 UTC  } {Ready True 0001-01-01 00:00:00 +0000 UTC 2019-10-02 03:38:09 +0000 UTC  } {ContainersReady True 0001-01-01 00:00:00 +0000 UTC 0001-01-01 00:00:00 +0000 UTC  } {PodScheduled True 0001-01-01 00:00:00 +0000 UTC 2019-09-16 06:32:55 +0000 UTC  }]
Oct  4 06:46:31.103: INFO: coredns-coredns-85468f6977-hldjb                             k8s-m1  Running           [{Initialized True 0001-01-01 00:00:00 +0000 UTC 2019-08-19 05:17:16 +0000 UTC  } {Ready True 0001-01-01 00:00:00 +0000 UTC 2019-10-02 03:37:42 +0000 UTC  } {ContainersReady True 0001-01-01 00:00:00 +0000 UTC 0001-01-01 00:00:00 +0000 UTC  } {PodScheduled True 0001-01-01 00:00:00 +0000 UTC 2019-08-19 05:17:16 +0000 UTC  }]
Oct  4 06:46:31.103: INFO: nginx-ingress-controller-5d755b5596-hnxrx                    k8s-m1  Running           [{Initialized True 0001-01-01 00:00:00 +0000 UTC 2019-09-06 07:06:52 +0000 UTC  } {Ready True 0001-01-01 00:00:00 +0000 UTC 2019-10-02 03:37:57 +0000 UTC  } {ContainersReady True 0001-01-01 00:00:00 +0000 UTC 0001-01-01 00:00:00 +0000 UTC  } {PodScheduled True 0001-01-01 00:00:00 +0000 UTC 2019-09-06 07:06:52 +0000 UTC  }]
Oct  4 06:46:31.103: INFO: nginx-ingress-default-backend-76c874bc49-rkwpz               k8s-m1  Running           [{Initialized True 0001-01-01 00:00:00 +0000 UTC 2019-09-06 07:06:53 +0000 UTC  } {Ready True 0001-01-01 00:00:00 +0000 UTC 2019-10-02 03:38:06 +0000 UTC  } {ContainersReady True 0001-01-01 00:00:00 +0000 UTC 0001-01-01 00:00:00 +0000 UTC  } {PodScheduled True 0001-01-01 00:00:00 +0000 UTC 2019-09-06 07:06:52 +0000 UTC  }]
Oct  4 06:46:31.103: INFO: chartmuseum-chartmuseum-654c79ccfb-tz2n7                     k8s-m1  Running           [{Initialized True 0001-01-01 00:00:00 +0000 UTC 2019-08-23 06:57:07 +0000 UTC  } {Ready True 0001-01-01 00:00:00 +0000 UTC 2019-10-02 03:37:56 +0000 UTC  } {ContainersReady True 0001-01-01 00:00:00 +0000 UTC 0001-01-01 00:00:00 +0000 UTC  } {PodScheduled True 0001-01-01 00:00:00 +0000 UTC 2019-08-23 06:57:07 +0000 UTC  }]
Oct  4 06:46:31.103: INFO: docker-registry-6d9f48dbd4-czvzp                             k8s-m1  Running           [{Initialized True 0001-01-01 00:00:00 +0000 UTC 2019-08-28 08:54:54 +0000 UTC  } {Ready True 0001-01-01 00:00:00 +0000 UTC 2019-10-02 03:38:07 +0000 UTC  } {ContainersReady True 0001-01-01 00:00:00 +0000 UTC 0001-01-01 00:00:00 +0000 UTC  } {PodScheduled True 0001-01-01 00:00:00 +0000 UTC 2019-08-28 08:54:54 +0000 UTC  }]
Oct  4 06:46:31.103: INFO: kubeapps-internal-apprepository-jobs-cleanup-shxwl                   Pending           [{PodScheduled False 0001-01-01 00:00:00 +0000 UTC 2019-08-23 07:31:33 +0000 UTC Unschedulable 0/1 nodes are available: 1 node(s) didn't match node selector.}]
Oct  4 06:46:31.103: INFO: weave-scope-agent-weave-bhxdb                                k8s-m1  Running           [{Initialized True 0001-01-01 00:00:00 +0000 UTC 2019-08-14 01:38:17 +0000 UTC  } {Ready True 0001-01-01 00:00:00 +0000 UTC 2019-10-02 03:37:26 +0000 UTC  } {ContainersReady True 0001-01-01 00:00:00 +0000 UTC 0001-01-01 00:00:00 +0000 UTC  } {PodScheduled True 0001-01-01 00:00:00 +0000 UTC 2019-08-14 01:38:17 +0000 UTC  }]
Oct  4 06:46:31.103: INFO: weave-scope-frontend-weave-689594d47-92fb4                   k8s-m1  Running           [{Initialized True 0001-01-01 00:00:00 +0000 UTC 2019-08-14 01:38:17 +0000 UTC  } {Ready True 0001-01-01 00:00:00 +0000 UTC 2019-10-02 03:37:36 +0000 UTC  } {ContainersReady True 0001-01-01 00:00:00 +0000 UTC 0001-01-01 00:00:00 +0000 UTC  } {PodScheduled True 0001-01-01 00:00:00 +0000 UTC 2019-08-14 01:38:17 +0000 UTC  }]
Oct  4 06:46:31.103: INFO: weavescope-http-statistics-plugin-cxkvh                      k8s-m1  Running           [{Initialized True 0001-01-01 00:00:00 +0000 UTC 2019-08-21 01:49:43 +0000 UTC  } {Ready True 0001-01-01 00:00:00 +0000 UTC 2019-10-02 03:37:51 +0000 UTC  } {ContainersReady True 0001-01-01 00:00:00 +0000 UTC 0001-01-01 00:00:00 +0000 UTC  } {PodScheduled True 0001-01-01 00:00:00 +0000 UTC 2019-08-21 01:49:43 +0000 UTC  }]
Oct  4 06:46:31.103: INFO: weavescope-iowait-plugin-7zx6j                               k8s-m1  Running           [{Initialized True 0001-01-01 00:00:00 +0000 UTC 2019-08-21 01:49:01 +0000 UTC  } {Ready True 0001-01-01 00:00:00 +0000 UTC 2019-10-02 03:37:36 +0000 UTC  } {ContainersReady True 0001-01-01 00:00:00 +0000 UTC 0001-01-01 00:00:00 +0000 UTC  } {PodScheduled True 0001-01-01 00:00:00 +0000 UTC 2019-08-21 01:49:01 +0000 UTC  }]
Oct  4 06:46:31.103: INFO: weavescope-traffic-control-plugin-ljcpb                      k8s-m1  Running           [{Initialized True 0001-01-01 00:00:00 +0000 UTC 2019-08-21 01:43:29 +0000 UTC  } {Ready True 0001-01-01 00:00:00 +0000 UTC 2019-10-02 03:37:46 +0000 UTC  } {ContainersReady True 0001-01-01 00:00:00 +0000 UTC 0001-01-01 00:00:00 +0000 UTC  } {PodScheduled True 0001-01-01 00:00:00 +0000 UTC 2019-08-21 01:43:29 +0000 UTC  }]
Oct  4 06:46:31.103: INFO: 
Oct  4 06:46:31.105: INFO: 
Logging node info for node k8s-m1
Oct  4 06:46:31.108: INFO: 
Logging kubelet events for node k8s-m1
Oct  4 06:46:31.109: INFO: 
Logging pods the kubelet thinks is on node k8s-m1
Oct  4 06:46:31.286: INFO: k8s-event-kubernetes-events-67c85c6f4d-px8hb started at 2019-09-25 02:56:47 +0000 UTC (0+1 container statuses recorded)
Oct  4 06:46:31.286: INFO: 	Container kubernetes-events ready: false, restart count 4360
Oct  4 06:46:31.286: INFO: calico-node-4p8hb started at 2019-05-15 03:23:49 +0000 UTC (0+1 container statuses recorded)
Oct  4 06:46:31.286: INFO: 	Container calico-node ready: true, restart count 6
Oct  4 06:46:31.286: INFO: cert-manager-7d4bfc44ff-mcnqk started at 2019-06-17 05:59:03 +0000 UTC (0+1 container statuses recorded)
Oct  4 06:46:31.286: INFO: 	Container cert-manager ready: true, restart count 5
Oct  4 06:46:31.286: INFO: weave-scope-frontend-weave-689594d47-92fb4 started at 2019-08-14 01:38:17 +0000 UTC (0+1 container statuses recorded)
Oct  4 06:46:31.286: INFO: 	Container weave-scope-frontend ready: true, restart count 3
Oct  4 06:46:31.286: INFO: apprepo-sync-chartmuseum-kl2qg-v78g9 started at 2019-10-04 05:35:27 +0000 UTC (0+1 container statuses recorded)
Oct  4 06:46:31.286: INFO: 	Container sync ready: false, restart count 1
Oct  4 06:46:31.286: INFO: weavescope-http-statistics-plugin-cxkvh started at 2019-08-21 01:49:43 +0000 UTC (0+1 container statuses recorded)
Oct  4 06:46:31.286: INFO: 	Container weavescope-http-statistics-plugin ready: true, restart count 3
Oct  4 06:46:31.286: INFO: rabbitmq-exporter-554cbf5dd6-qgrn5 started at 2019-09-16 06:32:55 +0000 UTC (0+1 container statuses recorded)
Oct  4 06:46:31.286: INFO: 	Container rabbitmq-exporter ready: true, restart count 3
Oct  4 06:46:31.286: INFO: kubeapps-internal-dashboard-78cb98dbf5-tkckk started at 2019-10-04 05:35:18 +0000 UTC (0+1 container statuses recorded)
Oct  4 06:46:31.286: INFO: 	Container dashboard ready: true, restart count 0
Oct  4 06:46:31.286: INFO: apprepo-sync-chartmuseum-1570168800-jkshl started at 2019-10-04 06:00:09 +0000 UTC (0+1 container statuses recorded)
Oct  4 06:46:31.286: INFO: 	Container sync ready: false, restart count 0
Oct  4 06:46:31.286: INFO: weavescope-traffic-control-plugin-ljcpb started at 2019-08-21 01:43:29 +0000 UTC (0+1 container statuses recorded)
Oct  4 06:46:31.286: INFO: 	Container weavescope-traffic-control-plugin ready: true, restart count 3
Oct  4 06:46:31.286: INFO: kubeapps-internal-chartsvc-6c5cf8955d-7nr9b started at 2019-10-04 05:35:18 +0000 UTC (0+1 container statuses recorded)
Oct  4 06:46:31.286: INFO: 	Container chartsvc ready: true, restart count 1
Oct  4 06:46:31.286: INFO: grafana-6779f4b4b9-22djb started at 2019-08-29 05:38:27 +0000 UTC (0+1 container statuses recorded)
Oct  4 06:46:31.286: INFO: 	Container grafana ready: true, restart count 4
Oct  4 06:46:31.286: INFO: es-rabbitmq-68b84c55d5-9pph5 started at 2019-09-05 09:11:16 +0000 UTC (0+1 container statuses recorded)
Oct  4 06:46:31.286: INFO: 	Container es-rabbitmq ready: true, restart count 2
Oct  4 06:46:31.286: INFO: es-edgesense-worker-5b6f55fc8d-56b8t started at 2019-10-02 07:45:47 +0000 UTC (2+1 container statuses recorded)
Oct  4 06:46:31.286: INFO: 	Init container init-postgres ready: true, restart count 0
Oct  4 06:46:31.286: INFO: 	Init container init-mongo ready: true, restart count 0
Oct  4 06:46:31.286: INFO: 	Container es-edgesense-worker ready: true, restart count 0
Oct  4 06:46:31.286: INFO: nginx-ingress-controller-5d755b5596-hnxrx started at 2019-09-06 07:06:52 +0000 UTC (0+1 container statuses recorded)
Oct  4 06:46:31.286: INFO: 	Container nginx-ingress-controller ready: true, restart count 4
Oct  4 06:46:31.286: INFO: prometheus-pushgateway-79855c6d66-xxvkv started at 2019-09-23 07:20:02 +0000 UTC (0+1 container statuses recorded)
Oct  4 06:46:31.286: INFO: 	Container prometheus-pushgateway ready: true, restart count 1
Oct  4 06:46:31.286: INFO: es-minio-68fb8556cf-chg6g started at 2019-09-27 08:58:22 +0000 UTC (0+1 container statuses recorded)
Oct  4 06:46:31.286: INFO: 	Container es-minio ready: true, restart count 1
Oct  4 06:46:31.286: INFO: kube-proxy-k8s-m1 started at <nil> (0+0 container statuses recorded)
Oct  4 06:46:31.286: INFO: coredns-7c949f49d5-m66dj started at 2019-05-15 03:24:15 +0000 UTC (0+1 container statuses recorded)
Oct  4 06:46:31.286: INFO: 	Container coredns ready: true, restart count 4
Oct  4 06:46:31.286: INFO: es-edgesense-portal-76f5b54966-x2pfx started at 2019-10-02 07:45:47 +0000 UTC (1+1 container statuses recorded)
Oct  4 06:46:31.286: INFO: 	Init container init ready: true, restart count 0
Oct  4 06:46:31.286: INFO: 	Container es-edgesense-portal ready: true, restart count 0
Oct  4 06:46:31.286: INFO: cattle-cluster-agent-76979d7d64-8hmwb started at 2019-06-10 05:40:32 +0000 UTC (0+1 container statuses recorded)
Oct  4 06:46:31.286: INFO: 	Container cluster-register ready: false, restart count 11770
Oct  4 06:46:31.286: INFO: es-postgres-d9448cc8c-qrx45 started at 2019-09-03 06:08:25 +0000 UTC (0+1 container statuses recorded)
Oct  4 06:46:31.286: INFO: 	Container es-postgres ready: true, restart count 2
Oct  4 06:46:31.286: INFO: kubeapps-mongodb-797676494d-j5fv2 started at 2019-10-04 05:35:18 +0000 UTC (0+1 container statuses recorded)
Oct  4 06:46:31.286: INFO: 	Container kubeapps-mongodb ready: true, restart count 0
Oct  4 06:46:31.286: INFO: kubeapps-657dd57975-cphvv started at 2019-10-04 05:35:18 +0000 UTC (0+1 container statuses recorded)
Oct  4 06:46:31.286: INFO: 	Container nginx ready: true, restart count 0
Oct  4 06:46:31.286: INFO: sonobuoy started at 2019-10-04 06:35:56 +0000 UTC (0+1 container statuses recorded)
Oct  4 06:46:31.286: INFO: 	Container kube-sonobuoy ready: true, restart count 0
Oct  4 06:46:31.286: INFO: cattle-node-agent-vdqgv started at 2019-06-10 05:40:35 +0000 UTC (0+1 container statuses recorded)
Oct  4 06:46:31.286: INFO: 	Container agent ready: false, restart count 11768
Oct  4 06:46:31.286: INFO: kubernetes-dashboard-6c4587f67d-pm2wb started at 2019-06-17 01:52:27 +0000 UTC (0+1 container statuses recorded)
Oct  4 06:46:31.286: INFO: 	Container kubernetes-dashboard ready: true, restart count 3
Oct  4 06:46:31.286: INFO: es-mongo-7477b4bcf-5gtwr started at 2019-08-19 06:06:51 +0000 UTC (1+1 container statuses recorded)
Oct  4 06:46:31.286: INFO: 	Init container init ready: true, restart count 3
Oct  4 06:46:31.286: INFO: 	Container es-mongo ready: true, restart count 3
Oct  4 06:46:31.286: INFO: tiller-deploy-7f554d9fd7-pzs8t started at 2019-07-01 08:58:05 +0000 UTC (0+1 container statuses recorded)
Oct  4 06:46:31.286: INFO: 	Container tiller ready: true, restart count 3
Oct  4 06:46:31.286: INFO: weavescope-iowait-plugin-7zx6j started at 2019-08-21 01:49:01 +0000 UTC (0+1 container statuses recorded)
Oct  4 06:46:31.286: INFO: 	Container weavescope-iowait-plugin ready: true, restart count 4
Oct  4 06:46:31.286: INFO: chartmuseum-chartmuseum-654c79ccfb-tz2n7 started at 2019-08-23 06:57:07 +0000 UTC (0+1 container statuses recorded)
Oct  4 06:46:31.286: INFO: 	Container chartmuseum ready: true, restart count 2
Oct  4 06:46:31.286: INFO: prometheus-server-c9dfd57b5-v47rb started at 2019-09-23 07:20:01 +0000 UTC (1+2 container statuses recorded)
Oct  4 06:46:31.286: INFO: 	Init container init-chown-data ready: true, restart count 1
Oct  4 06:46:31.286: INFO: 	Container prometheus-server ready: true, restart count 2
Oct  4 06:46:31.286: INFO: 	Container prometheus-server-configmap-reload ready: true, restart count 1
Oct  4 06:46:31.286: INFO: kube-controller-manager-k8s-m1 started at <nil> (0+0 container statuses recorded)
Oct  4 06:46:31.286: INFO: helm-exporter-d4bdd4ffb-rp89d started at 2019-09-19 07:18:07 +0000 UTC (0+1 container statuses recorded)
Oct  4 06:46:31.286: INFO: 	Container helm-exporter ready: true, restart count 5
Oct  4 06:46:31.286: INFO: prometheus-kube-state-metrics-545644b464-8g4tj started at 2019-09-23 07:20:03 +0000 UTC (0+1 container statuses recorded)
Oct  4 06:46:31.286: INFO: 	Container prometheus-kube-state-metrics ready: true, restart count 1
Oct  4 06:46:31.286: INFO: es-edgesense-ota-966c7fb68-f9442 started at 2019-10-02 07:45:47 +0000 UTC (1+1 container statuses recorded)
Oct  4 06:46:31.286: INFO: 	Init container init ready: true, restart count 0
Oct  4 06:46:31.286: INFO: 	Container es-edgesense-ota ready: true, restart count 0
Oct  4 06:46:31.286: INFO: es-deviceon-provisioning-6f5d74c9df-2vqzm started at 2019-10-02 07:25:06 +0000 UTC (1+1 container statuses recorded)
Oct  4 06:46:31.286: INFO: 	Init container init ready: true, restart count 0
Oct  4 06:46:31.286: INFO: 	Container es-deviceon-provisioning ready: true, restart count 0
Oct  4 06:46:31.286: INFO: coredns-coredns-85468f6977-hldjb started at 2019-08-19 05:17:16 +0000 UTC (0+1 container statuses recorded)
Oct  4 06:46:31.286: INFO: 	Container coredns ready: true, restart count 4
Oct  4 06:46:31.286: INFO: docker-registry-6d9f48dbd4-czvzp started at 2019-08-28 08:54:54 +0000 UTC (0+1 container statuses recorded)
Oct  4 06:46:31.286: INFO: 	Container docker-registry ready: true, restart count 2
Oct  4 06:46:31.286: INFO: postgres-exporter-dd675dbf5-mbjjt started at 2019-08-29 02:43:15 +0000 UTC (0+1 container statuses recorded)
Oct  4 06:46:31.286: INFO: 	Container postgres-exporter ready: true, restart count 4
Oct  4 06:46:31.286: INFO: metallb-speaker-cpd7g started at 2019-09-06 06:53:02 +0000 UTC (0+1 container statuses recorded)
Oct  4 06:46:31.286: INFO: 	Container speaker ready: true, restart count 3
Oct  4 06:46:31.286: INFO: calico-kube-controllers-55fcdc5bdb-k2tpm started at 2019-05-15 03:23:56 +0000 UTC (0+1 container statuses recorded)
Oct  4 06:46:31.286: INFO: 	Container calico-kube-controllers ready: true, restart count 5
Oct  4 06:46:31.286: INFO: nginx-ingress-default-backend-76c874bc49-rkwpz started at 2019-09-06 07:06:53 +0000 UTC (0+1 container statuses recorded)
Oct  4 06:46:31.286: INFO: 	Container nginx-ingress-default-backend ready: true, restart count 2
Oct  4 06:46:31.286: INFO: mongodb-exporter-98d89d647-qrmqv started at 2019-09-16 08:56:11 +0000 UTC (0+1 container statuses recorded)
Oct  4 06:46:31.286: INFO: 	Container mongodb-exporter ready: true, restart count 2
Oct  4 06:46:31.286: INFO: prometheus-node-exporter-sg8rh started at 2019-09-23 07:19:58 +0000 UTC (0+1 container statuses recorded)
Oct  4 06:46:31.286: INFO: 	Container prometheus-node-exporter ready: true, restart count 1
Oct  4 06:46:31.286: INFO: weave-scope-agent-weave-bhxdb started at 2019-08-14 01:38:17 +0000 UTC (0+1 container statuses recorded)
Oct  4 06:46:31.286: INFO: 	Container weave-scope-agent ready: true, restart count 4
Oct  4 06:46:31.286: INFO: metallb-controller-85bd6857c7-zkht6 started at 2019-09-06 06:53:02 +0000 UTC (0+1 container statuses recorded)
Oct  4 06:46:31.286: INFO: 	Container controller ready: true, restart count 2
Oct  4 06:46:31.286: INFO: prometheus-alertmanager-568d7f969c-nmjrg started at 2019-09-23 07:20:03 +0000 UTC (0+2 container statuses recorded)
Oct  4 06:46:31.286: INFO: 	Container prometheus-alertmanager ready: true, restart count 1
Oct  4 06:46:31.286: INFO: 	Container prometheus-alertmanager-configmap-reload ready: true, restart count 1
Oct  4 06:46:31.286: INFO: kube-apiserver-k8s-m1 started at <nil> (0+0 container statuses recorded)
Oct  4 06:46:31.286: INFO: kube-scheduler-k8s-m1 started at <nil> (0+0 container statuses recorded)
Oct  4 06:46:31.286: INFO: kubeapps-internal-apprepository-controller-7897bc78cd-mbtxp started at 2019-10-04 05:35:17 +0000 UTC (0+1 container statuses recorded)
Oct  4 06:46:31.286: INFO: 	Container controller ready: true, restart count 0
Oct  4 06:46:31.286: INFO: kubeapps-internal-tiller-proxy-67878879c9-92jsl started at 2019-10-04 05:35:18 +0000 UTC (0+1 container statuses recorded)
Oct  4 06:46:31.286: INFO: 	Container proxy ready: true, restart count 0
Oct  4 06:46:31.286: INFO: sonobuoy-e2e-job-5cf60ae935f841b1 started at 2019-10-04 06:36:04 +0000 UTC (0+2 container statuses recorded)
Oct  4 06:46:31.286: INFO: 	Container e2e ready: true, restart count 0
Oct  4 06:46:31.286: INFO: 	Container sonobuoy-worker ready: true, restart count 0
Oct  4 06:46:31.286: INFO: es-deviceon-portal-6886d46868-7hnrc started at 2019-10-02 07:25:05 +0000 UTC (1+1 container statuses recorded)
Oct  4 06:46:31.286: INFO: 	Init container init ready: true, restart count 0
Oct  4 06:46:31.286: INFO: 	Container es-deviceon-portal ready: true, restart count 0
Oct  4 06:46:31.286: INFO: es-deviceon-worker-78f8585bcd-q55nn started at 2019-10-02 07:25:06 +0000 UTC (2+1 container statuses recorded)
Oct  4 06:46:31.286: INFO: 	Init container init-postgres ready: true, restart count 0
Oct  4 06:46:31.286: INFO: 	Init container init-mongo ready: true, restart count 0
Oct  4 06:46:31.286: INFO: 	Container es-deviceon-worker ready: true, restart count 0
W1004 06:46:31.482271      17 metrics_grabber.go:81] Master node is not registered. Grabbing metrics from Scheduler, ControllerManager and ClusterAutoscaler is disabled.
Oct  4 06:46:31.917: INFO: 
Latency metrics for node k8s-m1
Oct  4 06:46:32.079: INFO: Running kubectl logs on non-ready containers in kube-system
Oct  4 06:46:32.278: INFO: Logs of kube-system/coredns-7c949f49d5-p6f2z:coredns on node 
Oct  4 06:46:32.278: INFO:  : STARTLOG

ENDLOG for container kube-system:coredns-7c949f49d5-p6f2z:coredns
Oct  4 06:46:32.279: INFO: Parsing pod from test/images/clusterapi-tester/pod.yaml
Oct  4 06:46:32.479: INFO: Waiting up to 5m0s for pod "clusterapi-tester" in namespace "default" to be "clusterapi-tester"
Oct  4 06:46:32.751: INFO: Pod "clusterapi-tester": Phase="Pending", Reason="", readiness=false. Elapsed: 271.37473ms
Oct  4 06:46:34.756: INFO: Pod "clusterapi-tester": Phase="Pending", Reason="", readiness=false. Elapsed: 2.276850018s
Oct  4 06:46:36.758: INFO: Pod "clusterapi-tester": Phase="Pending", Reason="", readiness=false. Elapsed: 4.27890655s
Oct  4 06:46:38.788: INFO: Pod "clusterapi-tester": Phase="Pending", Reason="", readiness=false. Elapsed: 6.309153486s
Oct  4 06:46:40.790: INFO: Pod "clusterapi-tester": Phase="Pending", Reason="", readiness=false. Elapsed: 8.310531061s
Oct  4 06:46:42.813: INFO: Pod "clusterapi-tester": Phase="Running", Reason="", readiness=false. Elapsed: 10.333723465s
Oct  4 06:46:44.814: INFO: Pod "clusterapi-tester": Phase="Running", Reason="", readiness=false. Elapsed: 12.335168293s
Oct  4 06:46:46.818: INFO: Pod "clusterapi-tester": Phase="Running", Reason="", readiness=false. Elapsed: 14.338600021s
Oct  4 06:46:48.820: INFO: Pod "clusterapi-tester": Phase="Running", Reason="", readiness=false. Elapsed: 16.341219312s
Oct  4 06:46:50.822: INFO: Pod "clusterapi-tester": Phase="Running", Reason="", readiness=false. Elapsed: 18.343168336s
Oct  4 06:46:52.854: INFO: Pod "clusterapi-tester": Phase="Running", Reason="", readiness=false. Elapsed: 20.375318012s
Oct  4 06:46:54.856: INFO: Pod "clusterapi-tester": Phase="Running", Reason="", readiness=false. Elapsed: 22.376765891s
Oct  4 06:46:56.858: INFO: Pod "clusterapi-tester": Phase="Running", Reason="", readiness=false. Elapsed: 24.379225411s
Oct  4 06:46:58.860: INFO: Pod "clusterapi-tester": Phase="Running", Reason="", readiness=false. Elapsed: 26.381077446s
Oct  4 06:47:00.864: INFO: Pod "clusterapi-tester": Phase="Running", Reason="", readiness=false. Elapsed: 28.384797189s
Oct  4 06:47:02.883: INFO: Pod "clusterapi-tester": Phase="Running", Reason="", readiness=false. Elapsed: 30.403444844s
Oct  4 06:47:04.910: INFO: Pod "clusterapi-tester": Phase="Running", Reason="", readiness=false. Elapsed: 32.431156151s
Oct  4 06:47:06.913: INFO: Pod "clusterapi-tester": Phase="Running", Reason="", readiness=false. Elapsed: 34.434034098s
Oct  4 06:47:08.916: INFO: Pod "clusterapi-tester": Phase="Running", Reason="", readiness=false. Elapsed: 36.437204653s
Oct  4 06:47:10.920: INFO: Pod "clusterapi-tester": Phase="Running", Reason="", readiness=false. Elapsed: 38.440906265s
Oct  4 06:47:12.921: INFO: Pod "clusterapi-tester": Phase="Running", Reason="", readiness=false. Elapsed: 40.44232075s
Oct  4 06:47:14.923: INFO: Pod "clusterapi-tester": Phase="Running", Reason="", readiness=false. Elapsed: 42.443899591s
Oct  4 06:47:16.926: INFO: Pod "clusterapi-tester": Phase="Running", Reason="", readiness=false. Elapsed: 44.447049305s
Oct  4 06:47:18.929: INFO: Pod "clusterapi-tester": Phase="Running", Reason="", readiness=false. Elapsed: 46.450052608s
Oct  4 06:47:20.961: INFO: Pod "clusterapi-tester": Phase="Running", Reason="", readiness=false. Elapsed: 48.481654775s
Oct  4 06:47:22.962: INFO: Pod "clusterapi-tester": Phase="Running", Reason="", readiness=false. Elapsed: 50.483078528s
Oct  4 06:47:24.964: INFO: Pod "clusterapi-tester": Phase="Running", Reason="", readiness=false. Elapsed: 52.484450216s
Oct  4 06:47:26.966: INFO: Pod "clusterapi-tester": Phase="Running", Reason="", readiness=false. Elapsed: 54.487040007s
Oct  4 06:47:28.969: INFO: Pod "clusterapi-tester": Phase="Running", Reason="", readiness=false. Elapsed: 56.489782051s
Oct  4 06:47:30.970: INFO: Pod "clusterapi-tester": Phase="Running", Reason="", readiness=false. Elapsed: 58.491305758s
Oct  4 06:47:32.972: INFO: Pod "clusterapi-tester": Phase="Running", Reason="", readiness=false. Elapsed: 1m0.492687665s
Oct  4 06:47:34.974: INFO: Pod "clusterapi-tester": Phase="Running", Reason="", readiness=false. Elapsed: 1m2.495207751s
Oct  4 06:47:36.977: INFO: Pod "clusterapi-tester": Phase="Running", Reason="", readiness=false. Elapsed: 1m4.498348653s
Oct  4 06:47:38.981: INFO: Pod "clusterapi-tester": Phase="Running", Reason="", readiness=false. Elapsed: 1m6.501473561s
Oct  4 06:47:40.982: INFO: Pod "clusterapi-tester": Phase="Running", Reason="", readiness=false. Elapsed: 1m8.503073348s
Oct  4 06:47:42.984: INFO: Pod "clusterapi-tester": Phase="Running", Reason="", readiness=false. Elapsed: 1m10.504510497s
Oct  4 06:47:44.985: INFO: Pod "clusterapi-tester": Phase="Running", Reason="", readiness=false. Elapsed: 1m12.506304268s
Oct  4 06:47:46.988: INFO: Pod "clusterapi-tester": Phase="Running", Reason="", readiness=false. Elapsed: 1m14.509278667s
Oct  4 06:47:48.992: INFO: Pod "clusterapi-tester": Phase="Running", Reason="", readiness=false. Elapsed: 1m16.512692822s
Oct  4 06:47:50.996: INFO: Pod "clusterapi-tester": Phase="Running", Reason="", readiness=false. Elapsed: 1m18.51642208s
Oct  4 06:47:52.997: INFO: Pod "clusterapi-tester": Phase="Running", Reason="", readiness=false. Elapsed: 1m20.517880154s
Oct  4 06:47:54.999: INFO: Pod "clusterapi-tester": Phase="Running", Reason="", readiness=false. Elapsed: 1m22.519449398s
Oct  4 06:47:57.002: INFO: Pod "clusterapi-tester": Phase="Running", Reason="", readiness=false. Elapsed: 1m24.523102198s
Oct  4 06:47:59.036: INFO: Pod "clusterapi-tester": Phase="Running", Reason="", readiness=false. Elapsed: 1m26.556741724s
Oct  4 06:48:01.100: INFO: Pod "clusterapi-tester": Phase="Running", Reason="", readiness=false. Elapsed: 1m28.62038233s
Oct  4 06:48:03.158: INFO: Pod "clusterapi-tester": Phase="Running", Reason="", readiness=false. Elapsed: 1m30.678766324s
Oct  4 06:48:05.561: INFO: Pod "clusterapi-tester": Phase="Running", Reason="", readiness=false. Elapsed: 1m33.082079948s
Oct  4 06:48:07.860: INFO: Pod "clusterapi-tester": Phase="Running", Reason="", readiness=false. Elapsed: 1m35.381306991s
Oct  4 06:48:09.911: INFO: Pod "clusterapi-tester": Phase="Running", Reason="", readiness=false. Elapsed: 1m37.432257445s
Oct  4 06:48:11.914: INFO: Pod "clusterapi-tester": Phase="Running", Reason="", readiness=false. Elapsed: 1m39.434830389s
Oct  4 06:48:13.917: INFO: Pod "clusterapi-tester": Phase="Running", Reason="", readiness=false. Elapsed: 1m41.438103058s
Oct  4 06:48:15.919: INFO: Pod "clusterapi-tester": Phase="Running", Reason="", readiness=false. Elapsed: 1m43.439567824s
Oct  4 06:48:17.920: INFO: Pod "clusterapi-tester": Phase="Running", Reason="", readiness=false. Elapsed: 1m45.4410841s
Oct  4 06:48:20.034: INFO: Pod "clusterapi-tester": Phase="Running", Reason="", readiness=false. Elapsed: 1m47.554719242s
Oct  4 06:48:22.055: INFO: Pod "clusterapi-tester": Phase="Running", Reason="", readiness=false. Elapsed: 1m49.576244152s
Oct  4 06:48:24.057: INFO: Pod "clusterapi-tester": Phase="Running", Reason="", readiness=false. Elapsed: 1m51.577688941s
Oct  4 06:48:26.058: INFO: Pod "clusterapi-tester": Phase="Running", Reason="", readiness=false. Elapsed: 1m53.579119521s
Oct  4 06:48:28.062: INFO: Pod "clusterapi-tester": Phase="Running", Reason="", readiness=false. Elapsed: 1m55.582502079s
Oct  4 06:48:30.065: INFO: Pod "clusterapi-tester": Phase="Running", Reason="", readiness=false. Elapsed: 1m57.58576364s
Oct  4 06:48:32.068: INFO: Pod "clusterapi-tester": Phase="Running", Reason="", readiness=false. Elapsed: 1m59.588516683s
Oct  4 06:48:34.070: INFO: Pod "clusterapi-tester": Phase="Running", Reason="", readiness=false. Elapsed: 2m1.590811294s
Oct  4 06:48:36.108: INFO: Pod "clusterapi-tester": Phase="Running", Reason="", readiness=false. Elapsed: 2m3.628360405s
Oct  4 06:48:38.109: INFO: Pod "clusterapi-tester": Phase="Running", Reason="", readiness=false. Elapsed: 2m5.62964256s
Oct  4 06:48:40.112: INFO: Pod "clusterapi-tester": Phase="Running", Reason="", readiness=false. Elapsed: 2m7.632910467s
Oct  4 06:48:42.115: INFO: Pod "clusterapi-tester": Phase="Running", Reason="", readiness=false. Elapsed: 2m9.635556831s
Oct  4 06:48:44.116: INFO: Pod "clusterapi-tester": Phase="Running", Reason="", readiness=false. Elapsed: 2m11.637298875s
Oct  4 06:48:46.119: INFO: Pod "clusterapi-tester": Phase="Running", Reason="", readiness=false. Elapsed: 2m13.639617024s
Oct  4 06:48:48.120: INFO: Pod "clusterapi-tester": Phase="Running", Reason="", readiness=false. Elapsed: 2m15.641002728s
Oct  4 06:48:50.123: INFO: Pod "clusterapi-tester": Phase="Running", Reason="", readiness=false. Elapsed: 2m17.644164559s
Oct  4 06:48:52.126: INFO: Pod "clusterapi-tester": Phase="Running", Reason="", readiness=false. Elapsed: 2m19.647131764s
Oct  4 06:48:54.268: INFO: Pod "clusterapi-tester": Phase="Running", Reason="", readiness=false. Elapsed: 2m21.789027789s
Oct  4 06:48:56.270: INFO: Pod "clusterapi-tester": Phase="Running", Reason="", readiness=false. Elapsed: 2m23.790461614s
Oct  4 06:48:58.273: INFO: Pod "clusterapi-tester": Phase="Running", Reason="", readiness=false. Elapsed: 2m25.793672696s
Oct  4 06:49:00.274: INFO: Pod "clusterapi-tester": Phase="Running", Reason="", readiness=false. Elapsed: 2m27.795043768s
Oct  4 06:49:02.277: INFO: Pod "clusterapi-tester": Phase="Running", Reason="", readiness=false. Elapsed: 2m29.797946509s
Oct  4 06:49:04.304: INFO: Pod "clusterapi-tester": Phase="Running", Reason="", readiness=false. Elapsed: 2m31.824780259s
Oct  4 06:49:06.312: INFO: Pod "clusterapi-tester": Phase="Running", Reason="", readiness=false. Elapsed: 2m33.832899485s
Oct  4 06:49:08.314: INFO: Pod "clusterapi-tester": Phase="Running", Reason="", readiness=false. Elapsed: 2m35.834461654s
Oct  4 06:49:10.316: INFO: Pod "clusterapi-tester": Phase="Running", Reason="", readiness=false. Elapsed: 2m37.837182825s
Oct  4 06:49:12.318: INFO: Pod "clusterapi-tester": Phase="Running", Reason="", readiness=false. Elapsed: 2m39.838535045s
Oct  4 06:49:14.319: INFO: Pod "clusterapi-tester": Phase="Running", Reason="", readiness=false. Elapsed: 2m41.840008161s
Oct  4 06:49:16.322: INFO: Pod "clusterapi-tester": Phase="Running", Reason="", readiness=false. Elapsed: 2m43.843053613s
Oct  4 06:49:18.325: INFO: Pod "clusterapi-tester": Phase="Running", Reason="", readiness=false. Elapsed: 2m45.84604034s
Oct  4 06:49:20.427: INFO: Pod "clusterapi-tester": Phase="Running", Reason="", readiness=false. Elapsed: 2m47.947388638s
Oct  4 06:49:22.437: INFO: Pod "clusterapi-tester": Phase="Running", Reason="", readiness=false. Elapsed: 2m49.958136424s
Oct  4 06:49:24.446: INFO: Pod "clusterapi-tester": Phase="Running", Reason="", readiness=false. Elapsed: 2m51.966693267s
Oct  4 06:49:26.449: INFO: Pod "clusterapi-tester": Phase="Running", Reason="", readiness=false. Elapsed: 2m53.970007186s
Oct  4 06:49:28.451: INFO: Pod "clusterapi-tester": Phase="Running", Reason="", readiness=false. Elapsed: 2m55.971451024s
Oct  4 06:49:30.453: INFO: Pod "clusterapi-tester": Phase="Running", Reason="", readiness=false. Elapsed: 2m57.974162655s
Oct  4 06:49:32.455: INFO: Pod "clusterapi-tester": Phase="Running", Reason="", readiness=false. Elapsed: 2m59.975911842s
Oct  4 06:49:34.456: INFO: Pod "clusterapi-tester": Phase="Running", Reason="", readiness=false. Elapsed: 3m1.97733616s
Oct  4 06:49:36.460: INFO: Pod "clusterapi-tester": Phase="Running", Reason="", readiness=false. Elapsed: 3m3.980516926s
Oct  4 06:49:38.464: INFO: Pod "clusterapi-tester": Phase="Running", Reason="", readiness=false. Elapsed: 3m5.984389394s
Oct  4 06:49:40.503: INFO: Pod "clusterapi-tester": Phase="Running", Reason="", readiness=false. Elapsed: 3m8.023854482s
Oct  4 06:49:42.505: INFO: Pod "clusterapi-tester": Phase="Running", Reason="", readiness=false. Elapsed: 3m10.025590061s
Oct  4 06:49:44.514: INFO: Pod "clusterapi-tester": Phase="Running", Reason="", readiness=false. Elapsed: 3m12.034381573s
Oct  4 06:49:46.517: INFO: Pod "clusterapi-tester": Phase="Running", Reason="", readiness=false. Elapsed: 3m14.038184105s
Oct  4 06:49:48.521: INFO: Pod "clusterapi-tester": Phase="Running", Reason="", readiness=false. Elapsed: 3m16.041864349s
Oct  4 06:49:50.523: INFO: Pod "clusterapi-tester": Phase="Running", Reason="", readiness=false. Elapsed: 3m18.043533169s
Oct  4 06:49:52.548: INFO: Pod "clusterapi-tester": Phase="Running", Reason="", readiness=false. Elapsed: 3m20.068695118s
Oct  4 06:49:54.551: INFO: Pod "clusterapi-tester": Phase="Running", Reason="", readiness=false. Elapsed: 3m22.071978701s
Oct  4 06:49:56.554: INFO: Pod "clusterapi-tester": Phase="Running", Reason="", readiness=false. Elapsed: 3m24.074810826s
Oct  4 06:49:58.606: INFO: Pod "clusterapi-tester": Phase="Running", Reason="", readiness=false. Elapsed: 3m26.127085143s
Oct  4 06:50:00.609: INFO: Pod "clusterapi-tester": Phase="Running", Reason="", readiness=false. Elapsed: 3m28.129492099s
Oct  4 06:50:02.611: INFO: Pod "clusterapi-tester": Phase="Running", Reason="", readiness=false. Elapsed: 3m30.131464595s
Oct  4 06:50:04.612: INFO: Pod "clusterapi-tester": Phase="Running", Reason="", readiness=false. Elapsed: 3m32.132882168s
Oct  4 06:50:06.615: INFO: Pod "clusterapi-tester": Phase="Running", Reason="", readiness=false. Elapsed: 3m34.135917374s
Oct  4 06:50:08.617: INFO: Pod "clusterapi-tester": Phase="Running", Reason="", readiness=false. Elapsed: 3m36.13778396s
Oct  4 06:50:10.618: INFO: Pod "clusterapi-tester": Phase="Running", Reason="", readiness=false. Elapsed: 3m38.139281539s
Oct  4 06:50:12.620: INFO: Pod "clusterapi-tester": Phase="Running", Reason="", readiness=false. Elapsed: 3m40.140626221s
Oct  4 06:50:14.621: INFO: Pod "clusterapi-tester": Phase="Running", Reason="", readiness=false. Elapsed: 3m42.142023266s
Oct  4 06:50:16.817: INFO: Pod "clusterapi-tester": Phase="Running", Reason="", readiness=false. Elapsed: 3m44.337599197s
Oct  4 06:50:18.820: INFO: Pod "clusterapi-tester": Phase="Running", Reason="", readiness=false. Elapsed: 3m46.340547511s
Oct  4 06:50:20.821: INFO: Pod "clusterapi-tester": Phase="Running", Reason="", readiness=false. Elapsed: 3m48.342255731s
Oct  4 06:50:22.823: INFO: Pod "clusterapi-tester": Phase="Running", Reason="", readiness=false. Elapsed: 3m50.343823442s
Oct  4 06:50:24.825: INFO: Pod "clusterapi-tester": Phase="Running", Reason="", readiness=false. Elapsed: 3m52.345387382s
Oct  4 06:50:26.827: INFO: Pod "clusterapi-tester": Phase="Running", Reason="", readiness=false. Elapsed: 3m54.347984689s
Oct  4 06:50:28.830: INFO: Pod "clusterapi-tester": Phase="Running", Reason="", readiness=false. Elapsed: 3m56.35076962s
Oct  4 06:50:30.831: INFO: Pod "clusterapi-tester": Phase="Running", Reason="", readiness=false. Elapsed: 3m58.352144016s
Oct  4 06:50:32.834: INFO: Pod "clusterapi-tester": Phase="Running", Reason="", readiness=false. Elapsed: 4m0.35497283s
Oct  4 06:50:34.836: INFO: Pod "clusterapi-tester": Phase="Running", Reason="", readiness=false. Elapsed: 4m2.356612471s
Oct  4 06:50:36.853: INFO: Pod "clusterapi-tester": Phase="Running", Reason="", readiness=false. Elapsed: 4m4.37380298s
Oct  4 06:50:38.855: INFO: Pod "clusterapi-tester": Phase="Running", Reason="", readiness=false. Elapsed: 4m6.376184124s
Oct  4 06:50:40.857: INFO: Pod "clusterapi-tester": Phase="Running", Reason="", readiness=false. Elapsed: 4m8.37753672s
Oct  4 06:50:42.860: INFO: Pod "clusterapi-tester": Phase="Running", Reason="", readiness=false. Elapsed: 4m10.38057357s
Oct  4 06:50:44.862: INFO: Pod "clusterapi-tester": Phase="Running", Reason="", readiness=false. Elapsed: 4m12.383130179s
Oct  4 06:50:46.866: INFO: Pod "clusterapi-tester": Phase="Running", Reason="", readiness=false. Elapsed: 4m14.386878502s
Oct  4 06:50:48.869: INFO: Pod "clusterapi-tester": Phase="Running", Reason="", readiness=false. Elapsed: 4m16.390066697s
Oct  4 06:50:50.871: INFO: Pod "clusterapi-tester": Phase="Running", Reason="", readiness=false. Elapsed: 4m18.391547688s
Oct  4 06:50:52.920: INFO: Pod "clusterapi-tester": Phase="Running", Reason="", readiness=false. Elapsed: 4m20.440514299s
Oct  4 06:50:54.924: INFO: Pod "clusterapi-tester": Phase="Running", Reason="", readiness=false. Elapsed: 4m22.444909894s
Oct  4 06:50:56.927: INFO: Pod "clusterapi-tester": Phase="Running", Reason="", readiness=false. Elapsed: 4m24.448168751s
Oct  4 06:50:58.930: INFO: Pod "clusterapi-tester": Phase="Running", Reason="", readiness=false. Elapsed: 4m26.451025981s
Oct  4 06:51:00.932: INFO: Pod "clusterapi-tester": Phase="Running", Reason="", readiness=false. Elapsed: 4m28.452555313s
Oct  4 06:51:02.944: INFO: Pod "clusterapi-tester": Phase="Running", Reason="", readiness=false. Elapsed: 4m30.46494366s
Oct  4 06:51:04.947: INFO: Pod "clusterapi-tester": Phase="Running", Reason="", readiness=false. Elapsed: 4m32.467845519s
Oct  4 06:51:06.950: INFO: Pod "clusterapi-tester": Phase="Running", Reason="", readiness=false. Elapsed: 4m34.471011922s
Oct  4 06:51:08.952: INFO: Pod "clusterapi-tester": Phase="Running", Reason="", readiness=false. Elapsed: 4m36.472445833s
Oct  4 06:51:10.953: INFO: Pod "clusterapi-tester": Phase="Running", Reason="", readiness=false. Elapsed: 4m38.474031192s
Oct  4 06:51:12.956: INFO: Pod "clusterapi-tester": Phase="Running", Reason="", readiness=false. Elapsed: 4m40.476986681s
Oct  4 06:51:14.958: INFO: Pod "clusterapi-tester": Phase="Running", Reason="", readiness=false. Elapsed: 4m42.478885159s
Oct  4 06:51:16.960: INFO: Pod "clusterapi-tester": Phase="Running", Reason="", readiness=false. Elapsed: 4m44.480787489s
Oct  4 06:51:19.028: INFO: Pod "clusterapi-tester": Phase="Running", Reason="", readiness=false. Elapsed: 4m46.548568754s
Oct  4 06:51:21.031: INFO: Pod "clusterapi-tester": Phase="Running", Reason="", readiness=false. Elapsed: 4m48.552110303s
Oct  4 06:51:23.034: INFO: Pod "clusterapi-tester": Phase="Running", Reason="", readiness=false. Elapsed: 4m50.554794203s
Oct  4 06:51:25.038: INFO: Pod "clusterapi-tester": Phase="Running", Reason="", readiness=false. Elapsed: 4m52.558426616s
Oct  4 06:51:27.041: INFO: Pod "clusterapi-tester": Phase="Running", Reason="", readiness=false. Elapsed: 4m54.561754343s
Oct  4 06:51:29.179: INFO: Pod "clusterapi-tester": Phase="Running", Reason="", readiness=false. Elapsed: 4m56.699876566s
Oct  4 06:51:31.182: INFO: Pod "clusterapi-tester": Phase="Running", Reason="", readiness=false. Elapsed: 4m58.702766695s
Oct  4 06:51:33.182: INFO: Pod clusterapi-tester took longer than 5m0s to enter running/ready: Gave up after waiting 5m0s for pod "clusterapi-tester" to be "clusterapi-tester"
Oct  4 06:51:33.188: INFO: Error waiting for all pods to be running and ready: 1 / 11 pods in namespace "kube-system" are NOT in RUNNING and READY state in 10m0s
POD                      NODE PHASE   GRACE CONDITIONS
coredns-7c949f49d5-p6f2z      Pending       [{Type:PodScheduled Status:False LastProbeTime:0001-01-01 00:00:00 +0000 UTC LastTransitionTime:2019-05-15 03:24:15 +0000 UTC Reason:Unschedulable Message:0/1 nodes are available: 1 node(s) didn't match pod affinity/anti-affinity, 1 node(s) didn't satisfy existing pods anti-affinity rules.}]

Failure [902.161 seconds]
[BeforeSuite] BeforeSuite 
/workspace/anago-v1.11.3-beta.0.71+a4529464e4629c/src/k8s.io/kubernetes/_output/dockerized/go/src/k8s.io/kubernetes/test/e2e/e2e.go:140

  Oct  4 06:51:33.188: Error waiting for all pods to be running and ready: 1 / 11 pods in namespace "kube-system" are NOT in RUNNING and READY state in 10m0s
  POD                      NODE PHASE   GRACE CONDITIONS
  coredns-7c949f49d5-p6f2z      Pending       [{Type:PodScheduled Status:False LastProbeTime:0001-01-01 00:00:00 +0000 UTC LastTransitionTime:2019-05-15 03:24:15 +0000 UTC Reason:Unschedulable Message:0/1 nodes are available: 1 node(s) didn't match pod affinity/anti-affinity, 1 node(s) didn't satisfy existing pods anti-affinity rules.}]
  

  /workspace/anago-v1.11.3-beta.0.71+a4529464e4629c/src/k8s.io/kubernetes/_output/dockerized/go/src/k8s.io/kubernetes/test/e2e/e2e.go:193
------------------------------
Oct  4 06:51:33.191: INFO: Running AfterSuite actions on all node
Oct  4 06:51:33.191: INFO: Running AfterSuite actions on node 1
Oct  4 06:51:33.191: INFO: Skipping dumping logs from cluster

Ran 1 of 0 Specs in 902.161 seconds
FAIL! -- 0 Passed | 1 Failed | 0 Pending | 0 Skipped --- FAIL: TestE2E (902.21s)
FAIL

Ginkgo ran 1 suite in 15m2.424116313s
Test Suite Failed
